[2025-08-21 14:29:17,881: ERROR/MainProcess] consumer: Cannot connect to redis://localhost:6379/0: Error 10061 connecting to localhost:6379. No connection could be made because the target machine actively refused it..
Trying again in 2.00 seconds... (1/100)

[2025-08-21 14:29:22,017: ERROR/SpawnPoolWorker-6] Pool process <billiard.pool.Worker object at 0x000001AABC16E120> error: PermissionError(13, 'Access is denied', None, 5, None)
Traceback (most recent call last):
  File "C:\Workspace\FrankTheLocalLLM-main\.venv\Lib\site-packages\billiard\pool.py", line 473, in receive
    ready, req = _receive(1.0)
                 ~~~~~~~~^^^^^
  File "C:\Workspace\FrankTheLocalLLM-main\.venv\Lib\site-packages\billiard\pool.py", line 445, in _recv
    return True, loads(get_payload())
                       ~~~~~~~~~~~^^
  File "C:\Workspace\FrankTheLocalLLM-main\.venv\Lib\site-packages\billiard\queues.py", line 394, in get_payload
    with self._rlock:
         ^^^^^^^^^^^
  File "C:\Workspace\FrankTheLocalLLM-main\.venv\Lib\site-packages\billiard\synchronize.py", line 115, in __enter__
    return self._semlock.__enter__()
           ~~~~~~~~~~~~~~~~~~~~~~~^^
PermissionError: [WinError 5] Access is denied

During handling of the above exception, another exception occurred:

Traceback (most recent call last):
  File "C:\Workspace\FrankTheLocalLLM-main\.venv\Lib\site-packages\billiard\pool.py", line 351, in workloop
    req = wait_for_job()
  File "C:\Workspace\FrankTheLocalLLM-main\.venv\Lib\site-packages\billiard\pool.py", line 480, in receive
    raise SystemExit(EX_FAILURE)
SystemExit: 1

During handling of the above exception, another exception occurred:

Traceback (most recent call last):
  File "C:\Workspace\FrankTheLocalLLM-main\.venv\Lib\site-packages\billiard\pool.py", line 292, in __call__
    sys.exit(self.workloop(pid=pid))
             ~~~~~~~~~~~~~^^^^^^^^^
  File "C:\Workspace\FrankTheLocalLLM-main\.venv\Lib\site-packages\billiard\pool.py", line 396, in workloop
    self._ensure_messages_consumed(completed=completed)
    ~~~~~~~~~~~~~~~~~~~~~~~~~~~~~~^^^^^^^^^^^^^^^^^^^^^
  File "C:\Workspace\FrankTheLocalLLM-main\.venv\Lib\site-packages\billiard\pool.py", line 406, in _ensure_messages_consumed
    if self.on_ready_counter.value >= completed:
       ^^^^^^^^^^^^^^^^^^^^^^^^^^^
  File "<string>", line 3, in getvalue
PermissionError: [WinError 5] Access is denied
[2025-08-21 14:29:22,017: ERROR/SpawnPoolWorker-6] Pool process <billiard.pool.Worker object at 0x000001AABC16E120> error: PermissionError(13, 'Access is denied', None, 5, None)
Traceback (most recent call last):
  File "C:\Workspace\FrankTheLocalLLM-main\.venv\Lib\site-packages\billiard\pool.py", line 473, in receive
    ready, req = _receive(1.0)
                 ~~~~~~~~^^^^^
  File "C:\Workspace\FrankTheLocalLLM-main\.venv\Lib\site-packages\billiard\pool.py", line 445, in _recv
    return True, loads(get_payload())
                       ~~~~~~~~~~~^^
  File "C:\Workspace\FrankTheLocalLLM-main\.venv\Lib\site-packages\billiard\queues.py", line 394, in get_payload
    with self._rlock:
         ^^^^^^^^^^^
  File "C:\Workspace\FrankTheLocalLLM-main\.venv\Lib\site-packages\billiard\synchronize.py", line 115, in __enter__
    return self._semlock.__enter__()
           ~~~~~~~~~~~~~~~~~~~~~~~^^
PermissionError: [WinError 5] Access is denied

During handling of the above exception, another exception occurred:

Traceback (most recent call last):
  File "C:\Workspace\FrankTheLocalLLM-main\.venv\Lib\site-packages\billiard\pool.py", line 351, in workloop
    req = wait_for_job()
  File "C:\Workspace\FrankTheLocalLLM-main\.venv\Lib\site-packages\billiard\pool.py", line 480, in receive
    raise SystemExit(EX_FAILURE)
SystemExit: 1

During handling of the above exception, another exception occurred:

Traceback (most recent call last):
  File "C:\Workspace\FrankTheLocalLLM-main\.venv\Lib\site-packages\billiard\pool.py", line 292, in __call__
    sys.exit(self.workloop(pid=pid))
             ~~~~~~~~~~~~~^^^^^^^^^
  File "C:\Workspace\FrankTheLocalLLM-main\.venv\Lib\site-packages\billiard\pool.py", line 396, in workloop
    self._ensure_messages_consumed(completed=completed)
    ~~~~~~~~~~~~~~~~~~~~~~~~~~~~~~^^^^^^^^^^^^^^^^^^^^^
  File "C:\Workspace\FrankTheLocalLLM-main\.venv\Lib\site-packages\billiard\pool.py", line 406, in _ensure_messages_consumed
    if self.on_ready_counter.value >= completed:
       ^^^^^^^^^^^^^^^^^^^^^^^^^^^
  File "<string>", line 3, in getvalue
PermissionError: [WinError 5] Access is denied
[2025-08-21 14:29:22,130: ERROR/SpawnPoolWorker-1] Pool process <billiard.pool.Worker object at 0x00000209FBB2E120> error: OSError(9, 'The handle is invalid', None, 6, None)
Traceback (most recent call last):
  File "C:\Workspace\FrankTheLocalLLM-main\.venv\Lib\site-packages\billiard\pool.py", line 473, in receive
    ready, req = _receive(1.0)
                 ~~~~~~~~^^^^^
  File "C:\Workspace\FrankTheLocalLLM-main\.venv\Lib\site-packages\billiard\pool.py", line 445, in _recv
    return True, loads(get_payload())
                       ~~~~~~~~~~~^^
  File "C:\Workspace\FrankTheLocalLLM-main\.venv\Lib\site-packages\billiard\queues.py", line 394, in get_payload
    with self._rlock:
         ^^^^^^^^^^^
  File "C:\Workspace\FrankTheLocalLLM-main\.venv\Lib\site-packages\billiard\synchronize.py", line 115, in __enter__
    return self._semlock.__enter__()
           ~~~~~~~~~~~~~~~~~~~~~~~^^
PermissionError: [WinError 5] Access is denied

During handling of the above exception, another exception occurred:

Traceback (most recent call last):
  File "C:\Workspace\FrankTheLocalLLM-main\.venv\Lib\site-packages\billiard\pool.py", line 351, in workloop
    req = wait_for_job()
  File "C:\Workspace\FrankTheLocalLLM-main\.venv\Lib\site-packages\billiard\pool.py", line 480, in receive
    raise SystemExit(EX_FAILURE)
SystemExit: 1

During handling of the above exception, another exception occurred:

Traceback (most recent call last):
  File "C:\Workspace\FrankTheLocalLLM-main\.venv\Lib\site-packages\billiard\pool.py", line 292, in __call__
    sys.exit(self.workloop(pid=pid))
             ~~~~~~~~~~~~~^^^^^^^^^
  File "C:\Workspace\FrankTheLocalLLM-main\.venv\Lib\site-packages\billiard\pool.py", line 396, in workloop
    self._ensure_messages_consumed(completed=completed)
    ~~~~~~~~~~~~~~~~~~~~~~~~~~~~~~^^^^^^^^^^^^^^^^^^^^^
  File "C:\Workspace\FrankTheLocalLLM-main\.venv\Lib\site-packages\billiard\pool.py", line 406, in _ensure_messages_consumed
    if self.on_ready_counter.value >= completed:
       ^^^^^^^^^^^^^^^^^^^^^^^^^^^
  File "<string>", line 7, in getvalue
OSError: [WinError 6] The handle is invalid
[2025-08-21 14:29:22,130: ERROR/SpawnPoolWorker-1] Pool process <billiard.pool.Worker object at 0x00000209FBB2E120> error: OSError(9, 'The handle is invalid', None, 6, None)
Traceback (most recent call last):
  File "C:\Workspace\FrankTheLocalLLM-main\.venv\Lib\site-packages\billiard\pool.py", line 473, in receive
    ready, req = _receive(1.0)
                 ~~~~~~~~^^^^^
  File "C:\Workspace\FrankTheLocalLLM-main\.venv\Lib\site-packages\billiard\pool.py", line 445, in _recv
    return True, loads(get_payload())
                       ~~~~~~~~~~~^^
  File "C:\Workspace\FrankTheLocalLLM-main\.venv\Lib\site-packages\billiard\queues.py", line 394, in get_payload
    with self._rlock:
         ^^^^^^^^^^^
  File "C:\Workspace\FrankTheLocalLLM-main\.venv\Lib\site-packages\billiard\synchronize.py", line 115, in __enter__
    return self._semlock.__enter__()
           ~~~~~~~~~~~~~~~~~~~~~~~^^
PermissionError: [WinError 5] Access is denied

During handling of the above exception, another exception occurred:

Traceback (most recent call last):
  File "C:\Workspace\FrankTheLocalLLM-main\.venv\Lib\site-packages\billiard\pool.py", line 351, in workloop
    req = wait_for_job()
  File "C:\Workspace\FrankTheLocalLLM-main\.venv\Lib\site-packages\billiard\pool.py", line 480, in receive
    raise SystemExit(EX_FAILURE)
SystemExit: 1

During handling of the above exception, another exception occurred:

Traceback (most recent call last):
  File "C:\Workspace\FrankTheLocalLLM-main\.venv\Lib\site-packages\billiard\pool.py", line 292, in __call__
    sys.exit(self.workloop(pid=pid))
             ~~~~~~~~~~~~~^^^^^^^^^
  File "C:\Workspace\FrankTheLocalLLM-main\.venv\Lib\site-packages\billiard\pool.py", line 396, in workloop
    self._ensure_messages_consumed(completed=completed)
    ~~~~~~~~~~~~~~~~~~~~~~~~~~~~~~^^^^^^^^^^^^^^^^^^^^^
  File "C:\Workspace\FrankTheLocalLLM-main\.venv\Lib\site-packages\billiard\pool.py", line 406, in _ensure_messages_consumed
    if self.on_ready_counter.value >= completed:
       ^^^^^^^^^^^^^^^^^^^^^^^^^^^
  File "<string>", line 7, in getvalue
OSError: [WinError 6] The handle is invalid
[2025-08-21 14:29:22,188: ERROR/SpawnPoolWorker-4] Pool process <billiard.pool.Worker object at 0x0000018350DCE120> error: PermissionError(13, 'Access is denied', None, 5, None)
Traceback (most recent call last):
  File "C:\Workspace\FrankTheLocalLLM-main\.venv\Lib\site-packages\billiard\pool.py", line 473, in receive
    ready, req = _receive(1.0)
                 ~~~~~~~~^^^^^
  File "C:\Workspace\FrankTheLocalLLM-main\.venv\Lib\site-packages\billiard\pool.py", line 445, in _recv
    return True, loads(get_payload())
                       ~~~~~~~~~~~^^
  File "C:\Workspace\FrankTheLocalLLM-main\.venv\Lib\site-packages\billiard\queues.py", line 394, in get_payload
    with self._rlock:
         ^^^^^^^^^^^
  File "C:\Workspace\FrankTheLocalLLM-main\.venv\Lib\site-packages\billiard\synchronize.py", line 115, in __enter__
    return self._semlock.__enter__()
           ~~~~~~~~~~~~~~~~~~~~~~~^^
PermissionError: [WinError 5] Access is denied

During handling of the above exception, another exception occurred:

Traceback (most recent call last):
  File "C:\Workspace\FrankTheLocalLLM-main\.venv\Lib\site-packages\billiard\pool.py", line 351, in workloop
    req = wait_for_job()
  File "C:\Workspace\FrankTheLocalLLM-main\.venv\Lib\site-packages\billiard\pool.py", line 480, in receive
    raise SystemExit(EX_FAILURE)
SystemExit: 1

During handling of the above exception, another exception occurred:

Traceback (most recent call last):
  File "C:\Workspace\FrankTheLocalLLM-main\.venv\Lib\site-packages\billiard\pool.py", line 292, in __call__
    sys.exit(self.workloop(pid=pid))
             ~~~~~~~~~~~~~^^^^^^^^^
  File "C:\Workspace\FrankTheLocalLLM-main\.venv\Lib\site-packages\billiard\pool.py", line 396, in workloop
    self._ensure_messages_consumed(completed=completed)
    ~~~~~~~~~~~~~~~~~~~~~~~~~~~~~~^^^^^^^^^^^^^^^^^^^^^
  File "C:\Workspace\FrankTheLocalLLM-main\.venv\Lib\site-packages\billiard\pool.py", line 406, in _ensure_messages_consumed
    if self.on_ready_counter.value >= completed:
       ^^^^^^^^^^^^^^^^^^^^^^^^^^^
  File "<string>", line 3, in getvalue
PermissionError: [WinError 5] Access is denied
[2025-08-21 14:29:22,188: ERROR/SpawnPoolWorker-4] Pool process <billiard.pool.Worker object at 0x0000018350DCE120> error: PermissionError(13, 'Access is denied', None, 5, None)
Traceback (most recent call last):
  File "C:\Workspace\FrankTheLocalLLM-main\.venv\Lib\site-packages\billiard\pool.py", line 473, in receive
    ready, req = _receive(1.0)
                 ~~~~~~~~^^^^^
  File "C:\Workspace\FrankTheLocalLLM-main\.venv\Lib\site-packages\billiard\pool.py", line 445, in _recv
    return True, loads(get_payload())
                       ~~~~~~~~~~~^^
  File "C:\Workspace\FrankTheLocalLLM-main\.venv\Lib\site-packages\billiard\queues.py", line 394, in get_payload
    with self._rlock:
         ^^^^^^^^^^^
  File "C:\Workspace\FrankTheLocalLLM-main\.venv\Lib\site-packages\billiard\synchronize.py", line 115, in __enter__
    return self._semlock.__enter__()
           ~~~~~~~~~~~~~~~~~~~~~~~^^
PermissionError: [WinError 5] Access is denied

During handling of the above exception, another exception occurred:

Traceback (most recent call last):
  File "C:\Workspace\FrankTheLocalLLM-main\.venv\Lib\site-packages\billiard\pool.py", line 351, in workloop
    req = wait_for_job()
  File "C:\Workspace\FrankTheLocalLLM-main\.venv\Lib\site-packages\billiard\pool.py", line 480, in receive
    raise SystemExit(EX_FAILURE)
SystemExit: 1

During handling of the above exception, another exception occurred:

Traceback (most recent call last):
  File "C:\Workspace\FrankTheLocalLLM-main\.venv\Lib\site-packages\billiard\pool.py", line 292, in __call__
    sys.exit(self.workloop(pid=pid))
             ~~~~~~~~~~~~~^^^^^^^^^
  File "C:\Workspace\FrankTheLocalLLM-main\.venv\Lib\site-packages\billiard\pool.py", line 396, in workloop
    self._ensure_messages_consumed(completed=completed)
    ~~~~~~~~~~~~~~~~~~~~~~~~~~~~~~^^^^^^^^^^^^^^^^^^^^^
  File "C:\Workspace\FrankTheLocalLLM-main\.venv\Lib\site-packages\billiard\pool.py", line 406, in _ensure_messages_consumed
    if self.on_ready_counter.value >= completed:
       ^^^^^^^^^^^^^^^^^^^^^^^^^^^
  File "<string>", line 3, in getvalue
PermissionError: [WinError 5] Access is denied
[2025-08-21 14:29:22,848: ERROR/MainProcess] Process 'SpawnPoolWorker-6' pid:29228 exited with 'exitcode 1'
[2025-08-21 14:29:22,859: ERROR/MainProcess] Process 'SpawnPoolWorker-4' pid:2300 exited with 'exitcode 1'
[2025-08-21 14:29:22,859: ERROR/MainProcess] Process 'SpawnPoolWorker-1' pid:25668 exited with 'exitcode 1'
[2025-08-21 14:29:24,134: ERROR/MainProcess] consumer: Cannot connect to redis://localhost:6379/0: Error 10061 connecting to localhost:6379. No connection could be made because the target machine actively refused it..
Trying again in 4.00 seconds... (2/100)

[2025-08-21 14:29:26,476: ERROR/SpawnPoolWorker-14] Pool process <billiard.pool.Worker object at 0x000001DABA1EE120> error: OSError(9, 'The handle is invalid', None, 6, None)
Traceback (most recent call last):
  File "C:\Workspace\FrankTheLocalLLM-main\.venv\Lib\site-packages\billiard\pool.py", line 473, in receive
    ready, req = _receive(1.0)
                 ~~~~~~~~^^^^^
  File "C:\Workspace\FrankTheLocalLLM-main\.venv\Lib\site-packages\billiard\pool.py", line 445, in _recv
    return True, loads(get_payload())
                       ~~~~~~~~~~~^^
  File "C:\Workspace\FrankTheLocalLLM-main\.venv\Lib\site-packages\billiard\queues.py", line 394, in get_payload
    with self._rlock:
         ^^^^^^^^^^^
  File "C:\Workspace\FrankTheLocalLLM-main\.venv\Lib\site-packages\billiard\synchronize.py", line 115, in __enter__
    return self._semlock.__enter__()
           ~~~~~~~~~~~~~~~~~~~~~~~^^
PermissionError: [WinError 5] Access is denied

During handling of the above exception, another exception occurred:

Traceback (most recent call last):
  File "C:\Workspace\FrankTheLocalLLM-main\.venv\Lib\site-packages\billiard\pool.py", line 351, in workloop
    req = wait_for_job()
  File "C:\Workspace\FrankTheLocalLLM-main\.venv\Lib\site-packages\billiard\pool.py", line 480, in receive
    raise SystemExit(EX_FAILURE)
SystemExit: 1

During handling of the above exception, another exception occurred:

Traceback (most recent call last):
  File "C:\Workspace\FrankTheLocalLLM-main\.venv\Lib\site-packages\billiard\pool.py", line 292, in __call__
    sys.exit(self.workloop(pid=pid))
             ~~~~~~~~~~~~~^^^^^^^^^
  File "C:\Workspace\FrankTheLocalLLM-main\.venv\Lib\site-packages\billiard\pool.py", line 396, in workloop
    self._ensure_messages_consumed(completed=completed)
    ~~~~~~~~~~~~~~~~~~~~~~~~~~~~~~^^^^^^^^^^^^^^^^^^^^^
  File "C:\Workspace\FrankTheLocalLLM-main\.venv\Lib\site-packages\billiard\pool.py", line 406, in _ensure_messages_consumed
    if self.on_ready_counter.value >= completed:
       ^^^^^^^^^^^^^^^^^^^^^^^^^^^
  File "<string>", line 7, in getvalue
OSError: [WinError 6] The handle is invalid
[2025-08-21 14:29:26,476: ERROR/SpawnPoolWorker-14] Pool process <billiard.pool.Worker object at 0x000001DABA1EE120> error: OSError(9, 'The handle is invalid', None, 6, None)
Traceback (most recent call last):
  File "C:\Workspace\FrankTheLocalLLM-main\.venv\Lib\site-packages\billiard\pool.py", line 473, in receive
    ready, req = _receive(1.0)
                 ~~~~~~~~^^^^^
  File "C:\Workspace\FrankTheLocalLLM-main\.venv\Lib\site-packages\billiard\pool.py", line 445, in _recv
    return True, loads(get_payload())
                       ~~~~~~~~~~~^^
  File "C:\Workspace\FrankTheLocalLLM-main\.venv\Lib\site-packages\billiard\queues.py", line 394, in get_payload
    with self._rlock:
         ^^^^^^^^^^^
  File "C:\Workspace\FrankTheLocalLLM-main\.venv\Lib\site-packages\billiard\synchronize.py", line 115, in __enter__
    return self._semlock.__enter__()
           ~~~~~~~~~~~~~~~~~~~~~~~^^
PermissionError: [WinError 5] Access is denied

During handling of the above exception, another exception occurred:

Traceback (most recent call last):
  File "C:\Workspace\FrankTheLocalLLM-main\.venv\Lib\site-packages\billiard\pool.py", line 351, in workloop
    req = wait_for_job()
  File "C:\Workspace\FrankTheLocalLLM-main\.venv\Lib\site-packages\billiard\pool.py", line 480, in receive
    raise SystemExit(EX_FAILURE)
SystemExit: 1

During handling of the above exception, another exception occurred:

Traceback (most recent call last):
  File "C:\Workspace\FrankTheLocalLLM-main\.venv\Lib\site-packages\billiard\pool.py", line 292, in __call__
    sys.exit(self.workloop(pid=pid))
             ~~~~~~~~~~~~~^^^^^^^^^
  File "C:\Workspace\FrankTheLocalLLM-main\.venv\Lib\site-packages\billiard\pool.py", line 396, in workloop
    self._ensure_messages_consumed(completed=completed)
    ~~~~~~~~~~~~~~~~~~~~~~~~~~~~~~^^^^^^^^^^^^^^^^^^^^^
  File "C:\Workspace\FrankTheLocalLLM-main\.venv\Lib\site-packages\billiard\pool.py", line 406, in _ensure_messages_consumed
    if self.on_ready_counter.value >= completed:
       ^^^^^^^^^^^^^^^^^^^^^^^^^^^
  File "<string>", line 7, in getvalue
OSError: [WinError 6] The handle is invalid
[2025-08-21 14:29:26,480: ERROR/SpawnPoolWorker-15] Pool process <billiard.pool.Worker object at 0x000001DF3F0DE120> error: PermissionError(13, 'Access is denied', None, 5, None)
Traceback (most recent call last):
  File "C:\Workspace\FrankTheLocalLLM-main\.venv\Lib\site-packages\billiard\pool.py", line 473, in receive
    ready, req = _receive(1.0)
                 ~~~~~~~~^^^^^
  File "C:\Workspace\FrankTheLocalLLM-main\.venv\Lib\site-packages\billiard\pool.py", line 445, in _recv
    return True, loads(get_payload())
                       ~~~~~~~~~~~^^
  File "C:\Workspace\FrankTheLocalLLM-main\.venv\Lib\site-packages\billiard\queues.py", line 394, in get_payload
    with self._rlock:
         ^^^^^^^^^^^
  File "C:\Workspace\FrankTheLocalLLM-main\.venv\Lib\site-packages\billiard\synchronize.py", line 115, in __enter__
    return self._semlock.__enter__()
           ~~~~~~~~~~~~~~~~~~~~~~~^^
PermissionError: [WinError 5] Access is denied

During handling of the above exception, another exception occurred:

Traceback (most recent call last):
  File "C:\Workspace\FrankTheLocalLLM-main\.venv\Lib\site-packages\billiard\pool.py", line 351, in workloop
    req = wait_for_job()
  File "C:\Workspace\FrankTheLocalLLM-main\.venv\Lib\site-packages\billiard\pool.py", line 480, in receive
    raise SystemExit(EX_FAILURE)
SystemExit: 1

During handling of the above exception, another exception occurred:

Traceback (most recent call last):
  File "C:\Workspace\FrankTheLocalLLM-main\.venv\Lib\site-packages\billiard\pool.py", line 292, in __call__
    sys.exit(self.workloop(pid=pid))
             ~~~~~~~~~~~~~^^^^^^^^^
  File "C:\Workspace\FrankTheLocalLLM-main\.venv\Lib\site-packages\billiard\pool.py", line 396, in workloop
    self._ensure_messages_consumed(completed=completed)
    ~~~~~~~~~~~~~~~~~~~~~~~~~~~~~~^^^^^^^^^^^^^^^^^^^^^
  File "C:\Workspace\FrankTheLocalLLM-main\.venv\Lib\site-packages\billiard\pool.py", line 406, in _ensure_messages_consumed
    if self.on_ready_counter.value >= completed:
       ^^^^^^^^^^^^^^^^^^^^^^^^^^^
  File "<string>", line 3, in getvalue
PermissionError: [WinError 5] Access is denied
[2025-08-21 14:29:26,480: ERROR/SpawnPoolWorker-15] Pool process <billiard.pool.Worker object at 0x000001DF3F0DE120> error: PermissionError(13, 'Access is denied', None, 5, None)
Traceback (most recent call last):
  File "C:\Workspace\FrankTheLocalLLM-main\.venv\Lib\site-packages\billiard\pool.py", line 473, in receive
    ready, req = _receive(1.0)
                 ~~~~~~~~^^^^^
  File "C:\Workspace\FrankTheLocalLLM-main\.venv\Lib\site-packages\billiard\pool.py", line 445, in _recv
    return True, loads(get_payload())
                       ~~~~~~~~~~~^^
  File "C:\Workspace\FrankTheLocalLLM-main\.venv\Lib\site-packages\billiard\queues.py", line 394, in get_payload
    with self._rlock:
         ^^^^^^^^^^^
  File "C:\Workspace\FrankTheLocalLLM-main\.venv\Lib\site-packages\billiard\synchronize.py", line 115, in __enter__
    return self._semlock.__enter__()
           ~~~~~~~~~~~~~~~~~~~~~~~^^
PermissionError: [WinError 5] Access is denied

During handling of the above exception, another exception occurred:

Traceback (most recent call last):
  File "C:\Workspace\FrankTheLocalLLM-main\.venv\Lib\site-packages\billiard\pool.py", line 351, in workloop
    req = wait_for_job()
  File "C:\Workspace\FrankTheLocalLLM-main\.venv\Lib\site-packages\billiard\pool.py", line 480, in receive
    raise SystemExit(EX_FAILURE)
SystemExit: 1

During handling of the above exception, another exception occurred:

Traceback (most recent call last):
  File "C:\Workspace\FrankTheLocalLLM-main\.venv\Lib\site-packages\billiard\pool.py", line 292, in __call__
    sys.exit(self.workloop(pid=pid))
             ~~~~~~~~~~~~~^^^^^^^^^
  File "C:\Workspace\FrankTheLocalLLM-main\.venv\Lib\site-packages\billiard\pool.py", line 396, in workloop
    self._ensure_messages_consumed(completed=completed)
    ~~~~~~~~~~~~~~~~~~~~~~~~~~~~~~^^^^^^^^^^^^^^^^^^^^^
  File "C:\Workspace\FrankTheLocalLLM-main\.venv\Lib\site-packages\billiard\pool.py", line 406, in _ensure_messages_consumed
    if self.on_ready_counter.value >= completed:
       ^^^^^^^^^^^^^^^^^^^^^^^^^^^
  File "<string>", line 3, in getvalue
PermissionError: [WinError 5] Access is denied
[2025-08-21 14:29:26,877: ERROR/MainProcess] Process 'SpawnPoolWorker-15' pid:20376 exited with 'exitcode 1'
[2025-08-21 14:29:26,888: ERROR/MainProcess] Process 'SpawnPoolWorker-14' pid:17528 exited with 'exitcode 1'
[2025-08-21 14:29:30,493: ERROR/SpawnPoolWorker-17] Pool process <billiard.pool.Worker object at 0x00000205FFE7E120> error: OSError(9, 'The handle is invalid', None, 6, None)
Traceback (most recent call last):
  File "C:\Workspace\FrankTheLocalLLM-main\.venv\Lib\site-packages\billiard\pool.py", line 473, in receive
    ready, req = _receive(1.0)
                 ~~~~~~~~^^^^^
  File "C:\Workspace\FrankTheLocalLLM-main\.venv\Lib\site-packages\billiard\pool.py", line 445, in _recv
    return True, loads(get_payload())
                       ~~~~~~~~~~~^^
  File "C:\Workspace\FrankTheLocalLLM-main\.venv\Lib\site-packages\billiard\queues.py", line 394, in get_payload
    with self._rlock:
         ^^^^^^^^^^^
  File "C:\Workspace\FrankTheLocalLLM-main\.venv\Lib\site-packages\billiard\synchronize.py", line 115, in __enter__
    return self._semlock.__enter__()
           ~~~~~~~~~~~~~~~~~~~~~~~^^
PermissionError: [WinError 5] Access is denied

During handling of the above exception, another exception occurred:

Traceback (most recent call last):
  File "C:\Workspace\FrankTheLocalLLM-main\.venv\Lib\site-packages\billiard\pool.py", line 351, in workloop
    req = wait_for_job()
  File "C:\Workspace\FrankTheLocalLLM-main\.venv\Lib\site-packages\billiard\pool.py", line 480, in receive
    raise SystemExit(EX_FAILURE)
SystemExit: 1

During handling of the above exception, another exception occurred:

Traceback (most recent call last):
  File "C:\Workspace\FrankTheLocalLLM-main\.venv\Lib\site-packages\billiard\pool.py", line 292, in __call__
    sys.exit(self.workloop(pid=pid))
             ~~~~~~~~~~~~~^^^^^^^^^
  File "C:\Workspace\FrankTheLocalLLM-main\.venv\Lib\site-packages\billiard\pool.py", line 396, in workloop
    self._ensure_messages_consumed(completed=completed)
    ~~~~~~~~~~~~~~~~~~~~~~~~~~~~~~^^^^^^^^^^^^^^^^^^^^^
  File "C:\Workspace\FrankTheLocalLLM-main\.venv\Lib\site-packages\billiard\pool.py", line 406, in _ensure_messages_consumed
    if self.on_ready_counter.value >= completed:
       ^^^^^^^^^^^^^^^^^^^^^^^^^^^
  File "<string>", line 7, in getvalue
OSError: [WinError 6] The handle is invalid
[2025-08-21 14:29:30,493: ERROR/SpawnPoolWorker-17] Pool process <billiard.pool.Worker object at 0x00000205FFE7E120> error: OSError(9, 'The handle is invalid', None, 6, None)
Traceback (most recent call last):
  File "C:\Workspace\FrankTheLocalLLM-main\.venv\Lib\site-packages\billiard\pool.py", line 473, in receive
    ready, req = _receive(1.0)
                 ~~~~~~~~^^^^^
  File "C:\Workspace\FrankTheLocalLLM-main\.venv\Lib\site-packages\billiard\pool.py", line 445, in _recv
    return True, loads(get_payload())
                       ~~~~~~~~~~~^^
  File "C:\Workspace\FrankTheLocalLLM-main\.venv\Lib\site-packages\billiard\queues.py", line 394, in get_payload
    with self._rlock:
         ^^^^^^^^^^^
  File "C:\Workspace\FrankTheLocalLLM-main\.venv\Lib\site-packages\billiard\synchronize.py", line 115, in __enter__
    return self._semlock.__enter__()
           ~~~~~~~~~~~~~~~~~~~~~~~^^
PermissionError: [WinError 5] Access is denied

During handling of the above exception, another exception occurred:

Traceback (most recent call last):
  File "C:\Workspace\FrankTheLocalLLM-main\.venv\Lib\site-packages\billiard\pool.py", line 351, in workloop
    req = wait_for_job()
  File "C:\Workspace\FrankTheLocalLLM-main\.venv\Lib\site-packages\billiard\pool.py", line 480, in receive
    raise SystemExit(EX_FAILURE)
SystemExit: 1

During handling of the above exception, another exception occurred:

Traceback (most recent call last):
  File "C:\Workspace\FrankTheLocalLLM-main\.venv\Lib\site-packages\billiard\pool.py", line 292, in __call__
    sys.exit(self.workloop(pid=pid))
             ~~~~~~~~~~~~~^^^^^^^^^
  File "C:\Workspace\FrankTheLocalLLM-main\.venv\Lib\site-packages\billiard\pool.py", line 396, in workloop
    self._ensure_messages_consumed(completed=completed)
    ~~~~~~~~~~~~~~~~~~~~~~~~~~~~~~^^^^^^^^^^^^^^^^^^^^^
  File "C:\Workspace\FrankTheLocalLLM-main\.venv\Lib\site-packages\billiard\pool.py", line 406, in _ensure_messages_consumed
    if self.on_ready_counter.value >= completed:
       ^^^^^^^^^^^^^^^^^^^^^^^^^^^
  File "<string>", line 7, in getvalue
OSError: [WinError 6] The handle is invalid
[2025-08-21 14:29:30,903: ERROR/MainProcess] Process 'SpawnPoolWorker-17' pid:27100 exited with 'exitcode 1'
[2025-08-21 14:29:32,196: ERROR/MainProcess] consumer: Cannot connect to redis://localhost:6379/0: Error 10061 connecting to localhost:6379. No connection could be made because the target machine actively refused it..
Trying again in 6.00 seconds... (3/100)

[2025-08-21 14:29:42,280: ERROR/MainProcess] consumer: Cannot connect to redis://localhost:6379/0: Error 10061 connecting to localhost:6379. No connection could be made because the target machine actively refused it..
Trying again in 8.00 seconds... (4/100)

[2025-08-21 14:29:54,342: ERROR/MainProcess] consumer: Cannot connect to redis://localhost:6379/0: Error 10061 connecting to localhost:6379. No connection could be made because the target machine actively refused it..
Trying again in 10.00 seconds... (5/100)

[2025-08-21 14:30:08,381: ERROR/MainProcess] consumer: Cannot connect to redis://localhost:6379/0: Error 10061 connecting to localhost:6379. No connection could be made because the target machine actively refused it..
Trying again in 12.00 seconds... (6/100)

[2025-08-21 14:30:24,467: ERROR/MainProcess] consumer: Cannot connect to redis://localhost:6379/0: Error 10061 connecting to localhost:6379. No connection could be made because the target machine actively refused it..
Trying again in 14.00 seconds... (7/100)

[2025-08-21 14:30:42,532: ERROR/MainProcess] consumer: Cannot connect to redis://localhost:6379/0: Error 10061 connecting to localhost:6379. No connection could be made because the target machine actively refused it..
Trying again in 16.00 seconds... (8/100)

[2025-08-21 14:31:02,585: ERROR/MainProcess] consumer: Cannot connect to redis://localhost:6379/0: Error 10061 connecting to localhost:6379. No connection could be made because the target machine actively refused it..
Trying again in 18.00 seconds... (9/100)

[2025-08-21 14:31:24,690: ERROR/MainProcess] consumer: Cannot connect to redis://localhost:6379/0: Error 10061 connecting to localhost:6379. No connection could be made because the target machine actively refused it..
Trying again in 20.00 seconds... (10/100)

[2025-08-21 14:31:48,792: ERROR/MainProcess] consumer: Cannot connect to redis://localhost:6379/0: Error 10061 connecting to localhost:6379. No connection could be made because the target machine actively refused it..
Trying again in 22.00 seconds... (11/100)

[2025-08-21 14:32:14,855: ERROR/MainProcess] consumer: Cannot connect to redis://localhost:6379/0: Error 10061 connecting to localhost:6379. No connection could be made because the target machine actively refused it..
Trying again in 24.00 seconds... (12/100)

[2025-08-21 14:32:42,927: ERROR/MainProcess] consumer: Cannot connect to redis://localhost:6379/0: Error 10061 connecting to localhost:6379. No connection could be made because the target machine actively refused it..
Trying again in 26.00 seconds... (13/100)

[2025-08-21 14:33:13,031: ERROR/MainProcess] consumer: Cannot connect to redis://localhost:6379/0: Error 10061 connecting to localhost:6379. No connection could be made because the target machine actively refused it..
Trying again in 28.00 seconds... (14/100)

[2025-08-21 14:33:45,140: ERROR/MainProcess] consumer: Cannot connect to redis://localhost:6379/0: Error 10061 connecting to localhost:6379. No connection could be made because the target machine actively refused it..
Trying again in 30.00 seconds... (15/100)

[2025-08-21 14:34:19,255: ERROR/MainProcess] consumer: Cannot connect to redis://localhost:6379/0: Error 10061 connecting to localhost:6379. No connection could be made because the target machine actively refused it..
Trying again in 32.00 seconds... (16/100)

[2025-08-21 14:34:55,362: ERROR/MainProcess] consumer: Cannot connect to redis://localhost:6379/0: Error 10061 connecting to localhost:6379. No connection could be made because the target machine actively refused it..
Trying again in 32.00 seconds... (16/100)

[2025-08-21 14:35:31,472: ERROR/MainProcess] consumer: Cannot connect to redis://localhost:6379/0: Error 10061 connecting to localhost:6379. No connection could be made because the target machine actively refused it..
Trying again in 32.00 seconds... (16/100)

[2025-08-21 14:36:07,541: ERROR/MainProcess] consumer: Cannot connect to redis://localhost:6379/0: Error 10061 connecting to localhost:6379. No connection could be made because the target machine actively refused it..
Trying again in 32.00 seconds... (16/100)

[2025-08-21 14:36:43,664: ERROR/MainProcess] consumer: Cannot connect to redis://localhost:6379/0: Error 10061 connecting to localhost:6379. No connection could be made because the target machine actively refused it..
Trying again in 32.00 seconds... (16/100)

[2025-08-21 14:37:19,764: ERROR/MainProcess] consumer: Cannot connect to redis://localhost:6379/0: Error 10061 connecting to localhost:6379. No connection could be made because the target machine actively refused it..
Trying again in 32.00 seconds... (16/100)

[2025-08-21 14:37:55,880: ERROR/MainProcess] consumer: Cannot connect to redis://localhost:6379/0: Error 10061 connecting to localhost:6379. No connection could be made because the target machine actively refused it..
Trying again in 32.00 seconds... (16/100)

[2025-08-21 14:38:31,961: ERROR/MainProcess] consumer: Cannot connect to redis://localhost:6379/0: Error 10061 connecting to localhost:6379. No connection could be made because the target machine actively refused it..
Trying again in 32.00 seconds... (16/100)

[2025-08-21 14:39:08,071: ERROR/MainProcess] consumer: Cannot connect to redis://localhost:6379/0: Error 10061 connecting to localhost:6379. No connection could be made because the target machine actively refused it..
Trying again in 32.00 seconds... (16/100)

[2025-08-21 14:39:44,171: ERROR/MainProcess] consumer: Cannot connect to redis://localhost:6379/0: Error 10061 connecting to localhost:6379. No connection could be made because the target machine actively refused it..
Trying again in 32.00 seconds... (16/100)

[2025-08-21 14:40:20,276: ERROR/MainProcess] consumer: Cannot connect to redis://localhost:6379/0: Error 10061 connecting to localhost:6379. No connection could be made because the target machine actively refused it..
Trying again in 32.00 seconds... (16/100)

[2025-08-21 14:40:56,389: ERROR/MainProcess] consumer: Cannot connect to redis://localhost:6379/0: Error 10061 connecting to localhost:6379. No connection could be made because the target machine actively refused it..
Trying again in 32.00 seconds... (16/100)

[2025-08-21 14:41:32,473: ERROR/MainProcess] consumer: Cannot connect to redis://localhost:6379/0: Error 10061 connecting to localhost:6379. No connection could be made because the target machine actively refused it..
Trying again in 32.00 seconds... (16/100)

[2025-08-21 14:42:08,532: ERROR/MainProcess] consumer: Cannot connect to redis://localhost:6379/0: Error 10061 connecting to localhost:6379. No connection could be made because the target machine actively refused it..
Trying again in 32.00 seconds... (16/100)

[2025-08-21 14:42:44,621: ERROR/MainProcess] consumer: Cannot connect to redis://localhost:6379/0: Error 10061 connecting to localhost:6379. No connection could be made because the target machine actively refused it..
Trying again in 32.00 seconds... (16/100)

[2025-08-21 14:43:20,712: ERROR/MainProcess] consumer: Cannot connect to redis://localhost:6379/0: Error 10061 connecting to localhost:6379. No connection could be made because the target machine actively refused it..
Trying again in 32.00 seconds... (16/100)

[2025-08-21 14:43:56,810: ERROR/MainProcess] consumer: Cannot connect to redis://localhost:6379/0: Error 10061 connecting to localhost:6379. No connection could be made because the target machine actively refused it..
Trying again in 32.00 seconds... (16/100)

[2025-08-21 14:44:32,902: ERROR/MainProcess] consumer: Cannot connect to redis://localhost:6379/0: Error 10061 connecting to localhost:6379. No connection could be made because the target machine actively refused it..
Trying again in 32.00 seconds... (16/100)

[2025-08-21 14:45:09,003: ERROR/MainProcess] consumer: Cannot connect to redis://localhost:6379/0: Error 10061 connecting to localhost:6379. No connection could be made because the target machine actively refused it..
Trying again in 32.00 seconds... (16/100)

[2025-08-21 14:45:45,099: ERROR/MainProcess] consumer: Cannot connect to redis://localhost:6379/0: Error 10061 connecting to localhost:6379. No connection could be made because the target machine actively refused it..
Trying again in 32.00 seconds... (16/100)

[2025-08-21 14:46:21,169: ERROR/MainProcess] consumer: Cannot connect to redis://localhost:6379/0: Error 10061 connecting to localhost:6379. No connection could be made because the target machine actively refused it..
Trying again in 32.00 seconds... (16/100)

[2025-08-21 14:46:57,265: ERROR/MainProcess] consumer: Cannot connect to redis://localhost:6379/0: Error 10061 connecting to localhost:6379. No connection could be made because the target machine actively refused it..
Trying again in 32.00 seconds... (16/100)

[2025-08-21 14:47:33,356: ERROR/MainProcess] consumer: Cannot connect to redis://localhost:6379/0: Error 10061 connecting to localhost:6379. No connection could be made because the target machine actively refused it..
Trying again in 32.00 seconds... (16/100)

[2025-08-21 14:48:09,449: ERROR/MainProcess] consumer: Cannot connect to redis://localhost:6379/0: Error 10061 connecting to localhost:6379. No connection could be made because the target machine actively refused it..
Trying again in 32.00 seconds... (16/100)

[2025-08-21 14:48:45,549: ERROR/MainProcess] consumer: Cannot connect to redis://localhost:6379/0: Error 10061 connecting to localhost:6379. No connection could be made because the target machine actively refused it..
Trying again in 32.00 seconds... (16/100)

[2025-08-21 14:49:21,672: ERROR/MainProcess] consumer: Cannot connect to redis://localhost:6379/0: Error 10061 connecting to localhost:6379. No connection could be made because the target machine actively refused it..
Trying again in 32.00 seconds... (16/100)

[2025-08-21 14:49:57,768: ERROR/MainProcess] consumer: Cannot connect to redis://localhost:6379/0: Error 10061 connecting to localhost:6379. No connection could be made because the target machine actively refused it..
Trying again in 32.00 seconds... (16/100)

[2025-08-21 14:50:33,851: ERROR/MainProcess] consumer: Cannot connect to redis://localhost:6379/0: Error 10061 connecting to localhost:6379. No connection could be made because the target machine actively refused it..
Trying again in 32.00 seconds... (16/100)

[2025-08-21 14:51:09,960: ERROR/MainProcess] consumer: Cannot connect to redis://localhost:6379/0: Error 10061 connecting to localhost:6379. No connection could be made because the target machine actively refused it..
Trying again in 32.00 seconds... (16/100)

[2025-08-21 14:51:46,017: ERROR/MainProcess] consumer: Cannot connect to redis://localhost:6379/0: Error 10061 connecting to localhost:6379. No connection could be made because the target machine actively refused it..
Trying again in 32.00 seconds... (16/100)

[2025-08-21 14:52:22,125: ERROR/MainProcess] consumer: Cannot connect to redis://localhost:6379/0: Error 10061 connecting to localhost:6379. No connection could be made because the target machine actively refused it..
Trying again in 32.00 seconds... (16/100)

[2025-08-21 14:52:58,197: ERROR/MainProcess] consumer: Cannot connect to redis://localhost:6379/0: Error 10061 connecting to localhost:6379. No connection could be made because the target machine actively refused it..
Trying again in 32.00 seconds... (16/100)

[2025-08-21 14:53:34,314: ERROR/MainProcess] consumer: Cannot connect to redis://localhost:6379/0: Error 10061 connecting to localhost:6379. No connection could be made because the target machine actively refused it..
Trying again in 32.00 seconds... (16/100)

[2025-08-21 14:54:10,387: ERROR/MainProcess] consumer: Cannot connect to redis://localhost:6379/0: Error 10061 connecting to localhost:6379. No connection could be made because the target machine actively refused it..
Trying again in 32.00 seconds... (16/100)

[2025-08-21 14:54:46,469: ERROR/MainProcess] consumer: Cannot connect to redis://localhost:6379/0: Error 10061 connecting to localhost:6379. No connection could be made because the target machine actively refused it..
Trying again in 32.00 seconds... (16/100)

[2025-08-21 14:55:22,516: ERROR/MainProcess] consumer: Cannot connect to redis://localhost:6379/0: Error 10061 connecting to localhost:6379. No connection could be made because the target machine actively refused it..
Trying again in 32.00 seconds... (16/100)

[2025-08-21 14:55:58,599: ERROR/MainProcess] consumer: Cannot connect to redis://localhost:6379/0: Error 10061 connecting to localhost:6379. No connection could be made because the target machine actively refused it..
Trying again in 32.00 seconds... (16/100)

[2025-08-21 14:56:34,693: ERROR/MainProcess] consumer: Cannot connect to redis://localhost:6379/0: Error 10061 connecting to localhost:6379. No connection could be made because the target machine actively refused it..
Trying again in 32.00 seconds... (16/100)

[2025-08-21 14:57:10,821: ERROR/MainProcess] consumer: Cannot connect to redis://localhost:6379/0: Error 10061 connecting to localhost:6379. No connection could be made because the target machine actively refused it..
Trying again in 32.00 seconds... (16/100)

[2025-08-21 14:57:46,931: ERROR/MainProcess] consumer: Cannot connect to redis://localhost:6379/0: Error 10061 connecting to localhost:6379. No connection could be made because the target machine actively refused it..
Trying again in 32.00 seconds... (16/100)

[2025-08-21 14:58:23,015: ERROR/MainProcess] consumer: Cannot connect to redis://localhost:6379/0: Error 10061 connecting to localhost:6379. No connection could be made because the target machine actively refused it..
Trying again in 32.00 seconds... (16/100)

[2025-08-21 14:58:59,076: ERROR/MainProcess] consumer: Cannot connect to redis://localhost:6379/0: Error 10061 connecting to localhost:6379. No connection could be made because the target machine actively refused it..
Trying again in 32.00 seconds... (16/100)

[2025-08-21 14:59:35,154: ERROR/MainProcess] consumer: Cannot connect to redis://localhost:6379/0: Error 10061 connecting to localhost:6379. No connection could be made because the target machine actively refused it..
Trying again in 32.00 seconds... (16/100)

[2025-08-21 15:00:11,239: ERROR/MainProcess] consumer: Cannot connect to redis://localhost:6379/0: Error 10061 connecting to localhost:6379. No connection could be made because the target machine actively refused it..
Trying again in 32.00 seconds... (16/100)

[2025-08-21 15:00:47,342: ERROR/MainProcess] consumer: Cannot connect to redis://localhost:6379/0: Error 10061 connecting to localhost:6379. No connection could be made because the target machine actively refused it..
Trying again in 32.00 seconds... (16/100)

[2025-08-21 15:01:23,424: ERROR/MainProcess] consumer: Cannot connect to redis://localhost:6379/0: Error 10061 connecting to localhost:6379. No connection could be made because the target machine actively refused it..
Trying again in 32.00 seconds... (16/100)

[2025-08-21 15:01:59,528: ERROR/MainProcess] consumer: Cannot connect to redis://localhost:6379/0: Error 10061 connecting to localhost:6379. No connection could be made because the target machine actively refused it..
Trying again in 32.00 seconds... (16/100)

[2025-08-21 15:02:35,623: ERROR/MainProcess] consumer: Cannot connect to redis://localhost:6379/0: Error 10061 connecting to localhost:6379. No connection could be made because the target machine actively refused it..
Trying again in 32.00 seconds... (16/100)

[2025-08-21 15:03:11,700: ERROR/MainProcess] consumer: Cannot connect to redis://localhost:6379/0: Error 10061 connecting to localhost:6379. No connection could be made because the target machine actively refused it..
Trying again in 32.00 seconds... (16/100)

[2025-08-21 15:03:47,787: ERROR/MainProcess] consumer: Cannot connect to redis://localhost:6379/0: Error 10061 connecting to localhost:6379. No connection could be made because the target machine actively refused it..
Trying again in 32.00 seconds... (16/100)

[2025-08-21 15:04:23,852: ERROR/MainProcess] consumer: Cannot connect to redis://localhost:6379/0: Error 10061 connecting to localhost:6379. No connection could be made because the target machine actively refused it..
Trying again in 32.00 seconds... (16/100)

[2025-08-21 15:04:59,916: ERROR/MainProcess] consumer: Cannot connect to redis://localhost:6379/0: Error 10061 connecting to localhost:6379. No connection could be made because the target machine actively refused it..
Trying again in 32.00 seconds... (16/100)

[2025-08-21 15:05:35,983: ERROR/MainProcess] consumer: Cannot connect to redis://localhost:6379/0: Error 10061 connecting to localhost:6379. No connection could be made because the target machine actively refused it..
Trying again in 32.00 seconds... (16/100)

[2025-08-21 15:06:12,034: ERROR/MainProcess] consumer: Cannot connect to redis://localhost:6379/0: Error 10061 connecting to localhost:6379. No connection could be made because the target machine actively refused it..
Trying again in 32.00 seconds... (16/100)

[2025-08-21 15:06:48,135: ERROR/MainProcess] consumer: Cannot connect to redis://localhost:6379/0: Error 10061 connecting to localhost:6379. No connection could be made because the target machine actively refused it..
Trying again in 32.00 seconds... (16/100)

[2025-08-21 15:07:24,203: ERROR/MainProcess] consumer: Cannot connect to redis://localhost:6379/0: Error 10061 connecting to localhost:6379. No connection could be made because the target machine actively refused it..
Trying again in 32.00 seconds... (16/100)

[2025-08-21 15:08:00,269: ERROR/MainProcess] consumer: Cannot connect to redis://localhost:6379/0: Error 10061 connecting to localhost:6379. No connection could be made because the target machine actively refused it..
Trying again in 32.00 seconds... (16/100)

[2025-08-21 15:08:36,368: ERROR/MainProcess] consumer: Cannot connect to redis://localhost:6379/0: Error 10061 connecting to localhost:6379. No connection could be made because the target machine actively refused it..
Trying again in 32.00 seconds... (16/100)

[2025-08-21 15:09:12,449: ERROR/MainProcess] consumer: Cannot connect to redis://localhost:6379/0: Error 10061 connecting to localhost:6379. No connection could be made because the target machine actively refused it..
Trying again in 32.00 seconds... (16/100)

[2025-08-21 15:09:48,553: ERROR/MainProcess] consumer: Cannot connect to redis://localhost:6379/0: Error 10061 connecting to localhost:6379. No connection could be made because the target machine actively refused it..
Trying again in 32.00 seconds... (16/100)

[2025-08-21 15:10:24,656: ERROR/MainProcess] consumer: Cannot connect to redis://localhost:6379/0: Error 10061 connecting to localhost:6379. No connection could be made because the target machine actively refused it..
Trying again in 32.00 seconds... (16/100)

[2025-08-21 15:11:00,757: ERROR/MainProcess] consumer: Cannot connect to redis://localhost:6379/0: Error 10061 connecting to localhost:6379. No connection could be made because the target machine actively refused it..
Trying again in 32.00 seconds... (16/100)

[2025-08-21 15:11:36,815: ERROR/MainProcess] consumer: Cannot connect to redis://localhost:6379/0: Error 10061 connecting to localhost:6379. No connection could be made because the target machine actively refused it..
Trying again in 32.00 seconds... (16/100)

[2025-08-21 15:12:12,887: ERROR/MainProcess] consumer: Cannot connect to redis://localhost:6379/0: Error 10061 connecting to localhost:6379. No connection could be made because the target machine actively refused it..
Trying again in 32.00 seconds... (16/100)

[2025-08-21 15:12:48,959: ERROR/MainProcess] consumer: Cannot connect to redis://localhost:6379/0: Error 10061 connecting to localhost:6379. No connection could be made because the target machine actively refused it..
Trying again in 32.00 seconds... (16/100)

[2025-08-21 15:13:25,037: ERROR/MainProcess] consumer: Cannot connect to redis://localhost:6379/0: Error 10061 connecting to localhost:6379. No connection could be made because the target machine actively refused it..
Trying again in 32.00 seconds... (16/100)

[2025-08-21 15:14:01,149: ERROR/MainProcess] consumer: Cannot connect to redis://localhost:6379/0: Error 10061 connecting to localhost:6379. No connection could be made because the target machine actively refused it..
Trying again in 32.00 seconds... (16/100)

[2025-08-21 15:14:37,228: ERROR/MainProcess] consumer: Cannot connect to redis://localhost:6379/0: Error 10061 connecting to localhost:6379. No connection could be made because the target machine actively refused it..
Trying again in 32.00 seconds... (16/100)

[2025-08-21 15:15:13,317: ERROR/MainProcess] consumer: Cannot connect to redis://localhost:6379/0: Error 10061 connecting to localhost:6379. No connection could be made because the target machine actively refused it..
Trying again in 32.00 seconds... (16/100)

[2025-08-21 15:15:49,387: ERROR/MainProcess] consumer: Cannot connect to redis://localhost:6379/0: Error 10061 connecting to localhost:6379. No connection could be made because the target machine actively refused it..
Trying again in 32.00 seconds... (16/100)

[2025-08-21 15:16:25,442: ERROR/MainProcess] consumer: Cannot connect to redis://localhost:6379/0: Error 10061 connecting to localhost:6379. No connection could be made because the target machine actively refused it..
Trying again in 32.00 seconds... (16/100)

[2025-08-21 15:17:01,513: ERROR/MainProcess] consumer: Cannot connect to redis://localhost:6379/0: Error 10061 connecting to localhost:6379. No connection could be made because the target machine actively refused it..
Trying again in 32.00 seconds... (16/100)

[2025-08-21 15:17:37,581: ERROR/MainProcess] consumer: Cannot connect to redis://localhost:6379/0: Error 10061 connecting to localhost:6379. No connection could be made because the target machine actively refused it..
Trying again in 32.00 seconds... (16/100)

[2025-08-21 15:18:13,666: ERROR/MainProcess] consumer: Cannot connect to redis://localhost:6379/0: Error 10061 connecting to localhost:6379. No connection could be made because the target machine actively refused it..
Trying again in 32.00 seconds... (16/100)

[2025-08-21 15:18:49,751: ERROR/MainProcess] consumer: Cannot connect to redis://localhost:6379/0: Error 10061 connecting to localhost:6379. No connection could be made because the target machine actively refused it..
Trying again in 32.00 seconds... (16/100)

[2025-08-21 15:19:25,815: ERROR/MainProcess] consumer: Cannot connect to redis://localhost:6379/0: Error 10061 connecting to localhost:6379. No connection could be made because the target machine actively refused it..
Trying again in 32.00 seconds... (16/100)

[2025-08-21 15:20:01,911: ERROR/MainProcess] consumer: Cannot connect to redis://localhost:6379/0: Error 10061 connecting to localhost:6379. No connection could be made because the target machine actively refused it..
Trying again in 32.00 seconds... (16/100)

[2025-08-21 15:20:37,991: ERROR/MainProcess] consumer: Cannot connect to redis://localhost:6379/0: Error 10061 connecting to localhost:6379. No connection could be made because the target machine actively refused it..
Trying again in 32.00 seconds... (16/100)

[2025-08-21 15:21:14,110: ERROR/MainProcess] consumer: Cannot connect to redis://localhost:6379/0: Error 10061 connecting to localhost:6379. No connection could be made because the target machine actively refused it..
Trying again in 32.00 seconds... (16/100)

[2025-08-21 15:21:50,210: ERROR/MainProcess] consumer: Cannot connect to redis://localhost:6379/0: Error 10061 connecting to localhost:6379. No connection could be made because the target machine actively refused it..
Trying again in 32.00 seconds... (16/100)

[2025-08-21 15:22:26,309: ERROR/MainProcess] consumer: Cannot connect to redis://localhost:6379/0: Error 10061 connecting to localhost:6379. No connection could be made because the target machine actively refused it..
Trying again in 32.00 seconds... (16/100)

[2025-08-21 15:23:02,415: ERROR/MainProcess] consumer: Cannot connect to redis://localhost:6379/0: Error 10061 connecting to localhost:6379. No connection could be made because the target machine actively refused it..
Trying again in 32.00 seconds... (16/100)

[2025-08-21 15:23:38,479: ERROR/MainProcess] consumer: Cannot connect to redis://localhost:6379/0: Error 10061 connecting to localhost:6379. No connection could be made because the target machine actively refused it..
Trying again in 32.00 seconds... (16/100)

[2025-08-21 15:24:14,554: ERROR/MainProcess] consumer: Cannot connect to redis://localhost:6379/0: Error 10061 connecting to localhost:6379. No connection could be made because the target machine actively refused it..
Trying again in 32.00 seconds... (16/100)

[2025-08-21 15:24:50,632: ERROR/MainProcess] consumer: Cannot connect to redis://localhost:6379/0: Error 10061 connecting to localhost:6379. No connection could be made because the target machine actively refused it..
Trying again in 32.00 seconds... (16/100)

[2025-08-21 15:25:26,697: CRITICAL/MainProcess] Unrecoverable error: OperationalError('Error 10061 connecting to localhost:6379. No connection could be made because the target machine actively refused it.')
Traceback (most recent call last):
  File "C:\Workspace\FrankTheLocalLLM-main\.venv\Lib\site-packages\kombu\transport\virtual\base.py", line 951, in create_channel
    return self._avail_channels.pop()
           ~~~~~~~~~~~~~~~~~~~~~~~~^^
IndexError: pop from empty list

During handling of the above exception, another exception occurred:

Traceback (most recent call last):
  File "C:\Workspace\FrankTheLocalLLM-main\.venv\Lib\site-packages\redis\connection.py", line 389, in connect_check_health
    sock = self.retry.call_with_retry(
        lambda: self._connect(), lambda error: self.disconnect(error)
    )
  File "C:\Workspace\FrankTheLocalLLM-main\.venv\Lib\site-packages\redis\retry.py", line 105, in call_with_retry
    return do()
  File "C:\Workspace\FrankTheLocalLLM-main\.venv\Lib\site-packages\redis\connection.py", line 390, in <lambda>
    lambda: self._connect(), lambda error: self.disconnect(error)
            ~~~~~~~~~~~~~^^
  File "C:\Workspace\FrankTheLocalLLM-main\.venv\Lib\site-packages\redis\connection.py", line 803, in _connect
    raise err
  File "C:\Workspace\FrankTheLocalLLM-main\.venv\Lib\site-packages\redis\connection.py", line 787, in _connect
    sock.connect(socket_address)
    ~~~~~~~~~~~~^^^^^^^^^^^^^^^^
ConnectionRefusedError: [WinError 10061] No connection could be made because the target machine actively refused it

During handling of the above exception, another exception occurred:

Traceback (most recent call last):
  File "C:\Workspace\FrankTheLocalLLM-main\.venv\Lib\site-packages\kombu\connection.py", line 472, in _reraise_as_library_errors
    yield
  File "C:\Workspace\FrankTheLocalLLM-main\.venv\Lib\site-packages\kombu\connection.py", line 459, in _ensure_connection
    return retry_over_time(
        self._connection_factory, self.recoverable_connection_errors,
    ...<2 lines>...
        callback, timeout=timeout
    )
  File "C:\Workspace\FrankTheLocalLLM-main\.venv\Lib\site-packages\kombu\utils\functional.py", line 318, in retry_over_time
    return fun(*args, **kwargs)
  File "C:\Workspace\FrankTheLocalLLM-main\.venv\Lib\site-packages\kombu\connection.py", line 938, in _connection_factory
    self._connection = self._establish_connection()
                       ~~~~~~~~~~~~~~~~~~~~~~~~~~^^
  File "C:\Workspace\FrankTheLocalLLM-main\.venv\Lib\site-packages\kombu\connection.py", line 860, in _establish_connection
    conn = self.transport.establish_connection()
  File "C:\Workspace\FrankTheLocalLLM-main\.venv\Lib\site-packages\kombu\transport\virtual\base.py", line 975, in establish_connection
    self._avail_channels.append(self.create_channel(self))
                                ~~~~~~~~~~~~~~~~~~~^^^^^^
  File "C:\Workspace\FrankTheLocalLLM-main\.venv\Lib\site-packages\kombu\transport\virtual\base.py", line 953, in create_channel
    channel = self.Channel(connection)
  File "C:\Workspace\FrankTheLocalLLM-main\.venv\Lib\site-packages\kombu\transport\redis.py", line 751, in __init__
    self.client.ping()
    ~~~~~~~~~~~~~~~~^^
  File "C:\Workspace\FrankTheLocalLLM-main\.venv\Lib\site-packages\redis\commands\core.py", line 1219, in ping
    return self.execute_command("PING", **kwargs)
           ~~~~~~~~~~~~~~~~~~~~^^^^^^^^^^^^^^^^^^
  File "C:\Workspace\FrankTheLocalLLM-main\.venv\Lib\site-packages\redis\client.py", line 621, in execute_command
    return self._execute_command(*args, **options)
           ~~~~~~~~~~~~~~~~~~~~~^^^^^^^^^^^^^^^^^^
  File "C:\Workspace\FrankTheLocalLLM-main\.venv\Lib\site-packages\redis\client.py", line 627, in _execute_command
    conn = self.connection or pool.get_connection()
                              ~~~~~~~~~~~~~~~~~~~^^
  File "C:\Workspace\FrankTheLocalLLM-main\.venv\Lib\site-packages\redis\utils.py", line 195, in wrapper
    return func(*args, **kwargs)
  File "C:\Workspace\FrankTheLocalLLM-main\.venv\Lib\site-packages\redis\connection.py", line 1533, in get_connection
    connection.connect()
    ~~~~~~~~~~~~~~~~~~^^
  File "C:\Workspace\FrankTheLocalLLM-main\.venv\Lib\site-packages\redis\connection.py", line 380, in connect
    self.connect_check_health(check_health=True)
    ~~~~~~~~~~~~~~~~~~~~~~~~~^^^^^^^^^^^^^^^^^^^
  File "C:\Workspace\FrankTheLocalLLM-main\.venv\Lib\site-packages\redis\connection.py", line 397, in connect_check_health
    raise ConnectionError(self._error_message(e))
redis.exceptions.ConnectionError: Error 10061 connecting to localhost:6379. No connection could be made because the target machine actively refused it.

The above exception was the direct cause of the following exception:

Traceback (most recent call last):
  File "C:\Workspace\FrankTheLocalLLM-main\.venv\Lib\site-packages\celery\worker\worker.py", line 203, in start
    self.blueprint.start(self)
    ~~~~~~~~~~~~~~~~~~~~^^^^^^
  File "C:\Workspace\FrankTheLocalLLM-main\.venv\Lib\site-packages\celery\bootsteps.py", line 116, in start
    step.start(parent)
    ~~~~~~~~~~^^^^^^^^
  File "C:\Workspace\FrankTheLocalLLM-main\.venv\Lib\site-packages\celery\bootsteps.py", line 365, in start
    return self.obj.start()
           ~~~~~~~~~~~~~~^^
  File "C:\Workspace\FrankTheLocalLLM-main\.venv\Lib\site-packages\celery\worker\consumer\consumer.py", line 341, in start
    blueprint.start(self)
    ~~~~~~~~~~~~~~~^^^^^^
  File "C:\Workspace\FrankTheLocalLLM-main\.venv\Lib\site-packages\celery\bootsteps.py", line 116, in start
    step.start(parent)
    ~~~~~~~~~~^^^^^^^^
  File "C:\Workspace\FrankTheLocalLLM-main\.venv\Lib\site-packages\celery\worker\consumer\connection.py", line 21, in start
    c.connection = c.connect()
                   ~~~~~~~~~^^
  File "C:\Workspace\FrankTheLocalLLM-main\.venv\Lib\site-packages\celery\worker\consumer\consumer.py", line 472, in connect
    conn = self.connection_for_read(heartbeat=self.amqheartbeat)
  File "C:\Workspace\FrankTheLocalLLM-main\.venv\Lib\site-packages\celery\worker\consumer\consumer.py", line 478, in connection_for_read
    return self.ensure_connected(
           ~~~~~~~~~~~~~~~~~~~~~^
        self.app.connection_for_read(heartbeat=heartbeat))
        ^^^^^^^^^^^^^^^^^^^^^^^^^^^^^^^^^^^^^^^^^^^^^^^^^^
  File "C:\Workspace\FrankTheLocalLLM-main\.venv\Lib\site-packages\celery\worker\consumer\consumer.py", line 530, in ensure_connected
    conn = conn.ensure_connection(
        _error_handler, self.app.conf.broker_connection_max_retries,
        callback=maybe_shutdown,
    )
  File "C:\Workspace\FrankTheLocalLLM-main\.venv\Lib\site-packages\kombu\connection.py", line 406, in ensure_connection
    self._ensure_connection(*args, **kwargs)
    ~~~~~~~~~~~~~~~~~~~~~~~^^^^^^^^^^^^^^^^^
  File "C:\Workspace\FrankTheLocalLLM-main\.venv\Lib\site-packages\kombu\connection.py", line 458, in _ensure_connection
    with ctx():
         ~~~^^
  File "C:\Python313\Lib\contextlib.py", line 162, in __exit__
    self.gen.throw(value)
    ~~~~~~~~~~~~~~^^^^^^^
  File "C:\Workspace\FrankTheLocalLLM-main\.venv\Lib\site-packages\kombu\connection.py", line 476, in _reraise_as_library_errors
    raise ConnectionError(str(exc)) from exc
kombu.exceptions.OperationalError: Error 10061 connecting to localhost:6379. No connection could be made because the target machine actively refused it.
[2025-08-21 15:25:26,853: ERROR/SpawnPoolWorker-10] Pool process <billiard.pool.Worker object at 0x000001EF1FE0E120> error: PermissionError(13, 'Access is denied', None, 5, None)
Traceback (most recent call last):
  File "C:\Workspace\FrankTheLocalLLM-main\.venv\Lib\site-packages\billiard\pool.py", line 473, in receive
    ready, req = _receive(1.0)
                 ~~~~~~~~^^^^^
  File "C:\Workspace\FrankTheLocalLLM-main\.venv\Lib\site-packages\billiard\pool.py", line 445, in _recv
    return True, loads(get_payload())
                       ~~~~~~~~~~~^^
  File "C:\Workspace\FrankTheLocalLLM-main\.venv\Lib\site-packages\billiard\queues.py", line 394, in get_payload
    with self._rlock:
         ^^^^^^^^^^^
  File "C:\Workspace\FrankTheLocalLLM-main\.venv\Lib\site-packages\billiard\synchronize.py", line 118, in __exit__
    return self._semlock.__exit__(*args)
           ~~~~~~~~~~~~~~~~~~~~~~^^^^^^^
OSError: [WinError 6] The handle is invalid

During handling of the above exception, another exception occurred:

Traceback (most recent call last):
  File "C:\Workspace\FrankTheLocalLLM-main\.venv\Lib\site-packages\billiard\pool.py", line 351, in workloop
    req = wait_for_job()
  File "C:\Workspace\FrankTheLocalLLM-main\.venv\Lib\site-packages\billiard\pool.py", line 480, in receive
    raise SystemExit(EX_FAILURE)
SystemExit: 1

During handling of the above exception, another exception occurred:

Traceback (most recent call last):
  File "C:\Workspace\FrankTheLocalLLM-main\.venv\Lib\site-packages\billiard\pool.py", line 292, in __call__
    sys.exit(self.workloop(pid=pid))
             ~~~~~~~~~~~~~^^^^^^^^^
  File "C:\Workspace\FrankTheLocalLLM-main\.venv\Lib\site-packages\billiard\pool.py", line 396, in workloop
    self._ensure_messages_consumed(completed=completed)
    ~~~~~~~~~~~~~~~~~~~~~~~~~~~~~~^^^^^^^^^^^^^^^^^^^^^
  File "C:\Workspace\FrankTheLocalLLM-main\.venv\Lib\site-packages\billiard\pool.py", line 406, in _ensure_messages_consumed
    if self.on_ready_counter.value >= completed:
       ^^^^^^^^^^^^^^^^^^^^^^^^^^^
  File "<string>", line 3, in getvalue
PermissionError: [WinError 5] Access is denied
[2025-08-21 15:25:26,853: ERROR/SpawnPoolWorker-11] Pool process <billiard.pool.Worker object at 0x0000024FAAABE120> error: PermissionError(13, 'Access is denied', None, 5, None)
Traceback (most recent call last):
  File "C:\Workspace\FrankTheLocalLLM-main\.venv\Lib\site-packages\billiard\pool.py", line 473, in receive
    ready, req = _receive(1.0)
                 ~~~~~~~~^^^^^
  File "C:\Workspace\FrankTheLocalLLM-main\.venv\Lib\site-packages\billiard\pool.py", line 445, in _recv
    return True, loads(get_payload())
                       ~~~~~~~~~~~^^
  File "C:\Workspace\FrankTheLocalLLM-main\.venv\Lib\site-packages\billiard\queues.py", line 394, in get_payload
    with self._rlock:
         ^^^^^^^^^^^
  File "C:\Workspace\FrankTheLocalLLM-main\.venv\Lib\site-packages\billiard\synchronize.py", line 118, in __exit__
    return self._semlock.__exit__(*args)
           ~~~~~~~~~~~~~~~~~~~~~~^^^^^^^
OSError: [WinError 6] The handle is invalid

During handling of the above exception, another exception occurred:

Traceback (most recent call last):
  File "C:\Workspace\FrankTheLocalLLM-main\.venv\Lib\site-packages\billiard\pool.py", line 351, in workloop
    req = wait_for_job()
  File "C:\Workspace\FrankTheLocalLLM-main\.venv\Lib\site-packages\billiard\pool.py", line 480, in receive
    raise SystemExit(EX_FAILURE)
SystemExit: 1

During handling of the above exception, another exception occurred:

Traceback (most recent call last):
  File "C:\Workspace\FrankTheLocalLLM-main\.venv\Lib\site-packages\billiard\pool.py", line 292, in __call__
    sys.exit(self.workloop(pid=pid))
             ~~~~~~~~~~~~~^^^^^^^^^
  File "C:\Workspace\FrankTheLocalLLM-main\.venv\Lib\site-packages\billiard\pool.py", line 396, in workloop
    self._ensure_messages_consumed(completed=completed)
    ~~~~~~~~~~~~~~~~~~~~~~~~~~~~~~^^^^^^^^^^^^^^^^^^^^^
  File "C:\Workspace\FrankTheLocalLLM-main\.venv\Lib\site-packages\billiard\pool.py", line 406, in _ensure_messages_consumed
    if self.on_ready_counter.value >= completed:
       ^^^^^^^^^^^^^^^^^^^^^^^^^^^
  File "<string>", line 3, in getvalue
PermissionError: [WinError 5] Access is denied
[2025-08-21 15:25:26,853: ERROR/SpawnPoolWorker-12] Pool process <billiard.pool.Worker object at 0x0000013933BFE120> error: PermissionError(13, 'Access is denied', None, 5, None)
Traceback (most recent call last):
  File "C:\Workspace\FrankTheLocalLLM-main\.venv\Lib\site-packages\billiard\pool.py", line 473, in receive
    ready, req = _receive(1.0)
                 ~~~~~~~~^^^^^
  File "C:\Workspace\FrankTheLocalLLM-main\.venv\Lib\site-packages\billiard\pool.py", line 445, in _recv
    return True, loads(get_payload())
                       ~~~~~~~~~~~^^
  File "C:\Workspace\FrankTheLocalLLM-main\.venv\Lib\site-packages\billiard\queues.py", line 394, in get_payload
    with self._rlock:
         ^^^^^^^^^^^
  File "C:\Workspace\FrankTheLocalLLM-main\.venv\Lib\site-packages\billiard\synchronize.py", line 118, in __exit__
    return self._semlock.__exit__(*args)
           ~~~~~~~~~~~~~~~~~~~~~~^^^^^^^
OSError: [WinError 6] The handle is invalid

During handling of the above exception, another exception occurred:

Traceback (most recent call last):
  File "C:\Workspace\FrankTheLocalLLM-main\.venv\Lib\site-packages\billiard\pool.py", line 351, in workloop
    req = wait_for_job()
  File "C:\Workspace\FrankTheLocalLLM-main\.venv\Lib\site-packages\billiard\pool.py", line 480, in receive
    raise SystemExit(EX_FAILURE)
SystemExit: 1

During handling of the above exception, another exception occurred:

Traceback (most recent call last):
  File "C:\Workspace\FrankTheLocalLLM-main\.venv\Lib\site-packages\billiard\pool.py", line 292, in __call__
    sys.exit(self.workloop(pid=pid))
             ~~~~~~~~~~~~~^^^^^^^^^
  File "C:\Workspace\FrankTheLocalLLM-main\.venv\Lib\site-packages\billiard\pool.py", line 396, in workloop
    self._ensure_messages_consumed(completed=completed)
    ~~~~~~~~~~~~~~~~~~~~~~~~~~~~~~^^^^^^^^^^^^^^^^^^^^^
  File "C:\Workspace\FrankTheLocalLLM-main\.venv\Lib\site-packages\billiard\pool.py", line 406, in _ensure_messages_consumed
    if self.on_ready_counter.value >= completed:
       ^^^^^^^^^^^^^^^^^^^^^^^^^^^
  File "<string>", line 3, in getvalue
PermissionError: [WinError 5] Access is denied
[2025-08-21 15:25:26,853: ERROR/SpawnPoolWorker-10] Pool process <billiard.pool.Worker object at 0x000001EF1FE0E120> error: PermissionError(13, 'Access is denied', None, 5, None)
Traceback (most recent call last):
  File "C:\Workspace\FrankTheLocalLLM-main\.venv\Lib\site-packages\billiard\pool.py", line 473, in receive
    ready, req = _receive(1.0)
                 ~~~~~~~~^^^^^
  File "C:\Workspace\FrankTheLocalLLM-main\.venv\Lib\site-packages\billiard\pool.py", line 445, in _recv
    return True, loads(get_payload())
                       ~~~~~~~~~~~^^
  File "C:\Workspace\FrankTheLocalLLM-main\.venv\Lib\site-packages\billiard\queues.py", line 394, in get_payload
    with self._rlock:
         ^^^^^^^^^^^
  File "C:\Workspace\FrankTheLocalLLM-main\.venv\Lib\site-packages\billiard\synchronize.py", line 118, in __exit__
    return self._semlock.__exit__(*args)
           ~~~~~~~~~~~~~~~~~~~~~~^^^^^^^
OSError: [WinError 6] The handle is invalid

During handling of the above exception, another exception occurred:

Traceback (most recent call last):
  File "C:\Workspace\FrankTheLocalLLM-main\.venv\Lib\site-packages\billiard\pool.py", line 351, in workloop
    req = wait_for_job()
  File "C:\Workspace\FrankTheLocalLLM-main\.venv\Lib\site-packages\billiard\pool.py", line 480, in receive
    raise SystemExit(EX_FAILURE)
SystemExit: 1

During handling of the above exception, another exception occurred:

Traceback (most recent call last):
  File "C:\Workspace\FrankTheLocalLLM-main\.venv\Lib\site-packages\billiard\pool.py", line 292, in __call__
    sys.exit(self.workloop(pid=pid))
             ~~~~~~~~~~~~~^^^^^^^^^
  File "C:\Workspace\FrankTheLocalLLM-main\.venv\Lib\site-packages\billiard\pool.py", line 396, in workloop
    self._ensure_messages_consumed(completed=completed)
    ~~~~~~~~~~~~~~~~~~~~~~~~~~~~~~^^^^^^^^^^^^^^^^^^^^^
  File "C:\Workspace\FrankTheLocalLLM-main\.venv\Lib\site-packages\billiard\pool.py", line 406, in _ensure_messages_consumed
    if self.on_ready_counter.value >= completed:
       ^^^^^^^^^^^^^^^^^^^^^^^^^^^
  File "<string>", line 3, in getvalue
PermissionError: [WinError 5] Access is denied
[2025-08-21 15:25:26,853: ERROR/SpawnPoolWorker-11] Pool process <billiard.pool.Worker object at 0x0000024FAAABE120> error: PermissionError(13, 'Access is denied', None, 5, None)
Traceback (most recent call last):
  File "C:\Workspace\FrankTheLocalLLM-main\.venv\Lib\site-packages\billiard\pool.py", line 473, in receive
    ready, req = _receive(1.0)
                 ~~~~~~~~^^^^^
  File "C:\Workspace\FrankTheLocalLLM-main\.venv\Lib\site-packages\billiard\pool.py", line 445, in _recv
    return True, loads(get_payload())
                       ~~~~~~~~~~~^^
  File "C:\Workspace\FrankTheLocalLLM-main\.venv\Lib\site-packages\billiard\queues.py", line 394, in get_payload
    with self._rlock:
         ^^^^^^^^^^^
  File "C:\Workspace\FrankTheLocalLLM-main\.venv\Lib\site-packages\billiard\synchronize.py", line 118, in __exit__
    return self._semlock.__exit__(*args)
           ~~~~~~~~~~~~~~~~~~~~~~^^^^^^^
OSError: [WinError 6] The handle is invalid

During handling of the above exception, another exception occurred:

Traceback (most recent call last):
  File "C:\Workspace\FrankTheLocalLLM-main\.venv\Lib\site-packages\billiard\pool.py", line 351, in workloop
    req = wait_for_job()
  File "C:\Workspace\FrankTheLocalLLM-main\.venv\Lib\site-packages\billiard\pool.py", line 480, in receive
    raise SystemExit(EX_FAILURE)
SystemExit: 1

During handling of the above exception, another exception occurred:

Traceback (most recent call last):
  File "C:\Workspace\FrankTheLocalLLM-main\.venv\Lib\site-packages\billiard\pool.py", line 292, in __call__
    sys.exit(self.workloop(pid=pid))
             ~~~~~~~~~~~~~^^^^^^^^^
  File "C:\Workspace\FrankTheLocalLLM-main\.venv\Lib\site-packages\billiard\pool.py", line 396, in workloop
    self._ensure_messages_consumed(completed=completed)
    ~~~~~~~~~~~~~~~~~~~~~~~~~~~~~~^^^^^^^^^^^^^^^^^^^^^
  File "C:\Workspace\FrankTheLocalLLM-main\.venv\Lib\site-packages\billiard\pool.py", line 406, in _ensure_messages_consumed
    if self.on_ready_counter.value >= completed:
       ^^^^^^^^^^^^^^^^^^^^^^^^^^^
  File "<string>", line 3, in getvalue
PermissionError: [WinError 5] Access is denied
[2025-08-21 15:25:26,853: ERROR/SpawnPoolWorker-12] Pool process <billiard.pool.Worker object at 0x0000013933BFE120> error: PermissionError(13, 'Access is denied', None, 5, None)
Traceback (most recent call last):
  File "C:\Workspace\FrankTheLocalLLM-main\.venv\Lib\site-packages\billiard\pool.py", line 473, in receive
    ready, req = _receive(1.0)
                 ~~~~~~~~^^^^^
  File "C:\Workspace\FrankTheLocalLLM-main\.venv\Lib\site-packages\billiard\pool.py", line 445, in _recv
    return True, loads(get_payload())
                       ~~~~~~~~~~~^^
  File "C:\Workspace\FrankTheLocalLLM-main\.venv\Lib\site-packages\billiard\queues.py", line 394, in get_payload
    with self._rlock:
         ^^^^^^^^^^^
  File "C:\Workspace\FrankTheLocalLLM-main\.venv\Lib\site-packages\billiard\synchronize.py", line 118, in __exit__
    return self._semlock.__exit__(*args)
           ~~~~~~~~~~~~~~~~~~~~~~^^^^^^^
OSError: [WinError 6] The handle is invalid

During handling of the above exception, another exception occurred:

Traceback (most recent call last):
  File "C:\Workspace\FrankTheLocalLLM-main\.venv\Lib\site-packages\billiard\pool.py", line 351, in workloop
    req = wait_for_job()
  File "C:\Workspace\FrankTheLocalLLM-main\.venv\Lib\site-packages\billiard\pool.py", line 480, in receive
    raise SystemExit(EX_FAILURE)
SystemExit: 1

During handling of the above exception, another exception occurred:

Traceback (most recent call last):
  File "C:\Workspace\FrankTheLocalLLM-main\.venv\Lib\site-packages\billiard\pool.py", line 292, in __call__
    sys.exit(self.workloop(pid=pid))
             ~~~~~~~~~~~~~^^^^^^^^^
  File "C:\Workspace\FrankTheLocalLLM-main\.venv\Lib\site-packages\billiard\pool.py", line 396, in workloop
    self._ensure_messages_consumed(completed=completed)
    ~~~~~~~~~~~~~~~~~~~~~~~~~~~~~~^^^^^^^^^^^^^^^^^^^^^
  File "C:\Workspace\FrankTheLocalLLM-main\.venv\Lib\site-packages\billiard\pool.py", line 406, in _ensure_messages_consumed
    if self.on_ready_counter.value >= completed:
       ^^^^^^^^^^^^^^^^^^^^^^^^^^^
  File "<string>", line 3, in getvalue
PermissionError: [WinError 5] Access is denied
 denied
[2025-08-21 15:28:31,738: ERROR/SpawnPoolWorker-7] Pool process <billiard.pool.Worker object at 0x00000209F63BE120> error: OSError(9, 'The handle is invalid', None, 6, None)
Traceback (most recent call last):
  File "C:\Workspace\FrankTheLocalLLM-main\.venv\Lib\site-packages\billiard\pool.py", line 473, in receive
    ready, req = _receive(1.0)
                 ~~~~~~~~^^^^^
  File "C:\Workspace\FrankTheLocalLLM-main\.venv\Lib\site-packages\billiard\pool.py", line 445, in _recv
    return True, loads(get_payload())
                       ~~~~~~~~~~~^^
  File "C:\Workspace\FrankTheLocalLLM-main\.venv\Lib\site-packages\billiard\queues.py", line 394, in get_payload
    with self._rlock:
         ^^^^^^^^^^^
  File "C:\Workspace\FrankTheLocalLLM-main\.venv\Lib\site-packages\billiard\synchronize.py", line 118, in __exit__
    return self._semlock.__exit__(*args)
           ~~~~~~~~~~~~~~~~~~~~~~^^^^^^^
OSError: [WinError 6] The handle is invalid

During handling of the above exception, another exception occurred:

Traceback (most recent call last):
  File "C:\Workspace\FrankTheLocalLLM-main\.venv\Lib\site-packages\billiard\pool.py", line 351, in workloop
    req = wait_for_job()
  File "C:\Workspace\FrankTheLocalLLM-main\.venv\Lib\site-packages\billiard\pool.py", line 480, in receive
    raise SystemExit(EX_FAILURE)
SystemExit: 1

During handling of the above exception, another exception occurred:

Traceback (most recent call last):
  File "C:\Workspace\FrankTheLocalLLM-main\.venv\Lib\site-packages\billiard\pool.py", line 292, in __call__
    sys.exit(self.workloop(pid=pid))
             ~~~~~~~~~~~~~^^^^^^^^^
  File "C:\Workspace\FrankTheLocalLLM-main\.venv\Lib\site-packages\billiard\pool.py", line 396, in workloop
    self._ensure_messages_consumed(completed=completed)
    ~~~~~~~~~~~~~~~~~~~~~~~~~~~~~~^^^^^^^^^^^^^^^^^^^^^
  File "C:\Workspace\FrankTheLocalLLM-main\.venv\Lib\site-packages\billiard\pool.py", line 406, in _ensure_messages_consumed
    if self.on_ready_counter.value >= completed:
       ^^^^^^^^^^^^^^^^^^^^^^^^^^^
  File "<string>", line 7, in getvalue
OSError: [WinError 6] The handle is invalid
[2025-08-21 15:28:31,738: ERROR/SpawnPoolWorker-7] Pool process <billiard.pool.Worker object at 0x00000209F63BE120> error: OSError(9, 'The handle is invalid', None, 6, None)
Traceback (most recent call last):
  File "C:\Workspace\FrankTheLocalLLM-main\.venv\Lib\site-packages\billiard\pool.py", line 473, in receive
    ready, req = _receive(1.0)
                 ~~~~~~~~^^^^^
  File "C:\Workspace\FrankTheLocalLLM-main\.venv\Lib\site-packages\billiard\pool.py", line 445, in _recv
    return True, loads(get_payload())
                       ~~~~~~~~~~~^^
  File "C:\Workspace\FrankTheLocalLLM-main\.venv\Lib\site-packages\billiard\queues.py", line 394, in get_payload
    with self._rlock:
         ^^^^^^^^^^^
  File "C:\Workspace\FrankTheLocalLLM-main\.venv\Lib\site-packages\billiard\synchronize.py", line 118, in __exit__
    return self._semlock.__exit__(*args)
           ~~~~~~~~~~~~~~~~~~~~~~^^^^^^^
OSError: [WinError 6] The handle is invalid

During handling of the above exception, another exception occurred:

Traceback (most recent call last):
  File "C:\Workspace\FrankTheLocalLLM-main\.venv\Lib\site-packages\billiard\pool.py", line 351, in workloop
    req = wait_for_job()
  File "C:\Workspace\FrankTheLocalLLM-main\.venv\Lib\site-packages\billiard\pool.py", line 480, in receive
    raise SystemExit(EX_FAILURE)
SystemExit: 1

During handling of the above exception, another exception occurred:

Traceback (most recent call last):
  File "C:\Workspace\FrankTheLocalLLM-main\.venv\Lib\site-packages\billiard\pool.py", line 292, in __call__
    sys.exit(self.workloop(pid=pid))
             ~~~~~~~~~~~~~^^^^^^^^^
  File "C:\Workspace\FrankTheLocalLLM-main\.venv\Lib\site-packages\billiard\pool.py", line 396, in workloop
    self._ensure_messages_consumed(completed=completed)
    ~~~~~~~~~~~~~~~~~~~~~~~~~~~~~~^^^^^^^^^^^^^^^^^^^^^
  File "C:\Workspace\FrankTheLocalLLM-main\.venv\Lib\site-packages\billiard\pool.py", line 406, in _ensure_messages_consumed
    if self.on_ready_counter.value >= completed:
       ^^^^^^^^^^^^^^^^^^^^^^^^^^^
  File "<string>", line 7, in getvalue
OSError: [WinError 6] The handle is invalid
