[2025-08-24 21:25:01,460: ERROR/MainProcess] consumer: Cannot connect to redis://localhost:6379/0: Error 10061 connecting to localhost:6379. No connection could be made because the target machine actively refused it..
Trying again in 2.00 seconds... (1/100)

[2025-08-24 21:25:06,691: ERROR/SpawnPoolWorker-3] Pool process <billiard.pool.Worker object at 0x000001E5E77DE120> error: OSError(9, 'The handle is invalid', None, 6, None)
Traceback (most recent call last):
  File "C:\Workspace\FrankTheLocalLLM-main\.venv\Lib\site-packages\billiard\pool.py", line 473, in receive
    ready, req = _receive(1.0)
                 ~~~~~~~~^^^^^
  File "C:\Workspace\FrankTheLocalLLM-main\.venv\Lib\site-packages\billiard\pool.py", line 445, in _recv
    return True, loads(get_payload())
                       ~~~~~~~~~~~^^
  File "C:\Workspace\FrankTheLocalLLM-main\.venv\Lib\site-packages\billiard\queues.py", line 394, in get_payload
    with self._rlock:
         ^^^^^^^^^^^
  File "C:\Workspace\FrankTheLocalLLM-main\.venv\Lib\site-packages\billiard\synchronize.py", line 115, in __enter__
    return self._semlock.__enter__()
           ~~~~~~~~~~~~~~~~~~~~~~~^^
PermissionError: [WinError 5] Access is denied

During handling of the above exception, another exception occurred:

Traceback (most recent call last):
  File "C:\Workspace\FrankTheLocalLLM-main\.venv\Lib\site-packages\billiard\pool.py", line 351, in workloop
    req = wait_for_job()
  File "C:\Workspace\FrankTheLocalLLM-main\.venv\Lib\site-packages\billiard\pool.py", line 480, in receive
    raise SystemExit(EX_FAILURE)
SystemExit: 1

During handling of the above exception, another exception occurred:

Traceback (most recent call last):
  File "C:\Workspace\FrankTheLocalLLM-main\.venv\Lib\site-packages\billiard\pool.py", line 292, in __call__
    sys.exit(self.workloop(pid=pid))
             ~~~~~~~~~~~~~^^^^^^^^^
  File "C:\Workspace\FrankTheLocalLLM-main\.venv\Lib\site-packages\billiard\pool.py", line 396, in workloop
    self._ensure_messages_consumed(completed=completed)
    ~~~~~~~~~~~~~~~~~~~~~~~~~~~~~~^^^^^^^^^^^^^^^^^^^^^
  File "C:\Workspace\FrankTheLocalLLM-main\.venv\Lib\site-packages\billiard\pool.py", line 406, in _ensure_messages_consumed
    if self.on_ready_counter.value >= completed:
       ^^^^^^^^^^^^^^^^^^^^^^^^^^^
  File "<string>", line 7, in getvalue
OSError: [WinError 6] The handle is invalid
[2025-08-24 21:25:06,691: ERROR/SpawnPoolWorker-3] Pool process <billiard.pool.Worker object at 0x000001E5E77DE120> error: OSError(9, 'The handle is invalid', None, 6, None)
Traceback (most recent call last):
  File "C:\Workspace\FrankTheLocalLLM-main\.venv\Lib\site-packages\billiard\pool.py", line 473, in receive
    ready, req = _receive(1.0)
                 ~~~~~~~~^^^^^
  File "C:\Workspace\FrankTheLocalLLM-main\.venv\Lib\site-packages\billiard\pool.py", line 445, in _recv
    return True, loads(get_payload())
                       ~~~~~~~~~~~^^
  File "C:\Workspace\FrankTheLocalLLM-main\.venv\Lib\site-packages\billiard\queues.py", line 394, in get_payload
    with self._rlock:
         ^^^^^^^^^^^
  File "C:\Workspace\FrankTheLocalLLM-main\.venv\Lib\site-packages\billiard\synchronize.py", line 115, in __enter__
    return self._semlock.__enter__()
           ~~~~~~~~~~~~~~~~~~~~~~~^^
PermissionError: [WinError 5] Access is denied

During handling of the above exception, another exception occurred:

Traceback (most recent call last):
  File "C:\Workspace\FrankTheLocalLLM-main\.venv\Lib\site-packages\billiard\pool.py", line 351, in workloop
    req = wait_for_job()
  File "C:\Workspace\FrankTheLocalLLM-main\.venv\Lib\site-packages\billiard\pool.py", line 480, in receive
    raise SystemExit(EX_FAILURE)
SystemExit: 1

During handling of the above exception, another exception occurred:

Traceback (most recent call last):
  File "C:\Workspace\FrankTheLocalLLM-main\.venv\Lib\site-packages\billiard\pool.py", line 292, in __call__
    sys.exit(self.workloop(pid=pid))
             ~~~~~~~~~~~~~^^^^^^^^^
  File "C:\Workspace\FrankTheLocalLLM-main\.venv\Lib\site-packages\billiard\pool.py", line 396, in workloop
    self._ensure_messages_consumed(completed=completed)
    ~~~~~~~~~~~~~~~~~~~~~~~~~~~~~~^^^^^^^^^^^^^^^^^^^^^
  File "C:\Workspace\FrankTheLocalLLM-main\.venv\Lib\site-packages\billiard\pool.py", line 406, in _ensure_messages_consumed
    if self.on_ready_counter.value >= completed:
       ^^^^^^^^^^^^^^^^^^^^^^^^^^^
  File "<string>", line 7, in getvalue
OSError: [WinError 6] The handle is invalid
[2025-08-24 21:25:06,782: ERROR/SpawnPoolWorker-2] Pool process <billiard.pool.Worker object at 0x000001ED3CF3E120> error: PermissionError(13, 'Access is denied', None, 5, None)
Traceback (most recent call last):
  File "C:\Workspace\FrankTheLocalLLM-main\.venv\Lib\site-packages\billiard\pool.py", line 473, in receive
    ready, req = _receive(1.0)
                 ~~~~~~~~^^^^^
  File "C:\Workspace\FrankTheLocalLLM-main\.venv\Lib\site-packages\billiard\pool.py", line 445, in _recv
    return True, loads(get_payload())
                       ~~~~~~~~~~~^^
  File "C:\Workspace\FrankTheLocalLLM-main\.venv\Lib\site-packages\billiard\queues.py", line 394, in get_payload
    with self._rlock:
         ^^^^^^^^^^^
  File "C:\Workspace\FrankTheLocalLLM-main\.venv\Lib\site-packages\billiard\synchronize.py", line 115, in __enter__
    return self._semlock.__enter__()
           ~~~~~~~~~~~~~~~~~~~~~~~^^
PermissionError: [WinError 5] Access is denied

During handling of the above exception, another exception occurred:

Traceback (most recent call last):
  File "C:\Workspace\FrankTheLocalLLM-main\.venv\Lib\site-packages\billiard\pool.py", line 351, in workloop
    req = wait_for_job()
  File "C:\Workspace\FrankTheLocalLLM-main\.venv\Lib\site-packages\billiard\pool.py", line 480, in receive
    raise SystemExit(EX_FAILURE)
SystemExit: 1

During handling of the above exception, another exception occurred:

Traceback (most recent call last):
  File "C:\Workspace\FrankTheLocalLLM-main\.venv\Lib\site-packages\billiard\pool.py", line 292, in __call__
    sys.exit(self.workloop(pid=pid))
             ~~~~~~~~~~~~~^^^^^^^^^
  File "C:\Workspace\FrankTheLocalLLM-main\.venv\Lib\site-packages\billiard\pool.py", line 396, in workloop
    self._ensure_messages_consumed(completed=completed)
    ~~~~~~~~~~~~~~~~~~~~~~~~~~~~~~^^^^^^^^^^^^^^^^^^^^^
  File "C:\Workspace\FrankTheLocalLLM-main\.venv\Lib\site-packages\billiard\pool.py", line 406, in _ensure_messages_consumed
    if self.on_ready_counter.value >= completed:
       ^^^^^^^^^^^^^^^^^^^^^^^^^^^
  File "<string>", line 3, in getvalue
PermissionError: [WinError 5] Access is denied
[2025-08-24 21:25:06,782: ERROR/SpawnPoolWorker-2] Pool process <billiard.pool.Worker object at 0x000001ED3CF3E120> error: PermissionError(13, 'Access is denied', None, 5, None)
Traceback (most recent call last):
  File "C:\Workspace\FrankTheLocalLLM-main\.venv\Lib\site-packages\billiard\pool.py", line 473, in receive
    ready, req = _receive(1.0)
                 ~~~~~~~~^^^^^
  File "C:\Workspace\FrankTheLocalLLM-main\.venv\Lib\site-packages\billiard\pool.py", line 445, in _recv
    return True, loads(get_payload())
                       ~~~~~~~~~~~^^
  File "C:\Workspace\FrankTheLocalLLM-main\.venv\Lib\site-packages\billiard\queues.py", line 394, in get_payload
    with self._rlock:
         ^^^^^^^^^^^
  File "C:\Workspace\FrankTheLocalLLM-main\.venv\Lib\site-packages\billiard\synchronize.py", line 115, in __enter__
    return self._semlock.__enter__()
           ~~~~~~~~~~~~~~~~~~~~~~~^^
PermissionError: [WinError 5] Access is denied

During handling of the above exception, another exception occurred:

Traceback (most recent call last):
  File "C:\Workspace\FrankTheLocalLLM-main\.venv\Lib\site-packages\billiard\pool.py", line 351, in workloop
    req = wait_for_job()
  File "C:\Workspace\FrankTheLocalLLM-main\.venv\Lib\site-packages\billiard\pool.py", line 480, in receive
    raise SystemExit(EX_FAILURE)
SystemExit: 1

During handling of the above exception, another exception occurred:

Traceback (most recent call last):
  File "C:\Workspace\FrankTheLocalLLM-main\.venv\Lib\site-packages\billiard\pool.py", line 292, in __call__
    sys.exit(self.workloop(pid=pid))
             ~~~~~~~~~~~~~^^^^^^^^^
  File "C:\Workspace\FrankTheLocalLLM-main\.venv\Lib\site-packages\billiard\pool.py", line 396, in workloop
    self._ensure_messages_consumed(completed=completed)
    ~~~~~~~~~~~~~~~~~~~~~~~~~~~~~~^^^^^^^^^^^^^^^^^^^^^
  File "C:\Workspace\FrankTheLocalLLM-main\.venv\Lib\site-packages\billiard\pool.py", line 406, in _ensure_messages_consumed
    if self.on_ready_counter.value >= completed:
       ^^^^^^^^^^^^^^^^^^^^^^^^^^^
  File "<string>", line 3, in getvalue
PermissionError: [WinError 5] Access is denied
[2025-08-24 21:25:06,785: ERROR/SpawnPoolWorker-5] Pool process <billiard.pool.Worker object at 0x00000200D7ABE120> error: PermissionError(13, 'Access is denied', None, 5, None)
Traceback (most recent call last):
  File "C:\Workspace\FrankTheLocalLLM-main\.venv\Lib\site-packages\billiard\pool.py", line 473, in receive
    ready, req = _receive(1.0)
                 ~~~~~~~~^^^^^
  File "C:\Workspace\FrankTheLocalLLM-main\.venv\Lib\site-packages\billiard\pool.py", line 445, in _recv
    return True, loads(get_payload())
                       ~~~~~~~~~~~^^
  File "C:\Workspace\FrankTheLocalLLM-main\.venv\Lib\site-packages\billiard\queues.py", line 394, in get_payload
    with self._rlock:
         ^^^^^^^^^^^
  File "C:\Workspace\FrankTheLocalLLM-main\.venv\Lib\site-packages\billiard\synchronize.py", line 115, in __enter__
    return self._semlock.__enter__()
           ~~~~~~~~~~~~~~~~~~~~~~~^^
PermissionError: [WinError 5] Access is denied

During handling of the above exception, another exception occurred:

Traceback (most recent call last):
  File "C:\Workspace\FrankTheLocalLLM-main\.venv\Lib\site-packages\billiard\pool.py", line 351, in workloop
    req = wait_for_job()
  File "C:\Workspace\FrankTheLocalLLM-main\.venv\Lib\site-packages\billiard\pool.py", line 480, in receive
    raise SystemExit(EX_FAILURE)
SystemExit: 1

During handling of the above exception, another exception occurred:

Traceback (most recent call last):
  File "C:\Workspace\FrankTheLocalLLM-main\.venv\Lib\site-packages\billiard\pool.py", line 292, in __call__
    sys.exit(self.workloop(pid=pid))
             ~~~~~~~~~~~~~^^^^^^^^^
  File "C:\Workspace\FrankTheLocalLLM-main\.venv\Lib\site-packages\billiard\pool.py", line 396, in workloop
    self._ensure_messages_consumed(completed=completed)
    ~~~~~~~~~~~~~~~~~~~~~~~~~~~~~~^^^^^^^^^^^^^^^^^^^^^
  File "C:\Workspace\FrankTheLocalLLM-main\.venv\Lib\site-packages\billiard\pool.py", line 406, in _ensure_messages_consumed
    if self.on_ready_counter.value >= completed:
       ^^^^^^^^^^^^^^^^^^^^^^^^^^^
  File "<string>", line 3, in getvalue
PermissionError: [WinError 5] Access is denied
[2025-08-24 21:25:06,785: ERROR/SpawnPoolWorker-5] Pool process <billiard.pool.Worker object at 0x00000200D7ABE120> error: PermissionError(13, 'Access is denied', None, 5, None)
Traceback (most recent call last):
  File "C:\Workspace\FrankTheLocalLLM-main\.venv\Lib\site-packages\billiard\pool.py", line 473, in receive
    ready, req = _receive(1.0)
                 ~~~~~~~~^^^^^
  File "C:\Workspace\FrankTheLocalLLM-main\.venv\Lib\site-packages\billiard\pool.py", line 445, in _recv
    return True, loads(get_payload())
                       ~~~~~~~~~~~^^
  File "C:\Workspace\FrankTheLocalLLM-main\.venv\Lib\site-packages\billiard\queues.py", line 394, in get_payload
    with self._rlock:
         ^^^^^^^^^^^
  File "C:\Workspace\FrankTheLocalLLM-main\.venv\Lib\site-packages\billiard\synchronize.py", line 115, in __enter__
    return self._semlock.__enter__()
           ~~~~~~~~~~~~~~~~~~~~~~~^^
PermissionError: [WinError 5] Access is denied

During handling of the above exception, another exception occurred:

Traceback (most recent call last):
  File "C:\Workspace\FrankTheLocalLLM-main\.venv\Lib\site-packages\billiard\pool.py", line 351, in workloop
    req = wait_for_job()
  File "C:\Workspace\FrankTheLocalLLM-main\.venv\Lib\site-packages\billiard\pool.py", line 480, in receive
    raise SystemExit(EX_FAILURE)
SystemExit: 1

During handling of the above exception, another exception occurred:

Traceback (most recent call last):
  File "C:\Workspace\FrankTheLocalLLM-main\.venv\Lib\site-packages\billiard\pool.py", line 292, in __call__
    sys.exit(self.workloop(pid=pid))
             ~~~~~~~~~~~~~^^^^^^^^^
  File "C:\Workspace\FrankTheLocalLLM-main\.venv\Lib\site-packages\billiard\pool.py", line 396, in workloop
    self._ensure_messages_consumed(completed=completed)
    ~~~~~~~~~~~~~~~~~~~~~~~~~~~~~~^^^^^^^^^^^^^^^^^^^^^
  File "C:\Workspace\FrankTheLocalLLM-main\.venv\Lib\site-packages\billiard\pool.py", line 406, in _ensure_messages_consumed
    if self.on_ready_counter.value >= completed:
       ^^^^^^^^^^^^^^^^^^^^^^^^^^^
  File "<string>", line 3, in getvalue
PermissionError: [WinError 5] Access is denied
[2025-08-24 21:25:06,803: ERROR/SpawnPoolWorker-4] Pool process <billiard.pool.Worker object at 0x0000028373FBE120> error: PermissionError(13, 'Access is denied', None, 5, None)
Traceback (most recent call last):
  File "C:\Workspace\FrankTheLocalLLM-main\.venv\Lib\site-packages\billiard\pool.py", line 473, in receive
    ready, req = _receive(1.0)
                 ~~~~~~~~^^^^^
  File "C:\Workspace\FrankTheLocalLLM-main\.venv\Lib\site-packages\billiard\pool.py", line 445, in _recv
    return True, loads(get_payload())
                       ~~~~~~~~~~~^^
  File "C:\Workspace\FrankTheLocalLLM-main\.venv\Lib\site-packages\billiard\queues.py", line 394, in get_payload
    with self._rlock:
         ^^^^^^^^^^^
  File "C:\Workspace\FrankTheLocalLLM-main\.venv\Lib\site-packages\billiard\synchronize.py", line 115, in __enter__
    return self._semlock.__enter__()
           ~~~~~~~~~~~~~~~~~~~~~~~^^
PermissionError: [WinError 5] Access is denied

During handling of the above exception, another exception occurred:

Traceback (most recent call last):
  File "C:\Workspace\FrankTheLocalLLM-main\.venv\Lib\site-packages\billiard\pool.py", line 351, in workloop
    req = wait_for_job()
  File "C:\Workspace\FrankTheLocalLLM-main\.venv\Lib\site-packages\billiard\pool.py", line 480, in receive
    raise SystemExit(EX_FAILURE)
SystemExit: 1

During handling of the above exception, another exception occurred:

Traceback (most recent call last):
  File "C:\Workspace\FrankTheLocalLLM-main\.venv\Lib\site-packages\billiard\pool.py", line 292, in __call__
    sys.exit(self.workloop(pid=pid))
             ~~~~~~~~~~~~~^^^^^^^^^
  File "C:\Workspace\FrankTheLocalLLM-main\.venv\Lib\site-packages\billiard\pool.py", line 396, in workloop
    self._ensure_messages_consumed(completed=completed)
    ~~~~~~~~~~~~~~~~~~~~~~~~~~~~~~^^^^^^^^^^^^^^^^^^^^^
  File "C:\Workspace\FrankTheLocalLLM-main\.venv\Lib\site-packages\billiard\pool.py", line 406, in _ensure_messages_consumed
    if self.on_ready_counter.value >= completed:
       ^^^^^^^^^^^^^^^^^^^^^^^^^^^
  File "<string>", line 3, in getvalue
PermissionError: [WinError 5] Access is denied
[2025-08-24 21:25:06,803: ERROR/SpawnPoolWorker-4] Pool process <billiard.pool.Worker object at 0x0000028373FBE120> error: PermissionError(13, 'Access is denied', None, 5, None)
Traceback (most recent call last):
  File "C:\Workspace\FrankTheLocalLLM-main\.venv\Lib\site-packages\billiard\pool.py", line 473, in receive
    ready, req = _receive(1.0)
                 ~~~~~~~~^^^^^
  File "C:\Workspace\FrankTheLocalLLM-main\.venv\Lib\site-packages\billiard\pool.py", line 445, in _recv
    return True, loads(get_payload())
                       ~~~~~~~~~~~^^
  File "C:\Workspace\FrankTheLocalLLM-main\.venv\Lib\site-packages\billiard\queues.py", line 394, in get_payload
    with self._rlock:
         ^^^^^^^^^^^
  File "C:\Workspace\FrankTheLocalLLM-main\.venv\Lib\site-packages\billiard\synchronize.py", line 115, in __enter__
    return self._semlock.__enter__()
           ~~~~~~~~~~~~~~~~~~~~~~~^^
PermissionError: [WinError 5] Access is denied

During handling of the above exception, another exception occurred:

Traceback (most recent call last):
  File "C:\Workspace\FrankTheLocalLLM-main\.venv\Lib\site-packages\billiard\pool.py", line 351, in workloop
    req = wait_for_job()
  File "C:\Workspace\FrankTheLocalLLM-main\.venv\Lib\site-packages\billiard\pool.py", line 480, in receive
    raise SystemExit(EX_FAILURE)
SystemExit: 1

During handling of the above exception, another exception occurred:

Traceback (most recent call last):
  File "C:\Workspace\FrankTheLocalLLM-main\.venv\Lib\site-packages\billiard\pool.py", line 292, in __call__
    sys.exit(self.workloop(pid=pid))
             ~~~~~~~~~~~~~^^^^^^^^^
  File "C:\Workspace\FrankTheLocalLLM-main\.venv\Lib\site-packages\billiard\pool.py", line 396, in workloop
    self._ensure_messages_consumed(completed=completed)
    ~~~~~~~~~~~~~~~~~~~~~~~~~~~~~~^^^^^^^^^^^^^^^^^^^^^
  File "C:\Workspace\FrankTheLocalLLM-main\.venv\Lib\site-packages\billiard\pool.py", line 406, in _ensure_messages_consumed
    if self.on_ready_counter.value >= completed:
       ^^^^^^^^^^^^^^^^^^^^^^^^^^^
  File "<string>", line 3, in getvalue
PermissionError: [WinError 5] Access is denied
[2025-08-24 21:25:06,847: ERROR/SpawnPoolWorker-1] Pool process <billiard.pool.Worker object at 0x0000017640DAE120> error: OSError(9, 'The handle is invalid', None, 6, None)
Traceback (most recent call last):
  File "C:\Workspace\FrankTheLocalLLM-main\.venv\Lib\site-packages\billiard\pool.py", line 473, in receive
    ready, req = _receive(1.0)
                 ~~~~~~~~^^^^^
  File "C:\Workspace\FrankTheLocalLLM-main\.venv\Lib\site-packages\billiard\pool.py", line 445, in _recv
    return True, loads(get_payload())
                       ~~~~~~~~~~~^^
  File "C:\Workspace\FrankTheLocalLLM-main\.venv\Lib\site-packages\billiard\queues.py", line 394, in get_payload
    with self._rlock:
         ^^^^^^^^^^^
  File "C:\Workspace\FrankTheLocalLLM-main\.venv\Lib\site-packages\billiard\synchronize.py", line 115, in __enter__
    return self._semlock.__enter__()
           ~~~~~~~~~~~~~~~~~~~~~~~^^
PermissionError: [WinError 5] Access is denied

During handling of the above exception, another exception occurred:

Traceback (most recent call last):
  File "C:\Workspace\FrankTheLocalLLM-main\.venv\Lib\site-packages\billiard\pool.py", line 351, in workloop
    req = wait_for_job()
  File "C:\Workspace\FrankTheLocalLLM-main\.venv\Lib\site-packages\billiard\pool.py", line 480, in receive
    raise SystemExit(EX_FAILURE)
SystemExit: 1

During handling of the above exception, another exception occurred:

Traceback (most recent call last):
  File "C:\Workspace\FrankTheLocalLLM-main\.venv\Lib\site-packages\billiard\pool.py", line 292, in __call__
    sys.exit(self.workloop(pid=pid))
             ~~~~~~~~~~~~~^^^^^^^^^
  File "C:\Workspace\FrankTheLocalLLM-main\.venv\Lib\site-packages\billiard\pool.py", line 396, in workloop
    self._ensure_messages_consumed(completed=completed)
    ~~~~~~~~~~~~~~~~~~~~~~~~~~~~~~^^^^^^^^^^^^^^^^^^^^^
  File "C:\Workspace\FrankTheLocalLLM-main\.venv\Lib\site-packages\billiard\pool.py", line 406, in _ensure_messages_consumed
    if self.on_ready_counter.value >= completed:
       ^^^^^^^^^^^^^^^^^^^^^^^^^^^
  File "<string>", line 7, in getvalue
OSError: [WinError 6] The handle is invalid
[2025-08-24 21:25:06,847: ERROR/SpawnPoolWorker-1] Pool process <billiard.pool.Worker object at 0x0000017640DAE120> error: OSError(9, 'The handle is invalid', None, 6, None)
Traceback (most recent call last):
  File "C:\Workspace\FrankTheLocalLLM-main\.venv\Lib\site-packages\billiard\pool.py", line 473, in receive
    ready, req = _receive(1.0)
                 ~~~~~~~~^^^^^
  File "C:\Workspace\FrankTheLocalLLM-main\.venv\Lib\site-packages\billiard\pool.py", line 445, in _recv
    return True, loads(get_payload())
                       ~~~~~~~~~~~^^
  File "C:\Workspace\FrankTheLocalLLM-main\.venv\Lib\site-packages\billiard\queues.py", line 394, in get_payload
    with self._rlock:
         ^^^^^^^^^^^
  File "C:\Workspace\FrankTheLocalLLM-main\.venv\Lib\site-packages\billiard\synchronize.py", line 115, in __enter__
    return self._semlock.__enter__()
           ~~~~~~~~~~~~~~~~~~~~~~~^^
PermissionError: [WinError 5] Access is denied

During handling of the above exception, another exception occurred:

Traceback (most recent call last):
  File "C:\Workspace\FrankTheLocalLLM-main\.venv\Lib\site-packages\billiard\pool.py", line 351, in workloop
    req = wait_for_job()
  File "C:\Workspace\FrankTheLocalLLM-main\.venv\Lib\site-packages\billiard\pool.py", line 480, in receive
    raise SystemExit(EX_FAILURE)
SystemExit: 1

During handling of the above exception, another exception occurred:

Traceback (most recent call last):
  File "C:\Workspace\FrankTheLocalLLM-main\.venv\Lib\site-packages\billiard\pool.py", line 292, in __call__
    sys.exit(self.workloop(pid=pid))
             ~~~~~~~~~~~~~^^^^^^^^^
  File "C:\Workspace\FrankTheLocalLLM-main\.venv\Lib\site-packages\billiard\pool.py", line 396, in workloop
    self._ensure_messages_consumed(completed=completed)
    ~~~~~~~~~~~~~~~~~~~~~~~~~~~~~~^^^^^^^^^^^^^^^^^^^^^
  File "C:\Workspace\FrankTheLocalLLM-main\.venv\Lib\site-packages\billiard\pool.py", line 406, in _ensure_messages_consumed
    if self.on_ready_counter.value >= completed:
       ^^^^^^^^^^^^^^^^^^^^^^^^^^^
  File "<string>", line 7, in getvalue
OSError: [WinError 6] The handle is invalid
[2025-08-24 21:25:07,406: ERROR/MainProcess] Process 'SpawnPoolWorker-5' pid:17204 exited with 'exitcode 1'
[2025-08-24 21:25:07,417: ERROR/MainProcess] Process 'SpawnPoolWorker-4' pid:2372 exited with 'exitcode 1'
[2025-08-24 21:25:07,417: ERROR/MainProcess] Process 'SpawnPoolWorker-3' pid:8696 exited with 'exitcode 1'
[2025-08-24 21:25:07,418: ERROR/MainProcess] Process 'SpawnPoolWorker-2' pid:9476 exited with 'exitcode 1'
[2025-08-24 21:25:07,418: ERROR/MainProcess] Process 'SpawnPoolWorker-1' pid:15776 exited with 'exitcode 1'
[2025-08-24 21:25:07,879: ERROR/MainProcess] consumer: Cannot connect to redis://localhost:6379/0: Error 10061 connecting to localhost:6379. No connection could be made because the target machine actively refused it..
Trying again in 4.00 seconds... (2/100)

[2025-08-24 21:25:09,841: ERROR/MainProcess] Process 'SpawnPoolWorker-17' pid:17648 exited with 'exitcode 3221225786'
[2025-08-24 21:25:09,842: ERROR/MainProcess] Process 'SpawnPoolWorker-16' pid:10880 exited with 'exitcode 3221225786'
[2025-08-24 21:25:11,449: ERROR/MainProcess] Process 'SpawnPoolWorker-19' pid:16344 exited with 'exitcode 3221225786'
[2025-08-24 21:25:11,450: ERROR/MainProcess] Process 'SpawnPoolWorker-18' pid:7024 exited with 'exitcode 3221225786'
[2025-08-24 21:25:13,060: ERROR/MainProcess] Process 'SpawnPoolWorker-21' pid:16732 exited with 'exitcode 3221225786'
[2025-08-24 21:25:13,060: ERROR/MainProcess] Process 'SpawnPoolWorker-20' pid:13064 exited with 'exitcode 3221225786'
[2025-08-24 21:25:15,471: ERROR/MainProcess] Process 'SpawnPoolWorker-23' pid:20868 exited with 'exitcode 3221225786'
[2025-08-24 21:25:15,481: ERROR/MainProcess] Process 'SpawnPoolWorker-22' pid:13704 exited with 'exitcode 3221225786'
[2025-08-24 21:25:15,900: ERROR/MainProcess] consumer: Cannot connect to redis://localhost:6379/0: Error 10061 connecting to localhost:6379. No connection could be made because the target machine actively refused it..
Trying again in 6.00 seconds... (3/100)

[2025-08-24 21:25:19,488: ERROR/MainProcess] Process 'SpawnPoolWorker-25' pid:20072 exited with 'exitcode 3221225786'
[2025-08-24 21:25:19,500: ERROR/MainProcess] Process 'SpawnPoolWorker-24' pid:17036 exited with 'exitcode 3221225786'
