[2025-08-23 13:10:49,431: ERROR/MainProcess] consumer: Cannot connect to redis://localhost:6379/0: Error 10061 connecting to localhost:6379. No connection could be made because the target machine actively refused it..
Trying again in 2.00 seconds... (1/100)

[2025-08-23 13:10:55,014: ERROR/SpawnPoolWorker-1] Pool process <billiard.pool.Worker object at 0x000001F4E6D9E120> error: PermissionError(13, 'Access is denied', None, 5, None)
Traceback (most recent call last):
  File "C:\Workspace\FrankTheLocalLLM-main\.venv\Lib\site-packages\billiard\pool.py", line 473, in receive
    ready, req = _receive(1.0)
                 ~~~~~~~~^^^^^
  File "C:\Workspace\FrankTheLocalLLM-main\.venv\Lib\site-packages\billiard\pool.py", line 445, in _recv
    return True, loads(get_payload())
                       ~~~~~~~~~~~^^
  File "C:\Workspace\FrankTheLocalLLM-main\.venv\Lib\site-packages\billiard\queues.py", line 394, in get_payload
    with self._rlock:
         ^^^^^^^^^^^
  File "C:\Workspace\FrankTheLocalLLM-main\.venv\Lib\site-packages\billiard\synchronize.py", line 115, in __enter__
    return self._semlock.__enter__()
           ~~~~~~~~~~~~~~~~~~~~~~~^^
PermissionError: [WinError 5] Access is denied

During handling of the above exception, another exception occurred:

Traceback (most recent call last):
  File "C:\Workspace\FrankTheLocalLLM-main\.venv\Lib\site-packages\billiard\pool.py", line 351, in workloop
    req = wait_for_job()
  File "C:\Workspace\FrankTheLocalLLM-main\.venv\Lib\site-packages\billiard\pool.py", line 480, in receive
    raise SystemExit(EX_FAILURE)
SystemExit: 1

During handling of the above exception, another exception occurred:

Traceback (most recent call last):
  File "C:\Workspace\FrankTheLocalLLM-main\.venv\Lib\site-packages\billiard\pool.py", line 292, in __call__
    sys.exit(self.workloop(pid=pid))
             ~~~~~~~~~~~~~^^^^^^^^^
  File "C:\Workspace\FrankTheLocalLLM-main\.venv\Lib\site-packages\billiard\pool.py", line 396, in workloop
    self._ensure_messages_consumed(completed=completed)
    ~~~~~~~~~~~~~~~~~~~~~~~~~~~~~~^^^^^^^^^^^^^^^^^^^^^
  File "C:\Workspace\FrankTheLocalLLM-main\.venv\Lib\site-packages\billiard\pool.py", line 406, in _ensure_messages_consumed
    if self.on_ready_counter.value >= completed:
       ^^^^^^^^^^^^^^^^^^^^^^^^^^^
  File "<string>", line 3, in getvalue
PermissionError: [WinError 5] Access is denied
[2025-08-23 13:10:55,032: ERROR/SpawnPoolWorker-8] Pool process <billiard.pool.Worker object at 0x000002495147E120> error: OSError(9, 'The handle is invalid', None, 6, None)
Traceback (most recent call last):
  File "C:\Workspace\FrankTheLocalLLM-main\.venv\Lib\site-packages\billiard\pool.py", line 473, in receive
    ready, req = _receive(1.0)
                 ~~~~~~~~^^^^^
  File "C:\Workspace\FrankTheLocalLLM-main\.venv\Lib\site-packages\billiard\pool.py", line 445, in _recv
    return True, loads(get_payload())
                       ~~~~~~~~~~~^^
  File "C:\Workspace\FrankTheLocalLLM-main\.venv\Lib\site-packages\billiard\queues.py", line 394, in get_payload
    with self._rlock:
         ^^^^^^^^^^^
  File "C:\Workspace\FrankTheLocalLLM-main\.venv\Lib\site-packages\billiard\synchronize.py", line 115, in __enter__
    return self._semlock.__enter__()
           ~~~~~~~~~~~~~~~~~~~~~~~^^
PermissionError: [WinError 5] Access is denied

During handling of the above exception, another exception occurred:

Traceback (most recent call last):
  File "C:\Workspace\FrankTheLocalLLM-main\.venv\Lib\site-packages\billiard\pool.py", line 351, in workloop
    req = wait_for_job()
  File "C:\Workspace\FrankTheLocalLLM-main\.venv\Lib\site-packages\billiard\pool.py", line 480, in receive
    raise SystemExit(EX_FAILURE)
SystemExit: 1

During handling of the above exception, another exception occurred:

Traceback (most recent call last):
  File "C:\Workspace\FrankTheLocalLLM-main\.venv\Lib\site-packages\billiard\pool.py", line 292, in __call__
    sys.exit(self.workloop(pid=pid))
             ~~~~~~~~~~~~~^^^^^^^^^
  File "C:\Workspace\FrankTheLocalLLM-main\.venv\Lib\site-packages\billiard\pool.py", line 396, in workloop
    self._ensure_messages_consumed(completed=completed)
    ~~~~~~~~~~~~~~~~~~~~~~~~~~~~~~^^^^^^^^^^^^^^^^^^^^^
  File "C:\Workspace\FrankTheLocalLLM-main\.venv\Lib\site-packages\billiard\pool.py", line 406, in _ensure_messages_consumed
    if self.on_ready_counter.value >= completed:
       ^^^^^^^^^^^^^^^^^^^^^^^^^^^
  File "<string>", line 7, in getvalue
OSError: [WinError 6] The handle is invalid
[2025-08-23 13:10:55,014: ERROR/SpawnPoolWorker-1] Pool process <billiard.pool.Worker object at 0x000001F4E6D9E120> error: PermissionError(13, 'Access is denied', None, 5, None)
Traceback (most recent call last):
  File "C:\Workspace\FrankTheLocalLLM-main\.venv\Lib\site-packages\billiard\pool.py", line 473, in receive
    ready, req = _receive(1.0)
                 ~~~~~~~~^^^^^
  File "C:\Workspace\FrankTheLocalLLM-main\.venv\Lib\site-packages\billiard\pool.py", line 445, in _recv
    return True, loads(get_payload())
                       ~~~~~~~~~~~^^
  File "C:\Workspace\FrankTheLocalLLM-main\.venv\Lib\site-packages\billiard\queues.py", line 394, in get_payload
    with self._rlock:
         ^^^^^^^^^^^
  File "C:\Workspace\FrankTheLocalLLM-main\.venv\Lib\site-packages\billiard\synchronize.py", line 115, in __enter__
    return self._semlock.__enter__()
           ~~~~~~~~~~~~~~~~~~~~~~~^^
PermissionError: [WinError 5] Access is denied

During handling of the above exception, another exception occurred:

Traceback (most recent call last):
  File "C:\Workspace\FrankTheLocalLLM-main\.venv\Lib\site-packages\billiard\pool.py", line 351, in workloop
    req = wait_for_job()
  File "C:\Workspace\FrankTheLocalLLM-main\.venv\Lib\site-packages\billiard\pool.py", line 480, in receive
    raise SystemExit(EX_FAILURE)
SystemExit: 1

During handling of the above exception, another exception occurred:

Traceback (most recent call last):
  File "C:\Workspace\FrankTheLocalLLM-main\.venv\Lib\site-packages\billiard\pool.py", line 292, in __call__
    sys.exit(self.workloop(pid=pid))
             ~~~~~~~~~~~~~^^^^^^^^^
  File "C:\Workspace\FrankTheLocalLLM-main\.venv\Lib\site-packages\billiard\pool.py", line 396, in workloop
    self._ensure_messages_consumed(completed=completed)
    ~~~~~~~~~~~~~~~~~~~~~~~~~~~~~~^^^^^^^^^^^^^^^^^^^^^
  File "C:\Workspace\FrankTheLocalLLM-main\.venv\Lib\site-packages\billiard\pool.py", line 406, in _ensure_messages_consumed
    if self.on_ready_counter.value >= completed:
       ^^^^^^^^^^^^^^^^^^^^^^^^^^^
  File "<string>", line 3, in getvalue
PermissionError: [WinError 5] Access is denied
[2025-08-23 13:10:55,032: ERROR/SpawnPoolWorker-8] Pool process <billiard.pool.Worker object at 0x000002495147E120> error: OSError(9, 'The handle is invalid', None, 6, None)
Traceback (most recent call last):
  File "C:\Workspace\FrankTheLocalLLM-main\.venv\Lib\site-packages\billiard\pool.py", line 473, in receive
    ready, req = _receive(1.0)
                 ~~~~~~~~^^^^^
  File "C:\Workspace\FrankTheLocalLLM-main\.venv\Lib\site-packages\billiard\pool.py", line 445, in _recv
    return True, loads(get_payload())
                       ~~~~~~~~~~~^^
  File "C:\Workspace\FrankTheLocalLLM-main\.venv\Lib\site-packages\billiard\queues.py", line 394, in get_payload
    with self._rlock:
         ^^^^^^^^^^^
  File "C:\Workspace\FrankTheLocalLLM-main\.venv\Lib\site-packages\billiard\synchronize.py", line 115, in __enter__
    return self._semlock.__enter__()
           ~~~~~~~~~~~~~~~~~~~~~~~^^
PermissionError: [WinError 5] Access is denied

During handling of the above exception, another exception occurred:

Traceback (most recent call last):
  File "C:\Workspace\FrankTheLocalLLM-main\.venv\Lib\site-packages\billiard\pool.py", line 351, in workloop
    req = wait_for_job()
  File "C:\Workspace\FrankTheLocalLLM-main\.venv\Lib\site-packages\billiard\pool.py", line 480, in receive
    raise SystemExit(EX_FAILURE)
SystemExit: 1

During handling of the above exception, another exception occurred:

Traceback (most recent call last):
  File "C:\Workspace\FrankTheLocalLLM-main\.venv\Lib\site-packages\billiard\pool.py", line 292, in __call__
    sys.exit(self.workloop(pid=pid))
             ~~~~~~~~~~~~~^^^^^^^^^
  File "C:\Workspace\FrankTheLocalLLM-main\.venv\Lib\site-packages\billiard\pool.py", line 396, in workloop
    self._ensure_messages_consumed(completed=completed)
    ~~~~~~~~~~~~~~~~~~~~~~~~~~~~~~^^^^^^^^^^^^^^^^^^^^^
  File "C:\Workspace\FrankTheLocalLLM-main\.venv\Lib\site-packages\billiard\pool.py", line 406, in _ensure_messages_consumed
    if self.on_ready_counter.value >= completed:
       ^^^^^^^^^^^^^^^^^^^^^^^^^^^
  File "<string>", line 7, in getvalue
OSError: [WinError 6] The handle is invalid
[2025-08-23 13:10:55,165: ERROR/MainProcess] Process 'SpawnPoolWorker-8' pid:17848 exited with 'exitcode 1'
[2025-08-23 13:10:55,165: ERROR/MainProcess] Process 'SpawnPoolWorker-1' pid:16832 exited with 'exitcode 1'
[2025-08-23 13:10:55,871: ERROR/MainProcess] consumer: Cannot connect to redis://localhost:6379/0: Error 10061 connecting to localhost:6379. No connection could be made because the target machine actively refused it..
Trying again in 4.00 seconds... (2/100)

[2025-08-23 13:10:59,657: ERROR/SpawnPoolWorker-14] Pool process <billiard.pool.Worker object at 0x00000163873DE120> error: OSError(9, 'The handle is invalid', None, 6, None)
Traceback (most recent call last):
  File "C:\Workspace\FrankTheLocalLLM-main\.venv\Lib\site-packages\billiard\pool.py", line 473, in receive
    ready, req = _receive(1.0)
                 ~~~~~~~~^^^^^
  File "C:\Workspace\FrankTheLocalLLM-main\.venv\Lib\site-packages\billiard\pool.py", line 445, in _recv
    return True, loads(get_payload())
                       ~~~~~~~~~~~^^
  File "C:\Workspace\FrankTheLocalLLM-main\.venv\Lib\site-packages\billiard\queues.py", line 394, in get_payload
    with self._rlock:
         ^^^^^^^^^^^
  File "C:\Workspace\FrankTheLocalLLM-main\.venv\Lib\site-packages\billiard\synchronize.py", line 115, in __enter__
    return self._semlock.__enter__()
           ~~~~~~~~~~~~~~~~~~~~~~~^^
PermissionError: [WinError 5] Access is denied

During handling of the above exception, another exception occurred:

Traceback (most recent call last):
  File "C:\Workspace\FrankTheLocalLLM-main\.venv\Lib\site-packages\billiard\pool.py", line 351, in workloop
    req = wait_for_job()
  File "C:\Workspace\FrankTheLocalLLM-main\.venv\Lib\site-packages\billiard\pool.py", line 480, in receive
    raise SystemExit(EX_FAILURE)
SystemExit: 1

During handling of the above exception, another exception occurred:

Traceback (most recent call last):
  File "C:\Workspace\FrankTheLocalLLM-main\.venv\Lib\site-packages\billiard\pool.py", line 292, in __call__
    sys.exit(self.workloop(pid=pid))
             ~~~~~~~~~~~~~^^^^^^^^^
  File "C:\Workspace\FrankTheLocalLLM-main\.venv\Lib\site-packages\billiard\pool.py", line 396, in workloop
    self._ensure_messages_consumed(completed=completed)
    ~~~~~~~~~~~~~~~~~~~~~~~~~~~~~~^^^^^^^^^^^^^^^^^^^^^
  File "C:\Workspace\FrankTheLocalLLM-main\.venv\Lib\site-packages\billiard\pool.py", line 406, in _ensure_messages_consumed
    if self.on_ready_counter.value >= completed:
       ^^^^^^^^^^^^^^^^^^^^^^^^^^^
  File "<string>", line 7, in getvalue
OSError: [WinError 6] The handle is invalid
[2025-08-23 13:10:59,657: ERROR/SpawnPoolWorker-14] Pool process <billiard.pool.Worker object at 0x00000163873DE120> error: OSError(9, 'The handle is invalid', None, 6, None)
Traceback (most recent call last):
  File "C:\Workspace\FrankTheLocalLLM-main\.venv\Lib\site-packages\billiard\pool.py", line 473, in receive
    ready, req = _receive(1.0)
                 ~~~~~~~~^^^^^
  File "C:\Workspace\FrankTheLocalLLM-main\.venv\Lib\site-packages\billiard\pool.py", line 445, in _recv
    return True, loads(get_payload())
                       ~~~~~~~~~~~^^
  File "C:\Workspace\FrankTheLocalLLM-main\.venv\Lib\site-packages\billiard\queues.py", line 394, in get_payload
    with self._rlock:
         ^^^^^^^^^^^
  File "C:\Workspace\FrankTheLocalLLM-main\.venv\Lib\site-packages\billiard\synchronize.py", line 115, in __enter__
    return self._semlock.__enter__()
           ~~~~~~~~~~~~~~~~~~~~~~~^^
PermissionError: [WinError 5] Access is denied

During handling of the above exception, another exception occurred:

Traceback (most recent call last):
  File "C:\Workspace\FrankTheLocalLLM-main\.venv\Lib\site-packages\billiard\pool.py", line 351, in workloop
    req = wait_for_job()
  File "C:\Workspace\FrankTheLocalLLM-main\.venv\Lib\site-packages\billiard\pool.py", line 480, in receive
    raise SystemExit(EX_FAILURE)
SystemExit: 1

During handling of the above exception, another exception occurred:

Traceback (most recent call last):
  File "C:\Workspace\FrankTheLocalLLM-main\.venv\Lib\site-packages\billiard\pool.py", line 292, in __call__
    sys.exit(self.workloop(pid=pid))
             ~~~~~~~~~~~~~^^^^^^^^^
  File "C:\Workspace\FrankTheLocalLLM-main\.venv\Lib\site-packages\billiard\pool.py", line 396, in workloop
    self._ensure_messages_consumed(completed=completed)
    ~~~~~~~~~~~~~~~~~~~~~~~~~~~~~~^^^^^^^^^^^^^^^^^^^^^
  File "C:\Workspace\FrankTheLocalLLM-main\.venv\Lib\site-packages\billiard\pool.py", line 406, in _ensure_messages_consumed
    if self.on_ready_counter.value >= completed:
       ^^^^^^^^^^^^^^^^^^^^^^^^^^^
  File "<string>", line 7, in getvalue
OSError: [WinError 6] The handle is invalid
[2025-08-23 13:10:59,981: ERROR/MainProcess] Process 'SpawnPoolWorker-14' pid:3452 exited with 'exitcode 1'
[2025-08-23 13:11:03,532: ERROR/SpawnPoolWorker-15] Pool process <billiard.pool.Worker object at 0x000001FFD0ECE120> error: OSError(9, 'The handle is invalid', None, 6, None)
Traceback (most recent call last):
  File "C:\Workspace\FrankTheLocalLLM-main\.venv\Lib\site-packages\billiard\pool.py", line 473, in receive
    ready, req = _receive(1.0)
                 ~~~~~~~~^^^^^
  File "C:\Workspace\FrankTheLocalLLM-main\.venv\Lib\site-packages\billiard\pool.py", line 445, in _recv
    return True, loads(get_payload())
                       ~~~~~~~~~~~^^
  File "C:\Workspace\FrankTheLocalLLM-main\.venv\Lib\site-packages\billiard\queues.py", line 394, in get_payload
    with self._rlock:
         ^^^^^^^^^^^
  File "C:\Workspace\FrankTheLocalLLM-main\.venv\Lib\site-packages\billiard\synchronize.py", line 115, in __enter__
    return self._semlock.__enter__()
           ~~~~~~~~~~~~~~~~~~~~~~~^^
PermissionError: [WinError 5] Access is denied

During handling of the above exception, another exception occurred:

Traceback (most recent call last):
  File "C:\Workspace\FrankTheLocalLLM-main\.venv\Lib\site-packages\billiard\pool.py", line 351, in workloop
    req = wait_for_job()
  File "C:\Workspace\FrankTheLocalLLM-main\.venv\Lib\site-packages\billiard\pool.py", line 480, in receive
    raise SystemExit(EX_FAILURE)
SystemExit: 1

During handling of the above exception, another exception occurred:

Traceback (most recent call last):
  File "C:\Workspace\FrankTheLocalLLM-main\.venv\Lib\site-packages\billiard\pool.py", line 292, in __call__
    sys.exit(self.workloop(pid=pid))
             ~~~~~~~~~~~~~^^^^^^^^^
  File "C:\Workspace\FrankTheLocalLLM-main\.venv\Lib\site-packages\billiard\pool.py", line 396, in workloop
    self._ensure_messages_consumed(completed=completed)
    ~~~~~~~~~~~~~~~~~~~~~~~~~~~~~~^^^^^^^^^^^^^^^^^^^^^
  File "C:\Workspace\FrankTheLocalLLM-main\.venv\Lib\site-packages\billiard\pool.py", line 406, in _ensure_messages_consumed
    if self.on_ready_counter.value >= completed:
       ^^^^^^^^^^^^^^^^^^^^^^^^^^^
  File "<string>", line 7, in getvalue
OSError: [WinError 6] The handle is invalid
[2025-08-23 13:11:03,532: ERROR/SpawnPoolWorker-15] Pool process <billiard.pool.Worker object at 0x000001FFD0ECE120> error: OSError(9, 'The handle is invalid', None, 6, None)
Traceback (most recent call last):
  File "C:\Workspace\FrankTheLocalLLM-main\.venv\Lib\site-packages\billiard\pool.py", line 473, in receive
    ready, req = _receive(1.0)
                 ~~~~~~~~^^^^^
  File "C:\Workspace\FrankTheLocalLLM-main\.venv\Lib\site-packages\billiard\pool.py", line 445, in _recv
    return True, loads(get_payload())
                       ~~~~~~~~~~~^^
  File "C:\Workspace\FrankTheLocalLLM-main\.venv\Lib\site-packages\billiard\queues.py", line 394, in get_payload
    with self._rlock:
         ^^^^^^^^^^^
  File "C:\Workspace\FrankTheLocalLLM-main\.venv\Lib\site-packages\billiard\synchronize.py", line 115, in __enter__
    return self._semlock.__enter__()
           ~~~~~~~~~~~~~~~~~~~~~~~^^
PermissionError: [WinError 5] Access is denied

During handling of the above exception, another exception occurred:

Traceback (most recent call last):
  File "C:\Workspace\FrankTheLocalLLM-main\.venv\Lib\site-packages\billiard\pool.py", line 351, in workloop
    req = wait_for_job()
  File "C:\Workspace\FrankTheLocalLLM-main\.venv\Lib\site-packages\billiard\pool.py", line 480, in receive
    raise SystemExit(EX_FAILURE)
SystemExit: 1

During handling of the above exception, another exception occurred:

Traceback (most recent call last):
  File "C:\Workspace\FrankTheLocalLLM-main\.venv\Lib\site-packages\billiard\pool.py", line 292, in __call__
    sys.exit(self.workloop(pid=pid))
             ~~~~~~~~~~~~~^^^^^^^^^
  File "C:\Workspace\FrankTheLocalLLM-main\.venv\Lib\site-packages\billiard\pool.py", line 396, in workloop
    self._ensure_messages_consumed(completed=completed)
    ~~~~~~~~~~~~~~~~~~~~~~~~~~~~~~^^^^^^^^^^^^^^^^^^^^^
  File "C:\Workspace\FrankTheLocalLLM-main\.venv\Lib\site-packages\billiard\pool.py", line 406, in _ensure_messages_consumed
    if self.on_ready_counter.value >= completed:
       ^^^^^^^^^^^^^^^^^^^^^^^^^^^
  File "<string>", line 7, in getvalue
OSError: [WinError 6] The handle is invalid
[2025-08-23 13:11:03,972: ERROR/MainProcess] consumer: Cannot connect to redis://localhost:6379/0: Error 10061 connecting to localhost:6379. No connection could be made because the target machine actively refused it..
Trying again in 6.00 seconds... (3/100)

[2025-08-23 13:11:04,039: ERROR/MainProcess] Process 'SpawnPoolWorker-15' pid:20884 exited with 'exitcode 1'
[2025-08-23 13:11:14,121: ERROR/MainProcess] consumer: Cannot connect to redis://localhost:6379/0: Error 10061 connecting to localhost:6379. No connection could be made because the target machine actively refused it..
Trying again in 8.00 seconds... (4/100)

[2025-08-23 13:11:26,258: ERROR/MainProcess] consumer: Cannot connect to redis://localhost:6379/0: Error 10061 connecting to localhost:6379. No connection could be made because the target machine actively refused it..
Trying again in 10.00 seconds... (5/100)

[2025-08-23 13:11:40,398: ERROR/MainProcess] consumer: Cannot connect to redis://localhost:6379/0: Error 10061 connecting to localhost:6379. No connection could be made because the target machine actively refused it..
Trying again in 12.00 seconds... (6/100)

[2025-08-23 13:11:56,530: ERROR/MainProcess] consumer: Cannot connect to redis://localhost:6379/0: Error 10061 connecting to localhost:6379. No connection could be made because the target machine actively refused it..
Trying again in 14.00 seconds... (7/100)

[2025-08-23 13:12:14,632: ERROR/MainProcess] consumer: Cannot connect to redis://localhost:6379/0: Error 10061 connecting to localhost:6379. No connection could be made because the target machine actively refused it..
Trying again in 16.00 seconds... (8/100)

[2025-08-23 13:12:34,762: ERROR/MainProcess] consumer: Cannot connect to redis://localhost:6379/0: Error 10061 connecting to localhost:6379. No connection could be made because the target machine actively refused it..
Trying again in 18.00 seconds... (9/100)

[2025-08-23 13:12:56,865: ERROR/MainProcess] consumer: Cannot connect to redis://localhost:6379/0: Error 10061 connecting to localhost:6379. No connection could be made because the target machine actively refused it..
Trying again in 20.00 seconds... (10/100)

[2025-08-23 13:13:21,008: ERROR/MainProcess] consumer: Cannot connect to redis://localhost:6379/0: Error 10061 connecting to localhost:6379. No connection could be made because the target machine actively refused it..
Trying again in 22.00 seconds... (11/100)

[2025-08-23 13:13:47,155: ERROR/MainProcess] consumer: Cannot connect to redis://localhost:6379/0: Error 10061 connecting to localhost:6379. No connection could be made because the target machine actively refused it..
Trying again in 24.00 seconds... (12/100)

[2025-08-23 13:14:15,276: ERROR/MainProcess] consumer: Cannot connect to redis://localhost:6379/0: Error 10061 connecting to localhost:6379. No connection could be made because the target machine actively refused it..
Trying again in 26.00 seconds... (13/100)

[2025-08-23 13:14:45,418: ERROR/MainProcess] consumer: Cannot connect to redis://localhost:6379/0: Error 10061 connecting to localhost:6379. No connection could be made because the target machine actively refused it..
Trying again in 28.00 seconds... (14/100)

[2025-08-23 13:15:17,530: ERROR/MainProcess] consumer: Cannot connect to redis://localhost:6379/0: Error 10061 connecting to localhost:6379. No connection could be made because the target machine actively refused it..
Trying again in 30.00 seconds... (15/100)

[2025-08-23 13:15:51,646: ERROR/MainProcess] consumer: Cannot connect to redis://localhost:6379/0: Error 10061 connecting to localhost:6379. No connection could be made because the target machine actively refused it..
Trying again in 32.00 seconds... (16/100)

[2025-08-23 13:16:27,772: ERROR/MainProcess] consumer: Cannot connect to redis://localhost:6379/0: Error 10061 connecting to localhost:6379. No connection could be made because the target machine actively refused it..
Trying again in 32.00 seconds... (16/100)

[2025-08-23 13:17:03,909: ERROR/MainProcess] consumer: Cannot connect to redis://localhost:6379/0: Error 10061 connecting to localhost:6379. No connection could be made because the target machine actively refused it..
Trying again in 32.00 seconds... (16/100)

[2025-08-23 13:17:40,070: ERROR/MainProcess] consumer: Cannot connect to redis://localhost:6379/0: Error 10061 connecting to localhost:6379. No connection could be made because the target machine actively refused it..
Trying again in 32.00 seconds... (16/100)

[2025-08-23 13:18:16,167: ERROR/MainProcess] consumer: Cannot connect to redis://localhost:6379/0: Error 10061 connecting to localhost:6379. No connection could be made because the target machine actively refused it..
Trying again in 32.00 seconds... (16/100)

[2025-08-23 13:18:52,329: ERROR/MainProcess] consumer: Cannot connect to redis://localhost:6379/0: Error 10061 connecting to localhost:6379. No connection could be made because the target machine actively refused it..
Trying again in 32.00 seconds... (16/100)

