[2025-08-20 12:05:38,373: ERROR/MainProcess] consumer: Cannot connect to redis://localhost:6379/0: Error 10061 connecting to localhost:6379. No connection could be made because the target machine actively refused it..
Trying again in 2.00 seconds... (1/100)

[2025-08-20 12:05:44,633: ERROR/MainProcess] consumer: Cannot connect to redis://localhost:6379/0: Error 10061 connecting to localhost:6379. No connection could be made because the target machine actively refused it..
Trying again in 4.00 seconds... (2/100)

[2025-08-20 12:05:47,675: ERROR/SpawnPoolWorker-1] Pool process <billiard.pool.Worker object at 0x0000023873B3A120> error: PermissionError(13, 'Access is denied', None, 5, None)
Traceback (most recent call last):
  File "C:\Users\itsup\Downloads\FrankTheLocalLLM-main\FrankTheLocalLLM-main\.venv\Lib\site-packages\billiard\pool.py", line 473, in receive
    ready, req = _receive(1.0)
                 ~~~~~~~~^^^^^
  File "C:\Users\itsup\Downloads\FrankTheLocalLLM-main\FrankTheLocalLLM-main\.venv\Lib\site-packages\billiard\pool.py", line 445, in _recv
    return True, loads(get_payload())
                       ~~~~~~~~~~~^^
  File "C:\Users\itsup\Downloads\FrankTheLocalLLM-main\FrankTheLocalLLM-main\.venv\Lib\site-packages\billiard\queues.py", line 394, in get_payload
    with self._rlock:
         ^^^^^^^^^^^
  File "C:\Users\itsup\Downloads\FrankTheLocalLLM-main\FrankTheLocalLLM-main\.venv\Lib\site-packages\billiard\synchronize.py", line 115, in __enter__
    return self._semlock.__enter__()
           ~~~~~~~~~~~~~~~~~~~~~~~^^
PermissionError: [WinError 5] Access is denied

During handling of the above exception, another exception occurred:

Traceback (most recent call last):
  File "C:\Users\itsup\Downloads\FrankTheLocalLLM-main\FrankTheLocalLLM-main\.venv\Lib\site-packages\billiard\pool.py", line 351, in workloop
    req = wait_for_job()
  File "C:\Users\itsup\Downloads\FrankTheLocalLLM-main\FrankTheLocalLLM-main\.venv\Lib\site-packages\billiard\pool.py", line 480, in receive
    raise SystemExit(EX_FAILURE)
SystemExit: 1

During handling of the above exception, another exception occurred:

Traceback (most recent call last):
  File "C:\Users\itsup\Downloads\FrankTheLocalLLM-main\FrankTheLocalLLM-main\.venv\Lib\site-packages\billiard\pool.py", line 292, in __call__
    sys.exit(self.workloop(pid=pid))
             ~~~~~~~~~~~~~^^^^^^^^^
  File "C:\Users\itsup\Downloads\FrankTheLocalLLM-main\FrankTheLocalLLM-main\.venv\Lib\site-packages\billiard\pool.py", line 396, in workloop
    self._ensure_messages_consumed(completed=completed)
    ~~~~~~~~~~~~~~~~~~~~~~~~~~~~~~^^^^^^^^^^^^^^^^^^^^^
  File "C:\Users\itsup\Downloads\FrankTheLocalLLM-main\FrankTheLocalLLM-main\.venv\Lib\site-packages\billiard\pool.py", line 406, in _ensure_messages_consumed
    if self.on_ready_counter.value >= completed:
       ^^^^^^^^^^^^^^^^^^^^^^^^^^^
  File "<string>", line 3, in getvalue
PermissionError: [WinError 5] Access is denied
[2025-08-20 12:05:47,675: ERROR/SpawnPoolWorker-1] Pool process <billiard.pool.Worker object at 0x0000023873B3A120> error: PermissionError(13, 'Access is denied', None, 5, None)
Traceback (most recent call last):
  File "C:\Users\itsup\Downloads\FrankTheLocalLLM-main\FrankTheLocalLLM-main\.venv\Lib\site-packages\billiard\pool.py", line 473, in receive
    ready, req = _receive(1.0)
                 ~~~~~~~~^^^^^
  File "C:\Users\itsup\Downloads\FrankTheLocalLLM-main\FrankTheLocalLLM-main\.venv\Lib\site-packages\billiard\pool.py", line 445, in _recv
    return True, loads(get_payload())
                       ~~~~~~~~~~~^^
  File "C:\Users\itsup\Downloads\FrankTheLocalLLM-main\FrankTheLocalLLM-main\.venv\Lib\site-packages\billiard\queues.py", line 394, in get_payload
    with self._rlock:
         ^^^^^^^^^^^
  File "C:\Users\itsup\Downloads\FrankTheLocalLLM-main\FrankTheLocalLLM-main\.venv\Lib\site-packages\billiard\synchronize.py", line 115, in __enter__
    return self._semlock.__enter__()
           ~~~~~~~~~~~~~~~~~~~~~~~^^
PermissionError: [WinError 5] Access is denied

During handling of the above exception, another exception occurred:

Traceback (most recent call last):
  File "C:\Users\itsup\Downloads\FrankTheLocalLLM-main\FrankTheLocalLLM-main\.venv\Lib\site-packages\billiard\pool.py", line 351, in workloop
    req = wait_for_job()
  File "C:\Users\itsup\Downloads\FrankTheLocalLLM-main\FrankTheLocalLLM-main\.venv\Lib\site-packages\billiard\pool.py", line 480, in receive
    raise SystemExit(EX_FAILURE)
SystemExit: 1

During handling of the above exception, another exception occurred:

Traceback (most recent call last):
  File "C:\Users\itsup\Downloads\FrankTheLocalLLM-main\FrankTheLocalLLM-main\.venv\Lib\site-packages\billiard\pool.py", line 292, in __call__
    sys.exit(self.workloop(pid=pid))
             ~~~~~~~~~~~~~^^^^^^^^^
  File "C:\Users\itsup\Downloads\FrankTheLocalLLM-main\FrankTheLocalLLM-main\.venv\Lib\site-packages\billiard\pool.py", line 396, in workloop
    self._ensure_messages_consumed(completed=completed)
    ~~~~~~~~~~~~~~~~~~~~~~~~~~~~~~^^^^^^^^^^^^^^^^^^^^^
  File "C:\Users\itsup\Downloads\FrankTheLocalLLM-main\FrankTheLocalLLM-main\.venv\Lib\site-packages\billiard\pool.py", line 406, in _ensure_messages_consumed
    if self.on_ready_counter.value >= completed:
       ^^^^^^^^^^^^^^^^^^^^^^^^^^^
  File "<string>", line 3, in getvalue
PermissionError: [WinError 5] Access is denied
[2025-08-20 12:05:48,221: ERROR/MainProcess] Process 'SpawnPoolWorker-1' pid:40712 exited with 'exitcode 1'
[2025-08-20 12:05:52,694: ERROR/MainProcess] consumer: Cannot connect to redis://localhost:6379/0: Error 10061 connecting to localhost:6379. No connection could be made because the target machine actively refused it..
Trying again in 6.00 seconds... (3/100)

[2025-08-20 12:06:02,717: ERROR/MainProcess] consumer: Cannot connect to redis://localhost:6379/0: Error 10061 connecting to localhost:6379. No connection could be made because the target machine actively refused it..
Trying again in 8.00 seconds... (4/100)

[2025-08-20 12:06:14,749: ERROR/MainProcess] consumer: Cannot connect to redis://localhost:6379/0: Error 10061 connecting to localhost:6379. No connection could be made because the target machine actively refused it..
Trying again in 10.00 seconds... (5/100)

[2025-08-20 12:06:28,765: ERROR/MainProcess] consumer: Cannot connect to redis://localhost:6379/0: Error 10061 connecting to localhost:6379. No connection could be made because the target machine actively refused it..
Trying again in 12.00 seconds... (6/100)

[2025-08-20 12:06:44,791: ERROR/MainProcess] consumer: Cannot connect to redis://localhost:6379/0: Error 10061 connecting to localhost:6379. No connection could be made because the target machine actively refused it..
Trying again in 14.00 seconds... (7/100)

[2025-08-20 12:07:02,819: ERROR/MainProcess] consumer: Cannot connect to redis://localhost:6379/0: Error 10061 connecting to localhost:6379. No connection could be made because the target machine actively refused it..
Trying again in 16.00 seconds... (8/100)

[2025-08-20 12:07:22,851: ERROR/MainProcess] consumer: Cannot connect to redis://localhost:6379/0: Error 10061 connecting to localhost:6379. No connection could be made because the target machine actively refused it..
Trying again in 18.00 seconds... (9/100)

[2025-08-20 12:07:44,873: ERROR/MainProcess] consumer: Cannot connect to redis://localhost:6379/0: Error 10061 connecting to localhost:6379. No connection could be made because the target machine actively refused it..
Trying again in 20.00 seconds... (10/100)

[2025-08-20 12:08:08,897: ERROR/MainProcess] consumer: Cannot connect to redis://localhost:6379/0: Error 10061 connecting to localhost:6379. No connection could be made because the target machine actively refused it..
Trying again in 22.00 seconds... (11/100)

[2025-08-20 12:08:34,937: ERROR/MainProcess] consumer: Cannot connect to redis://localhost:6379/0: Error 10061 connecting to localhost:6379. No connection could be made because the target machine actively refused it..
Trying again in 24.00 seconds... (12/100)

[2025-08-20 12:09:02,973: ERROR/MainProcess] consumer: Cannot connect to redis://localhost:6379/0: Error 10061 connecting to localhost:6379. No connection could be made because the target machine actively refused it..
Trying again in 26.00 seconds... (13/100)

[2025-08-20 12:09:33,007: ERROR/MainProcess] consumer: Cannot connect to redis://localhost:6379/0: Error 10061 connecting to localhost:6379. No connection could be made because the target machine actively refused it..
Trying again in 28.00 seconds... (14/100)

[2025-08-20 12:10:05,040: ERROR/MainProcess] consumer: Cannot connect to redis://localhost:6379/0: Error 10061 connecting to localhost:6379. No connection could be made because the target machine actively refused it..
Trying again in 30.00 seconds... (15/100)

[2025-08-20 12:10:39,073: ERROR/MainProcess] consumer: Cannot connect to redis://localhost:6379/0: Error 10061 connecting to localhost:6379. No connection could be made because the target machine actively refused it..
Trying again in 32.00 seconds... (16/100)

[2025-08-20 12:11:15,116: ERROR/MainProcess] consumer: Cannot connect to redis://localhost:6379/0: Error 10061 connecting to localhost:6379. No connection could be made because the target machine actively refused it..
Trying again in 32.00 seconds... (16/100)

[2025-08-20 12:11:51,149: ERROR/MainProcess] consumer: Cannot connect to redis://localhost:6379/0: Error 10061 connecting to localhost:6379. No connection could be made because the target machine actively refused it..
Trying again in 32.00 seconds... (16/100)

[2025-08-20 12:12:27,189: ERROR/MainProcess] consumer: Cannot connect to redis://localhost:6379/0: Error 10061 connecting to localhost:6379. No connection could be made because the target machine actively refused it..
Trying again in 32.00 seconds... (16/100)

[2025-08-20 12:13:03,231: ERROR/MainProcess] consumer: Cannot connect to redis://localhost:6379/0: Error 10061 connecting to localhost:6379. No connection could be made because the target machine actively refused it..
Trying again in 32.00 seconds... (16/100)

[2025-08-20 12:13:39,255: ERROR/MainProcess] consumer: Cannot connect to redis://localhost:6379/0: Error 10061 connecting to localhost:6379. No connection could be made because the target machine actively refused it..
Trying again in 32.00 seconds... (16/100)

[2025-08-20 12:14:15,329: ERROR/MainProcess] consumer: Cannot connect to redis://localhost:6379/0: Error 10061 connecting to localhost:6379. No connection could be made because the target machine actively refused it..
Trying again in 32.00 seconds... (16/100)

[2025-08-20 12:14:51,357: ERROR/MainProcess] consumer: Cannot connect to redis://localhost:6379/0: Error 10061 connecting to localhost:6379. No connection could be made because the target machine actively refused it..
Trying again in 32.00 seconds... (16/100)

[2025-08-20 12:15:27,385: ERROR/MainProcess] consumer: Cannot connect to redis://localhost:6379/0: Error 10061 connecting to localhost:6379. No connection could be made because the target machine actively refused it..
Trying again in 32.00 seconds... (16/100)

[2025-08-20 12:16:03,450: ERROR/MainProcess] consumer: Cannot connect to redis://localhost:6379/0: Error 10061 connecting to localhost:6379. No connection could be made because the target machine actively refused it..
Trying again in 32.00 seconds... (16/100)

[2025-08-20 12:16:39,479: ERROR/MainProcess] consumer: Cannot connect to redis://localhost:6379/0: Error 10061 connecting to localhost:6379. No connection could be made because the target machine actively refused it..
Trying again in 32.00 seconds... (16/100)

[2025-08-20 12:17:15,510: ERROR/MainProcess] consumer: Cannot connect to redis://localhost:6379/0: Error 10061 connecting to localhost:6379. No connection could be made because the target machine actively refused it..
Trying again in 32.00 seconds... (16/100)

[2025-08-20 12:17:51,538: ERROR/MainProcess] consumer: Cannot connect to redis://localhost:6379/0: Error 10061 connecting to localhost:6379. No connection could be made because the target machine actively refused it..
Trying again in 32.00 seconds... (16/100)

[2025-08-20 12:18:27,579: ERROR/MainProcess] consumer: Cannot connect to redis://localhost:6379/0: Error 10061 connecting to localhost:6379. No connection could be made because the target machine actively refused it..
Trying again in 32.00 seconds... (16/100)

[2025-08-20 12:19:03,606: ERROR/MainProcess] consumer: Cannot connect to redis://localhost:6379/0: Error 10061 connecting to localhost:6379. No connection could be made because the target machine actively refused it..
Trying again in 32.00 seconds... (16/100)

[2025-08-20 12:19:39,641: ERROR/MainProcess] consumer: Cannot connect to redis://localhost:6379/0: Error 10061 connecting to localhost:6379. No connection could be made because the target machine actively refused it..
Trying again in 32.00 seconds... (16/100)

[2025-08-20 12:20:15,769: ERROR/MainProcess] consumer: Cannot connect to redis://localhost:6379/0: Error 10061 connecting to localhost:6379. No connection could be made because the target machine actively refused it..
Trying again in 32.00 seconds... (16/100)

[2025-08-20 12:20:51,867: ERROR/MainProcess] consumer: Cannot connect to redis://localhost:6379/0: Error 10061 connecting to localhost:6379. No connection could be made because the target machine actively refused it..
Trying again in 32.00 seconds... (16/100)

[2025-08-20 12:21:27,984: ERROR/MainProcess] consumer: Cannot connect to redis://localhost:6379/0: Error 10061 connecting to localhost:6379. No connection could be made because the target machine actively refused it..
Trying again in 32.00 seconds... (16/100)

[2025-08-20 12:22:04,065: ERROR/MainProcess] consumer: Cannot connect to redis://localhost:6379/0: Error 10061 connecting to localhost:6379. No connection could be made because the target machine actively refused it..
Trying again in 32.00 seconds... (16/100)

[2025-08-20 12:22:40,158: ERROR/MainProcess] consumer: Cannot connect to redis://localhost:6379/0: Error 10061 connecting to localhost:6379. No connection could be made because the target machine actively refused it..
Trying again in 32.00 seconds... (16/100)

[2025-08-20 12:23:16,264: ERROR/MainProcess] consumer: Cannot connect to redis://localhost:6379/0: Error 10061 connecting to localhost:6379. No connection could be made because the target machine actively refused it..
Trying again in 32.00 seconds... (16/100)

[2025-08-20 12:23:52,376: ERROR/MainProcess] consumer: Cannot connect to redis://localhost:6379/0: Error 10061 connecting to localhost:6379. No connection could be made because the target machine actively refused it..
Trying again in 32.00 seconds... (16/100)

[2025-08-20 12:24:28,490: ERROR/MainProcess] consumer: Cannot connect to redis://localhost:6379/0: Error 10061 connecting to localhost:6379. No connection could be made because the target machine actively refused it..
Trying again in 32.00 seconds... (16/100)

[2025-08-20 12:25:04,605: ERROR/MainProcess] consumer: Cannot connect to redis://localhost:6379/0: Error 10061 connecting to localhost:6379. No connection could be made because the target machine actively refused it..
Trying again in 32.00 seconds... (16/100)

[2025-08-20 12:25:40,731: ERROR/MainProcess] consumer: Cannot connect to redis://localhost:6379/0: Error 10061 connecting to localhost:6379. No connection could be made because the target machine actively refused it..
Trying again in 32.00 seconds... (16/100)

[2025-08-20 12:26:16,836: ERROR/MainProcess] consumer: Cannot connect to redis://localhost:6379/0: Error 10061 connecting to localhost:6379. No connection could be made because the target machine actively refused it..
Trying again in 32.00 seconds... (16/100)

[2025-08-20 12:26:52,938: ERROR/MainProcess] consumer: Cannot connect to redis://localhost:6379/0: Error 10061 connecting to localhost:6379. No connection could be made because the target machine actively refused it..
Trying again in 32.00 seconds... (16/100)

[2025-08-20 12:27:29,046: ERROR/MainProcess] consumer: Cannot connect to redis://localhost:6379/0: Error 10061 connecting to localhost:6379. No connection could be made because the target machine actively refused it..
Trying again in 32.00 seconds... (16/100)

[2025-08-20 12:28:05,171: ERROR/MainProcess] consumer: Cannot connect to redis://localhost:6379/0: Error 10061 connecting to localhost:6379. No connection could be made because the target machine actively refused it..
Trying again in 32.00 seconds... (16/100)

[2025-08-20 12:28:41,302: ERROR/MainProcess] consumer: Cannot connect to redis://localhost:6379/0: Error 10061 connecting to localhost:6379. No connection could be made because the target machine actively refused it..
Trying again in 32.00 seconds... (16/100)

[2025-08-20 12:29:17,420: ERROR/MainProcess] consumer: Cannot connect to redis://localhost:6379/0: Error 10061 connecting to localhost:6379. No connection could be made because the target machine actively refused it..
Trying again in 32.00 seconds... (16/100)

[2025-08-20 12:29:53,507: ERROR/MainProcess] consumer: Cannot connect to redis://localhost:6379/0: Error 10061 connecting to localhost:6379. No connection could be made because the target machine actively refused it..
Trying again in 32.00 seconds... (16/100)

[2025-08-20 12:30:29,590: ERROR/MainProcess] consumer: Cannot connect to redis://localhost:6379/0: Error 10061 connecting to localhost:6379. No connection could be made because the target machine actively refused it..
Trying again in 32.00 seconds... (16/100)

[2025-08-20 12:31:05,714: ERROR/MainProcess] consumer: Cannot connect to redis://localhost:6379/0: Error 10061 connecting to localhost:6379. No connection could be made because the target machine actively refused it..
Trying again in 32.00 seconds... (16/100)

[2025-08-20 12:31:41,824: ERROR/MainProcess] consumer: Cannot connect to redis://localhost:6379/0: Error 10061 connecting to localhost:6379. No connection could be made because the target machine actively refused it..
Trying again in 32.00 seconds... (16/100)

[2025-08-20 12:32:17,916: ERROR/MainProcess] consumer: Cannot connect to redis://localhost:6379/0: Error 10061 connecting to localhost:6379. No connection could be made because the target machine actively refused it..
Trying again in 32.00 seconds... (16/100)

[2025-08-20 12:32:54,033: ERROR/MainProcess] consumer: Cannot connect to redis://localhost:6379/0: Error 10061 connecting to localhost:6379. No connection could be made because the target machine actively refused it..
Trying again in 32.00 seconds... (16/100)

[2025-08-20 12:33:30,140: ERROR/MainProcess] consumer: Cannot connect to redis://localhost:6379/0: Error 10061 connecting to localhost:6379. No connection could be made because the target machine actively refused it..
Trying again in 32.00 seconds... (16/100)

[2025-08-20 12:34:06,228: ERROR/MainProcess] consumer: Cannot connect to redis://localhost:6379/0: Error 10061 connecting to localhost:6379. No connection could be made because the target machine actively refused it..
Trying again in 32.00 seconds... (16/100)

[2025-08-20 12:34:42,315: ERROR/MainProcess] consumer: Cannot connect to redis://localhost:6379/0: Error 10061 connecting to localhost:6379. No connection could be made because the target machine actively refused it..
Trying again in 32.00 seconds... (16/100)

[2025-08-20 12:35:18,434: ERROR/MainProcess] consumer: Cannot connect to redis://localhost:6379/0: Error 10061 connecting to localhost:6379. No connection could be made because the target machine actively refused it..
Trying again in 32.00 seconds... (16/100)

[2025-08-20 12:35:54,539: ERROR/MainProcess] consumer: Cannot connect to redis://localhost:6379/0: Error 10061 connecting to localhost:6379. No connection could be made because the target machine actively refused it..
Trying again in 32.00 seconds... (16/100)

[2025-08-20 12:36:30,649: ERROR/MainProcess] consumer: Cannot connect to redis://localhost:6379/0: Error 10061 connecting to localhost:6379. No connection could be made because the target machine actively refused it..
Trying again in 32.00 seconds... (16/100)

[2025-08-20 12:37:06,747: ERROR/MainProcess] consumer: Cannot connect to redis://localhost:6379/0: Error 10061 connecting to localhost:6379. No connection could be made because the target machine actively refused it..
Trying again in 32.00 seconds... (16/100)

[2025-08-20 12:37:42,841: ERROR/MainProcess] consumer: Cannot connect to redis://localhost:6379/0: Error 10061 connecting to localhost:6379. No connection could be made because the target machine actively refused it..
Trying again in 32.00 seconds... (16/100)

[2025-08-20 12:38:18,953: ERROR/MainProcess] consumer: Cannot connect to redis://localhost:6379/0: Error 10061 connecting to localhost:6379. No connection could be made because the target machine actively refused it..
Trying again in 32.00 seconds... (16/100)

[2025-08-20 12:38:55,033: ERROR/MainProcess] consumer: Cannot connect to redis://localhost:6379/0: Error 10061 connecting to localhost:6379. No connection could be made because the target machine actively refused it..
Trying again in 32.00 seconds... (16/100)

[2025-08-20 12:39:31,150: ERROR/MainProcess] consumer: Cannot connect to redis://localhost:6379/0: Error 10061 connecting to localhost:6379. No connection could be made because the target machine actively refused it..
Trying again in 32.00 seconds... (16/100)

[2025-08-20 12:40:07,234: ERROR/MainProcess] consumer: Cannot connect to redis://localhost:6379/0: Error 10061 connecting to localhost:6379. No connection could be made because the target machine actively refused it..
Trying again in 32.00 seconds... (16/100)

[2025-08-20 12:40:43,304: ERROR/MainProcess] consumer: Cannot connect to redis://localhost:6379/0: Error 10061 connecting to localhost:6379. No connection could be made because the target machine actively refused it..
Trying again in 32.00 seconds... (16/100)

[2025-08-20 12:41:19,417: ERROR/MainProcess] consumer: Cannot connect to redis://localhost:6379/0: Error 10061 connecting to localhost:6379. No connection could be made because the target machine actively refused it..
Trying again in 32.00 seconds... (16/100)

[2025-08-20 12:41:55,536: ERROR/MainProcess] consumer: Cannot connect to redis://localhost:6379/0: Error 10061 connecting to localhost:6379. No connection could be made because the target machine actively refused it..
Trying again in 32.00 seconds... (16/100)

[2025-08-20 12:42:31,651: ERROR/MainProcess] consumer: Cannot connect to redis://localhost:6379/0: Error 10061 connecting to localhost:6379. No connection could be made because the target machine actively refused it..
Trying again in 32.00 seconds... (16/100)

[2025-08-20 12:43:07,761: ERROR/MainProcess] consumer: Cannot connect to redis://localhost:6379/0: Error 10061 connecting to localhost:6379. No connection could be made because the target machine actively refused it..
Trying again in 32.00 seconds... (16/100)

[2025-08-20 12:43:43,883: ERROR/MainProcess] consumer: Cannot connect to redis://localhost:6379/0: Error 10061 connecting to localhost:6379. No connection could be made because the target machine actively refused it..
Trying again in 32.00 seconds... (16/100)

[2025-08-20 12:44:19,990: ERROR/MainProcess] consumer: Cannot connect to redis://localhost:6379/0: Error 10061 connecting to localhost:6379. No connection could be made because the target machine actively refused it..
Trying again in 32.00 seconds... (16/100)

[2025-08-20 12:44:56,107: ERROR/MainProcess] consumer: Cannot connect to redis://localhost:6379/0: Error 10061 connecting to localhost:6379. No connection could be made because the target machine actively refused it..
Trying again in 32.00 seconds... (16/100)

[2025-08-20 12:45:32,215: ERROR/MainProcess] consumer: Cannot connect to redis://localhost:6379/0: Error 10061 connecting to localhost:6379. No connection could be made because the target machine actively refused it..
Trying again in 32.00 seconds... (16/100)

[2025-08-20 12:46:08,329: ERROR/MainProcess] consumer: Cannot connect to redis://localhost:6379/0: Error 10061 connecting to localhost:6379. No connection could be made because the target machine actively refused it..
Trying again in 32.00 seconds... (16/100)

[2025-08-20 12:46:44,414: ERROR/MainProcess] consumer: Cannot connect to redis://localhost:6379/0: Error 10061 connecting to localhost:6379. No connection could be made because the target machine actively refused it..
Trying again in 32.00 seconds... (16/100)

[2025-08-20 12:47:20,526: ERROR/MainProcess] consumer: Cannot connect to redis://localhost:6379/0: Error 10061 connecting to localhost:6379. No connection could be made because the target machine actively refused it..
Trying again in 32.00 seconds... (16/100)

[2025-08-20 12:47:56,619: ERROR/MainProcess] consumer: Cannot connect to redis://localhost:6379/0: Error 10061 connecting to localhost:6379. No connection could be made because the target machine actively refused it..
Trying again in 32.00 seconds... (16/100)

[2025-08-20 12:48:32,732: ERROR/MainProcess] consumer: Cannot connect to redis://localhost:6379/0: Error 10061 connecting to localhost:6379. No connection could be made because the target machine actively refused it..
Trying again in 32.00 seconds... (16/100)

[2025-08-20 12:49:08,837: ERROR/MainProcess] consumer: Cannot connect to redis://localhost:6379/0: Error 10061 connecting to localhost:6379. No connection could be made because the target machine actively refused it..
Trying again in 32.00 seconds... (16/100)

[2025-08-20 12:49:44,950: ERROR/MainProcess] consumer: Cannot connect to redis://localhost:6379/0: Error 10061 connecting to localhost:6379. No connection could be made because the target machine actively refused it..
Trying again in 32.00 seconds... (16/100)

[2025-08-20 12:50:21,066: ERROR/MainProcess] consumer: Cannot connect to redis://localhost:6379/0: Error 10061 connecting to localhost:6379. No connection could be made because the target machine actively refused it..
Trying again in 32.00 seconds... (16/100)

[2025-08-20 12:50:57,162: ERROR/MainProcess] consumer: Cannot connect to redis://localhost:6379/0: Error 10061 connecting to localhost:6379. No connection could be made because the target machine actively refused it..
Trying again in 32.00 seconds... (16/100)

[2025-08-20 12:51:33,263: ERROR/MainProcess] consumer: Cannot connect to redis://localhost:6379/0: Error 10061 connecting to localhost:6379. No connection could be made because the target machine actively refused it..
Trying again in 32.00 seconds... (16/100)

[2025-08-20 12:52:09,374: ERROR/MainProcess] consumer: Cannot connect to redis://localhost:6379/0: Error 10061 connecting to localhost:6379. No connection could be made because the target machine actively refused it..
Trying again in 32.00 seconds... (16/100)

[2025-08-20 12:52:45,516: ERROR/MainProcess] consumer: Cannot connect to redis://localhost:6379/0: Error 10061 connecting to localhost:6379. No connection could be made because the target machine actively refused it..
Trying again in 32.00 seconds... (16/100)

[2025-08-20 12:53:21,615: ERROR/MainProcess] consumer: Cannot connect to redis://localhost:6379/0: Error 10061 connecting to localhost:6379. No connection could be made because the target machine actively refused it..
Trying again in 32.00 seconds... (16/100)

[2025-08-20 12:53:57,713: ERROR/MainProcess] consumer: Cannot connect to redis://localhost:6379/0: Error 10061 connecting to localhost:6379. No connection could be made because the target machine actively refused it..
Trying again in 32.00 seconds... (16/100)

[2025-08-20 12:54:33,823: ERROR/MainProcess] consumer: Cannot connect to redis://localhost:6379/0: Error 10061 connecting to localhost:6379. No connection could be made because the target machine actively refused it..
Trying again in 32.00 seconds... (16/100)

[2025-08-20 12:55:09,938: ERROR/MainProcess] consumer: Cannot connect to redis://localhost:6379/0: Error 10061 connecting to localhost:6379. No connection could be made because the target machine actively refused it..
Trying again in 32.00 seconds... (16/100)

[2025-08-20 12:55:46,042: ERROR/MainProcess] consumer: Cannot connect to redis://localhost:6379/0: Error 10061 connecting to localhost:6379. No connection could be made because the target machine actively refused it..
Trying again in 32.00 seconds... (16/100)

[2025-08-20 12:56:22,153: ERROR/MainProcess] consumer: Cannot connect to redis://localhost:6379/0: Error 10061 connecting to localhost:6379. No connection could be made because the target machine actively refused it..
Trying again in 32.00 seconds... (16/100)

[2025-08-20 12:56:58,253: ERROR/MainProcess] consumer: Cannot connect to redis://localhost:6379/0: Error 10061 connecting to localhost:6379. No connection could be made because the target machine actively refused it..
Trying again in 32.00 seconds... (16/100)

[2025-08-20 12:57:34,370: ERROR/MainProcess] consumer: Cannot connect to redis://localhost:6379/0: Error 10061 connecting to localhost:6379. No connection could be made because the target machine actively refused it..
Trying again in 32.00 seconds... (16/100)

[2025-08-20 12:58:10,475: ERROR/MainProcess] consumer: Cannot connect to redis://localhost:6379/0: Error 10061 connecting to localhost:6379. No connection could be made because the target machine actively refused it..
Trying again in 32.00 seconds... (16/100)

[2025-08-20 12:58:46,609: ERROR/MainProcess] consumer: Cannot connect to redis://localhost:6379/0: Error 10061 connecting to localhost:6379. No connection could be made because the target machine actively refused it..
Trying again in 32.00 seconds... (16/100)

[2025-08-20 12:59:22,681: ERROR/MainProcess] consumer: Cannot connect to redis://localhost:6379/0: Error 10061 connecting to localhost:6379. No connection could be made because the target machine actively refused it..
Trying again in 32.00 seconds... (16/100)

[2025-08-20 12:59:58,724: ERROR/MainProcess] consumer: Cannot connect to redis://localhost:6379/0: Error 10061 connecting to localhost:6379. No connection could be made because the target machine actively refused it..
Trying again in 32.00 seconds... (16/100)

[2025-08-20 13:00:34,764: ERROR/MainProcess] consumer: Cannot connect to redis://localhost:6379/0: Error 10061 connecting to localhost:6379. No connection could be made because the target machine actively refused it..
Trying again in 32.00 seconds... (16/100)

[2025-08-20 13:01:10,795: ERROR/MainProcess] consumer: Cannot connect to redis://localhost:6379/0: Error 10061 connecting to localhost:6379. No connection could be made because the target machine actively refused it..
Trying again in 32.00 seconds... (16/100)

[2025-08-20 13:01:46,829: CRITICAL/MainProcess] Unrecoverable error: OperationalError('Error 10061 connecting to localhost:6379. No connection could be made because the target machine actively refused it.')
Traceback (most recent call last):
  File "C:\Users\itsup\Downloads\FrankTheLocalLLM-main\FrankTheLocalLLM-main\.venv\Lib\site-packages\kombu\transport\virtual\base.py", line 951, in create_channel
    return self._avail_channels.pop()
           ~~~~~~~~~~~~~~~~~~~~~~~~^^
IndexError: pop from empty list

During handling of the above exception, another exception occurred:

Traceback (most recent call last):
  File "C:\Users\itsup\Downloads\FrankTheLocalLLM-main\FrankTheLocalLLM-main\.venv\Lib\site-packages\redis\connection.py", line 389, in connect_check_health
    sock = self.retry.call_with_retry(
        lambda: self._connect(), lambda error: self.disconnect(error)
    )
  File "C:\Users\itsup\Downloads\FrankTheLocalLLM-main\FrankTheLocalLLM-main\.venv\Lib\site-packages\redis\retry.py", line 105, in call_with_retry
    return do()
  File "C:\Users\itsup\Downloads\FrankTheLocalLLM-main\FrankTheLocalLLM-main\.venv\Lib\site-packages\redis\connection.py", line 390, in <lambda>
    lambda: self._connect(), lambda error: self.disconnect(error)
            ~~~~~~~~~~~~~^^
  File "C:\Users\itsup\Downloads\FrankTheLocalLLM-main\FrankTheLocalLLM-main\.venv\Lib\site-packages\redis\connection.py", line 803, in _connect
    raise err
  File "C:\Users\itsup\Downloads\FrankTheLocalLLM-main\FrankTheLocalLLM-main\.venv\Lib\site-packages\redis\connection.py", line 787, in _connect
    sock.connect(socket_address)
    ~~~~~~~~~~~~^^^^^^^^^^^^^^^^
ConnectionRefusedError: [WinError 10061] No connection could be made because the target machine actively refused it

During handling of the above exception, another exception occurred:

Traceback (most recent call last):
  File "C:\Users\itsup\Downloads\FrankTheLocalLLM-main\FrankTheLocalLLM-main\.venv\Lib\site-packages\kombu\connection.py", line 472, in _reraise_as_library_errors
    yield
  File "C:\Users\itsup\Downloads\FrankTheLocalLLM-main\FrankTheLocalLLM-main\.venv\Lib\site-packages\kombu\connection.py", line 459, in _ensure_connection
    return retry_over_time(
        self._connection_factory, self.recoverable_connection_errors,
    ...<2 lines>...
        callback, timeout=timeout
    )
  File "C:\Users\itsup\Downloads\FrankTheLocalLLM-main\FrankTheLocalLLM-main\.venv\Lib\site-packages\kombu\utils\functional.py", line 318, in retry_over_time
    return fun(*args, **kwargs)
  File "C:\Users\itsup\Downloads\FrankTheLocalLLM-main\FrankTheLocalLLM-main\.venv\Lib\site-packages\kombu\connection.py", line 938, in _connection_factory
    self._connection = self._establish_connection()
                       ~~~~~~~~~~~~~~~~~~~~~~~~~~^^
  File "C:\Users\itsup\Downloads\FrankTheLocalLLM-main\FrankTheLocalLLM-main\.venv\Lib\site-packages\kombu\connection.py", line 860, in _establish_connection
    conn = self.transport.establish_connection()
  File "C:\Users\itsup\Downloads\FrankTheLocalLLM-main\FrankTheLocalLLM-main\.venv\Lib\site-packages\kombu\transport\virtual\base.py", line 975, in establish_connection
    self._avail_channels.append(self.create_channel(self))
                                ~~~~~~~~~~~~~~~~~~~^^^^^^
  File "C:\Users\itsup\Downloads\FrankTheLocalLLM-main\FrankTheLocalLLM-main\.venv\Lib\site-packages\kombu\transport\virtual\base.py", line 953, in create_channel
    channel = self.Channel(connection)
  File "C:\Users\itsup\Downloads\FrankTheLocalLLM-main\FrankTheLocalLLM-main\.venv\Lib\site-packages\kombu\transport\redis.py", line 751, in __init__
    self.client.ping()
    ~~~~~~~~~~~~~~~~^^
  File "C:\Users\itsup\Downloads\FrankTheLocalLLM-main\FrankTheLocalLLM-main\.venv\Lib\site-packages\redis\commands\core.py", line 1219, in ping
    return self.execute_command("PING", **kwargs)
           ~~~~~~~~~~~~~~~~~~~~^^^^^^^^^^^^^^^^^^
  File "C:\Users\itsup\Downloads\FrankTheLocalLLM-main\FrankTheLocalLLM-main\.venv\Lib\site-packages\redis\client.py", line 621, in execute_command
    return self._execute_command(*args, **options)
           ~~~~~~~~~~~~~~~~~~~~~^^^^^^^^^^^^^^^^^^
  File "C:\Users\itsup\Downloads\FrankTheLocalLLM-main\FrankTheLocalLLM-main\.venv\Lib\site-packages\redis\client.py", line 627, in _execute_command
    conn = self.connection or pool.get_connection()
                              ~~~~~~~~~~~~~~~~~~~^^
  File "C:\Users\itsup\Downloads\FrankTheLocalLLM-main\FrankTheLocalLLM-main\.venv\Lib\site-packages\redis\utils.py", line 195, in wrapper
    return func(*args, **kwargs)
  File "C:\Users\itsup\Downloads\FrankTheLocalLLM-main\FrankTheLocalLLM-main\.venv\Lib\site-packages\redis\connection.py", line 1533, in get_connection
    connection.connect()
    ~~~~~~~~~~~~~~~~~~^^
  File "C:\Users\itsup\Downloads\FrankTheLocalLLM-main\FrankTheLocalLLM-main\.venv\Lib\site-packages\redis\connection.py", line 380, in connect
    self.connect_check_health(check_health=True)
    ~~~~~~~~~~~~~~~~~~~~~~~~~^^^^^^^^^^^^^^^^^^^
  File "C:\Users\itsup\Downloads\FrankTheLocalLLM-main\FrankTheLocalLLM-main\.venv\Lib\site-packages\redis\connection.py", line 397, in connect_check_health
    raise ConnectionError(self._error_message(e))
redis.exceptions.ConnectionError: Error 10061 connecting to localhost:6379. No connection could be made because the target machine actively refused it.

The above exception was the direct cause of the following exception:

Traceback (most recent call last):
  File "C:\Users\itsup\Downloads\FrankTheLocalLLM-main\FrankTheLocalLLM-main\.venv\Lib\site-packages\celery\worker\worker.py", line 203, in start
    self.blueprint.start(self)
    ~~~~~~~~~~~~~~~~~~~~^^^^^^
  File "C:\Users\itsup\Downloads\FrankTheLocalLLM-main\FrankTheLocalLLM-main\.venv\Lib\site-packages\celery\bootsteps.py", line 116, in start
    step.start(parent)
    ~~~~~~~~~~^^^^^^^^
  File "C:\Users\itsup\Downloads\FrankTheLocalLLM-main\FrankTheLocalLLM-main\.venv\Lib\site-packages\celery\bootsteps.py", line 365, in start
    return self.obj.start()
           ~~~~~~~~~~~~~~^^
  File "C:\Users\itsup\Downloads\FrankTheLocalLLM-main\FrankTheLocalLLM-main\.venv\Lib\site-packages\celery\worker\consumer\consumer.py", line 341, in start
    blueprint.start(self)
    ~~~~~~~~~~~~~~~^^^^^^
  File "C:\Users\itsup\Downloads\FrankTheLocalLLM-main\FrankTheLocalLLM-main\.venv\Lib\site-packages\celery\bootsteps.py", line 116, in start
    step.start(parent)
    ~~~~~~~~~~^^^^^^^^
  File "C:\Users\itsup\Downloads\FrankTheLocalLLM-main\FrankTheLocalLLM-main\.venv\Lib\site-packages\celery\worker\consumer\connection.py", line 21, in start
    c.connection = c.connect()
                   ~~~~~~~~~^^
  File "C:\Users\itsup\Downloads\FrankTheLocalLLM-main\FrankTheLocalLLM-main\.venv\Lib\site-packages\celery\worker\consumer\consumer.py", line 472, in connect
    conn = self.connection_for_read(heartbeat=self.amqheartbeat)
  File "C:\Users\itsup\Downloads\FrankTheLocalLLM-main\FrankTheLocalLLM-main\.venv\Lib\site-packages\celery\worker\consumer\consumer.py", line 478, in connection_for_read
    return self.ensure_connected(
           ~~~~~~~~~~~~~~~~~~~~~^
        self.app.connection_for_read(heartbeat=heartbeat))
        ^^^^^^^^^^^^^^^^^^^^^^^^^^^^^^^^^^^^^^^^^^^^^^^^^^
  File "C:\Users\itsup\Downloads\FrankTheLocalLLM-main\FrankTheLocalLLM-main\.venv\Lib\site-packages\celery\worker\consumer\consumer.py", line 530, in ensure_connected
    conn = conn.ensure_connection(
        _error_handler, self.app.conf.broker_connection_max_retries,
        callback=maybe_shutdown,
    )
  File "C:\Users\itsup\Downloads\FrankTheLocalLLM-main\FrankTheLocalLLM-main\.venv\Lib\site-packages\kombu\connection.py", line 406, in ensure_connection
    self._ensure_connection(*args, **kwargs)
    ~~~~~~~~~~~~~~~~~~~~~~~^^^^^^^^^^^^^^^^^
  File "C:\Users\itsup\Downloads\FrankTheLocalLLM-main\FrankTheLocalLLM-main\.venv\Lib\site-packages\kombu\connection.py", line 458, in _ensure_connection
    with ctx():
         ~~~^^
  File "C:\Python313\Lib\contextlib.py", line 162, in __exit__
    self.gen.throw(value)
    ~~~~~~~~~~~~~~^^^^^^^
  File "C:\Users\itsup\Downloads\FrankTheLocalLLM-main\FrankTheLocalLLM-main\.venv\Lib\site-packages\kombu\connection.py", line 476, in _reraise_as_library_errors
    raise ConnectionError(str(exc)) from exc
kombu.exceptions.OperationalError: Error 10061 connecting to localhost:6379. No connection could be made because the target machine actively refused it.
[2025-08-20 13:01:46,885: ERROR/SpawnPoolWorker-12] Pool process <billiard.pool.Worker object at 0x000002184E94A120> error: PermissionError(13, 'Access is denied', None, 5, None)
Traceback (most recent call last):
  File "C:\Users\itsup\Downloads\FrankTheLocalLLM-main\FrankTheLocalLLM-main\.venv\Lib\site-packages\billiard\pool.py", line 473, in receive
    ready, req = _receive(1.0)
                 ~~~~~~~~^^^^^
  File "C:\Users\itsup\Downloads\FrankTheLocalLLM-main\FrankTheLocalLLM-main\.venv\Lib\site-packages\billiard\pool.py", line 445, in _recv
    return True, loads(get_payload())
                       ~~~~~~~~~~~^^
  File "C:\Users\itsup\Downloads\FrankTheLocalLLM-main\FrankTheLocalLLM-main\.venv\Lib\site-packages\billiard\queues.py", line 394, in get_payload
    with self._rlock:
         ^^^^^^^^^^^
  File "C:\Users\itsup\Downloads\FrankTheLocalLLM-main\FrankTheLocalLLM-main\.venv\Lib\site-packages\billiard\synchronize.py", line 118, in __exit__
    return self._semlock.__exit__(*args)
           ~~~~~~~~~~~~~~~~~~~~~~^^^^^^^
OSError: [WinError 6] The handle is invalid

During handling of the above exception, another exception occurred:

Traceback (most recent call last):
  File "C:\Users\itsup\Downloads\FrankTheLocalLLM-main\FrankTheLocalLLM-main\.venv\Lib\site-packages\billiard\pool.py", line 351, in workloop
    req = wait_for_job()
  File "C:\Users\itsup\Downloads\FrankTheLocalLLM-main\FrankTheLocalLLM-main\.venv\Lib\site-packages\billiard\pool.py", line 480, in receive
    raise SystemExit(EX_FAILURE)
SystemExit: 1

During handling of the above exception, another exception occurred:

Traceback (most recent call last):
  File "C:\Users\itsup\Downloads\FrankTheLocalLLM-main\FrankTheLocalLLM-main\.venv\Lib\site-packages\billiard\pool.py", line 292, in __call__
    sys.exit(self.workloop(pid=pid))
             ~~~~~~~~~~~~~^^^^^^^^^
  File "C:\Users\itsup\Downloads\FrankTheLocalLLM-main\FrankTheLocalLLM-main\.venv\Lib\site-packages\billiard\pool.py", line 396, in workloop
    self._ensure_messages_consumed(completed=completed)
    ~~~~~~~~~~~~~~~~~~~~~~~~~~~~~~^^^^^^^^^^^^^^^^^^^^^
  File "C:\Users\itsup\Downloads\FrankTheLocalLLM-main\FrankTheLocalLLM-main\.venv\Lib\site-packages\billiard\pool.py", line 406, in _ensure_messages_consumed
    if self.on_ready_counter.value >= completed:
       ^^^^^^^^^^^^^^^^^^^^^^^^^^^
  File "<string>", line 3, in getvalue
PermissionError: [WinError 5] Access is denied
[2025-08-20 13:01:46,885: ERROR/SpawnPoolWorker-7] Pool process <billiard.pool.Worker object at 0x0000024A7B20A120> error: PermissionError(13, 'Access is denied', None, 5, None)
Traceback (most recent call last):
  File "C:\Users\itsup\Downloads\FrankTheLocalLLM-main\FrankTheLocalLLM-main\.venv\Lib\site-packages\billiard\pool.py", line 473, in receive
    ready, req = _receive(1.0)
                 ~~~~~~~~^^^^^
  File "C:\Users\itsup\Downloads\FrankTheLocalLLM-main\FrankTheLocalLLM-main\.venv\Lib\site-packages\billiard\pool.py", line 445, in _recv
    return True, loads(get_payload())
                       ~~~~~~~~~~~^^
  File "C:\Users\itsup\Downloads\FrankTheLocalLLM-main\FrankTheLocalLLM-main\.venv\Lib\site-packages\billiard\queues.py", line 394, in get_payload
    with self._rlock:
         ^^^^^^^^^^^
  File "C:\Users\itsup\Downloads\FrankTheLocalLLM-main\FrankTheLocalLLM-main\.venv\Lib\site-packages\billiard\synchronize.py", line 118, in __exit__
    return self._semlock.__exit__(*args)
           ~~~~~~~~~~~~~~~~~~~~~~^^^^^^^
OSError: [WinError 6] The handle is invalid

During handling of the above exception, another exception occurred:

Traceback (most recent call last):
  File "C:\Users\itsup\Downloads\FrankTheLocalLLM-main\FrankTheLocalLLM-main\.venv\Lib\site-packages\billiard\pool.py", line 351, in workloop
    req = wait_for_job()
  File "C:\Users\itsup\Downloads\FrankTheLocalLLM-main\FrankTheLocalLLM-main\.venv\Lib\site-packages\billiard\pool.py", line 480, in receive
    raise SystemExit(EX_FAILURE)
SystemExit: 1

During handling of the above exception, another exception occurred:

Traceback (most recent call last):
  File "C:\Users\itsup\Downloads\FrankTheLocalLLM-main\FrankTheLocalLLM-main\.venv\Lib\site-packages\billiard\pool.py", line 292, in __call__
    sys.exit(self.workloop(pid=pid))
             ~~~~~~~~~~~~~^^^^^^^^^
  File "C:\Users\itsup\Downloads\FrankTheLocalLLM-main\FrankTheLocalLLM-main\.venv\Lib\site-packages\billiard\pool.py", line 396, in workloop
    self._ensure_messages_consumed(completed=completed)
    ~~~~~~~~~~~~~~~~~~~~~~~~~~~~~~^^^^^^^^^^^^^^^^^^^^^
  File "C:\Users\itsup\Downloads\FrankTheLocalLLM-main\FrankTheLocalLLM-main\.venv\Lib\site-packages\billiard\pool.py", line 406, in _ensure_messages_consumed
    if self.on_ready_counter.value >= completed:
       ^^^^^^^^^^^^^^^^^^^^^^^^^^^
  File "<string>", line 3, in getvalue
PermissionError: [WinError 5] Access is denied
[2025-08-20 13:01:46,885: ERROR/SpawnPoolWorker-8] Pool process <billiard.pool.Worker object at 0x000001CA125CA120> error: PermissionError(13, 'Access is denied', None, 5, None)
Traceback (most recent call last):
  File "C:\Users\itsup\Downloads\FrankTheLocalLLM-main\FrankTheLocalLLM-main\.venv\Lib\site-packages\billiard\pool.py", line 473, in receive
    ready, req = _receive(1.0)
                 ~~~~~~~~^^^^^
  File "C:\Users\itsup\Downloads\FrankTheLocalLLM-main\FrankTheLocalLLM-main\.venv\Lib\site-packages\billiard\pool.py", line 445, in _recv
    return True, loads(get_payload())
                       ~~~~~~~~~~~^^
  File "C:\Users\itsup\Downloads\FrankTheLocalLLM-main\FrankTheLocalLLM-main\.venv\Lib\site-packages\billiard\queues.py", line 394, in get_payload
    with self._rlock:
         ^^^^^^^^^^^
  File "C:\Users\itsup\Downloads\FrankTheLocalLLM-main\FrankTheLocalLLM-main\.venv\Lib\site-packages\billiard\synchronize.py", line 118, in __exit__
    return self._semlock.__exit__(*args)
           ~~~~~~~~~~~~~~~~~~~~~~^^^^^^^
OSError: [WinError 6] The handle is invalid

During handling of the above exception, another exception occurred:

Traceback (most recent call last):
  File "C:\Users\itsup\Downloads\FrankTheLocalLLM-main\FrankTheLocalLLM-main\.venv\Lib\site-packages\billiard\pool.py", line 351, in workloop
    req = wait_for_job()
  File "C:\Users\itsup\Downloads\FrankTheLocalLLM-main\FrankTheLocalLLM-main\.venv\Lib\site-packages\billiard\pool.py", line 480, in receive
    raise SystemExit(EX_FAILURE)
SystemExit: 1

During handling of the above exception, another exception occurred:

Traceback (most recent call last):
  File "C:\Users\itsup\Downloads\FrankTheLocalLLM-main\FrankTheLocalLLM-main\.venv\Lib\site-packages\billiard\pool.py", line 292, in __call__
    sys.exit(self.workloop(pid=pid))
             ~~~~~~~~~~~~~^^^^^^^^^
  File "C:\Users\itsup\Downloads\FrankTheLocalLLM-main\FrankTheLocalLLM-main\.venv\Lib\site-packages\billiard\pool.py", line 396, in workloop
    self._ensure_messages_consumed(completed=completed)
    ~~~~~~~~~~~~~~~~~~~~~~~~~~~~~~^^^^^^^^^^^^^^^^^^^^^
  File "C:\Users\itsup\Downloads\FrankTheLocalLLM-main\FrankTheLocalLLM-main\.venv\Lib\site-packages\billiard\pool.py", line 406, in _ensure_messages_consumed
    if self.on_ready_counter.value >= completed:
       ^^^^^^^^^^^^^^^^^^^^^^^^^^^
  File "<string>", line 3, in getvalue
PermissionError: [WinError 5] Access is denied
[2025-08-20 13:01:46,885: ERROR/SpawnPoolWorker-12] Pool process <billiard.pool.Worker object at 0x000002184E94A120> error: PermissionError(13, 'Access is denied', None, 5, None)
Traceback (most recent call last):
  File "C:\Users\itsup\Downloads\FrankTheLocalLLM-main\FrankTheLocalLLM-main\.venv\Lib\site-packages\billiard\pool.py", line 473, in receive
    ready, req = _receive(1.0)
                 ~~~~~~~~^^^^^
  File "C:\Users\itsup\Downloads\FrankTheLocalLLM-main\FrankTheLocalLLM-main\.venv\Lib\site-packages\billiard\pool.py", line 445, in _recv
    return True, loads(get_payload())
                       ~~~~~~~~~~~^^
  File "C:\Users\itsup\Downloads\FrankTheLocalLLM-main\FrankTheLocalLLM-main\.venv\Lib\site-packages\billiard\queues.py", line 394, in get_payload
    with self._rlock:
         ^^^^^^^^^^^
  File "C:\Users\itsup\Downloads\FrankTheLocalLLM-main\FrankTheLocalLLM-main\.venv\Lib\site-packages\billiard\synchronize.py", line 118, in __exit__
    return self._semlock.__exit__(*args)
           ~~~~~~~~~~~~~~~~~~~~~~^^^^^^^
OSError: [WinError 6] The handle is invalid

During handling of the above exception, another exception occurred:

Traceback (most recent call last):
  File "C:\Users\itsup\Downloads\FrankTheLocalLLM-main\FrankTheLocalLLM-main\.venv\Lib\site-packages\billiard\pool.py", line 351, in workloop
    req = wait_for_job()
  File "C:\Users\itsup\Downloads\FrankTheLocalLLM-main\FrankTheLocalLLM-main\.venv\Lib\site-packages\billiard\pool.py", line 480, in receive
    raise SystemExit(EX_FAILURE)
SystemExit: 1

During handling of the above exception, another exception occurred:

Traceback (most recent call last):
  File "C:\Users\itsup\Downloads\FrankTheLocalLLM-main\FrankTheLocalLLM-main\.venv\Lib\site-packages\billiard\pool.py", line 292, in __call__
    sys.exit(self.workloop(pid=pid))
             ~~~~~~~~~~~~~^^^^^^^^^
  File "C:\Users\itsup\Downloads\FrankTheLocalLLM-main\FrankTheLocalLLM-main\.venv\Lib\site-packages\billiard\pool.py", line 396, in workloop
    self._ensure_messages_consumed(completed=completed)
    ~~~~~~~~~~~~~~~~~~~~~~~~~~~~~~^^^^^^^^^^^^^^^^^^^^^
  File "C:\Users\itsup\Downloads\FrankTheLocalLLM-main\FrankTheLocalLLM-main\.venv\Lib\site-packages\billiard\pool.py", line 406, in _ensure_messages_consumed
    if self.on_ready_counter.value >= completed:
       ^^^^^^^^^^^^^^^^^^^^^^^^^^^
  File "<string>", line 3, in getvalue
PermissionError: [WinError 5] Access is denied
[2025-08-20 13:01:46,886: ERROR/SpawnPoolWorker-11] Pool process <billiard.pool.Worker object at 0x0000018CD236A120> error: PermissionError(13, 'Access is denied', None, 5, None)
Traceback (most recent call last):
  File "C:\Users\itsup\Downloads\FrankTheLocalLLM-main\FrankTheLocalLLM-main\.venv\Lib\site-packages\billiard\pool.py", line 473, in receive
    ready, req = _receive(1.0)
                 ~~~~~~~~^^^^^
  File "C:\Users\itsup\Downloads\FrankTheLocalLLM-main\FrankTheLocalLLM-main\.venv\Lib\site-packages\billiard\pool.py", line 445, in _recv
    return True, loads(get_payload())
                       ~~~~~~~~~~~^^
  File "C:\Users\itsup\Downloads\FrankTheLocalLLM-main\FrankTheLocalLLM-main\.venv\Lib\site-packages\billiard\queues.py", line 394, in get_payload
    with self._rlock:
         ^^^^^^^^^^^
  File "C:\Users\itsup\Downloads\FrankTheLocalLLM-main\FrankTheLocalLLM-main\.venv\Lib\site-packages\billiard\synchronize.py", line 118, in __exit__
    return self._semlock.__exit__(*args)
           ~~~~~~~~~~~~~~~~~~~~~~^^^^^^^
OSError: [WinError 6] The handle is invalid

During handling of the above exception, another exception occurred:

Traceback (most recent call last):
  File "C:\Users\itsup\Downloads\FrankTheLocalLLM-main\FrankTheLocalLLM-main\.venv\Lib\site-packages\billiard\pool.py", line 351, in workloop
    req = wait_for_job()
  File "C:\Users\itsup\Downloads\FrankTheLocalLLM-main\FrankTheLocalLLM-main\.venv\Lib\site-packages\billiard\pool.py", line 480, in receive
    raise SystemExit(EX_FAILURE)
SystemExit: 1

During handling of the above exception, another exception occurred:

Traceback (most recent call last):
  File "C:\Users\itsup\Downloads\FrankTheLocalLLM-main\FrankTheLocalLLM-main\.venv\Lib\site-packages\billiard\pool.py", line 292, in __call__
    sys.exit(self.workloop(pid=pid))
             ~~~~~~~~~~~~~^^^^^^^^^
  File "C:\Users\itsup\Downloads\FrankTheLocalLLM-main\FrankTheLocalLLM-main\.venv\Lib\site-packages\billiard\pool.py", line 396, in workloop
    self._ensure_messages_consumed(completed=completed)
    ~~~~~~~~~~~~~~~~~~~~~~~~~~~~~~^^^^^^^^^^^^^^^^^^^^^
  File "C:\Users\itsup\Downloads\FrankTheLocalLLM-main\FrankTheLocalLLM-main\.venv\Lib\site-packages\billiard\pool.py", line 406, in _ensure_messages_consumed
    if self.on_ready_counter.value >= completed:
       ^^^^^^^^^^^^^^^^^^^^^^^^^^^
  File "<string>", line 3, in getvalue
PermissionError: [WinError 5] Access is denied
[2025-08-20 13:01:46,885: ERROR/SpawnPoolWorker-7] Pool process <billiard.pool.Worker object at 0x0000024A7B20A120> error: PermissionError(13, 'Access is denied', None, 5, None)
Traceback (most recent call last):
  File "C:\Users\itsup\Downloads\FrankTheLocalLLM-main\FrankTheLocalLLM-main\.venv\Lib\site-packages\billiard\pool.py", line 473, in receive
    ready, req = _receive(1.0)
                 ~~~~~~~~^^^^^
  File "C:\Users\itsup\Downloads\FrankTheLocalLLM-main\FrankTheLocalLLM-main\.venv\Lib\site-packages\billiard\pool.py", line 445, in _recv
    return True, loads(get_payload())
                       ~~~~~~~~~~~^^
  File "C:\Users\itsup\Downloads\FrankTheLocalLLM-main\FrankTheLocalLLM-main\.venv\Lib\site-packages\billiard\queues.py", line 394, in get_payload
    with self._rlock:
         ^^^^^^^^^^^
  File "C:\Users\itsup\Downloads\FrankTheLocalLLM-main\FrankTheLocalLLM-main\.venv\Lib\site-packages\billiard\synchronize.py", line 118, in __exit__
    return self._semlock.__exit__(*args)
           ~~~~~~~~~~~~~~~~~~~~~~^^^^^^^
OSError: [WinError 6] The handle is invalid

During handling of the above exception, another exception occurred:

Traceback (most recent call last):
  File "C:\Users\itsup\Downloads\FrankTheLocalLLM-main\FrankTheLocalLLM-main\.venv\Lib\site-packages\billiard\pool.py", line 351, in workloop
    req = wait_for_job()
  File "C:\Users\itsup\Downloads\FrankTheLocalLLM-main\FrankTheLocalLLM-main\.venv\Lib\site-packages\billiard\pool.py", line 480, in receive
    raise SystemExit(EX_FAILURE)
SystemExit: 1

During handling of the above exception, another exception occurred:

Traceback (most recent call last):
  File "C:\Users\itsup\Downloads\FrankTheLocalLLM-main\FrankTheLocalLLM-main\.venv\Lib\site-packages\billiard\pool.py", line 292, in __call__
    sys.exit(self.workloop(pid=pid))
             ~~~~~~~~~~~~~^^^^^^^^^
  File "C:\Users\itsup\Downloads\FrankTheLocalLLM-main\FrankTheLocalLLM-main\.venv\Lib\site-packages\billiard\pool.py", line 396, in workloop
    self._ensure_messages_consumed(completed=completed)
    ~~~~~~~~~~~~~~~~~~~~~~~~~~~~~~^^^^^^^^^^^^^^^^^^^^^
  File "C:\Users\itsup\Downloads\FrankTheLocalLLM-main\FrankTheLocalLLM-main\.venv\Lib\site-packages\billiard\pool.py", line 406, in _ensure_messages_consumed
    if self.on_ready_counter.value >= completed:
       ^^^^^^^^^^^^^^^^^^^^^^^^^^^
  File "<string>", line 3, in getvalue
PermissionError: [WinError 5] Access is denied
[2025-08-20 13:01:46,885: ERROR/SpawnPoolWorker-3] Pool process <billiard.pool.Worker object at 0x000001C5D2FBA120> error: PermissionError(13, 'Access is denied', None, 5, None)
Traceback (most recent call last):
  File "C:\Users\itsup\Downloads\FrankTheLocalLLM-main\FrankTheLocalLLM-main\.venv\Lib\site-packages\billiard\pool.py", line 473, in receive
    ready, req = _receive(1.0)
                 ~~~~~~~~^^^^^
  File "C:\Users\itsup\Downloads\FrankTheLocalLLM-main\FrankTheLocalLLM-main\.venv\Lib\site-packages\billiard\pool.py", line 445, in _recv
    return True, loads(get_payload())
                       ~~~~~~~~~~~^^
  File "C:\Users\itsup\Downloads\FrankTheLocalLLM-main\FrankTheLocalLLM-main\.venv\Lib\site-packages\billiard\queues.py", line 394, in get_payload
    with self._rlock:
         ^^^^^^^^^^^
  File "C:\Users\itsup\Downloads\FrankTheLocalLLM-main\FrankTheLocalLLM-main\.venv\Lib\site-packages\billiard\synchronize.py", line 118, in __exit__
    return self._semlock.__exit__(*args)
           ~~~~~~~~~~~~~~~~~~~~~~^^^^^^^
OSError: [WinError 6] The handle is invalid

During handling of the above exception, another exception occurred:

Traceback (most recent call last):
  File "C:\Users\itsup\Downloads\FrankTheLocalLLM-main\FrankTheLocalLLM-main\.venv\Lib\site-packages\billiard\pool.py", line 351, in workloop
    req = wait_for_job()
  File "C:\Users\itsup\Downloads\FrankTheLocalLLM-main\FrankTheLocalLLM-main\.venv\Lib\site-packages\billiard\pool.py", line 480, in receive
    raise SystemExit(EX_FAILURE)
SystemExit: 1

During handling of the above exception, another exception occurred:

Traceback (most recent call last):
  File "C:\Users\itsup\Downloads\FrankTheLocalLLM-main\FrankTheLocalLLM-main\.venv\Lib\site-packages\billiard\pool.py", line 292, in __call__
    sys.exit(self.workloop(pid=pid))
             ~~~~~~~~~~~~~^^^^^^^^^
  File "C:\Users\itsup\Downloads\FrankTheLocalLLM-main\FrankTheLocalLLM-main\.venv\Lib\site-packages\billiard\pool.py", line 396, in workloop
    self._ensure_messages_consumed(completed=completed)
    ~~~~~~~~~~~~~~~~~~~~~~~~~~~~~~^^^^^^^^^^^^^^^^^^^^^
  File "C:\Users\itsup\Downloads\FrankTheLocalLLM-main\FrankTheLocalLLM-main\.venv\Lib\site-packages\billiard\pool.py", line 406, in _ensure_messages_consumed
    if self.on_ready_counter.value >= completed:
       ^^^^^^^^^^^^^^^^^^^^^^^^^^^
  File "<string>", line 3, in getvalue
PermissionError: [WinError 5] Access is denied
[2025-08-20 13:01:46,885: ERROR/SpawnPoolWorker-8] Pool process <billiard.pool.Worker object at 0x000001CA125CA120> error: PermissionError(13, 'Access is denied', None, 5, None)
Traceback (most recent call last):
  File "C:\Users\itsup\Downloads\FrankTheLocalLLM-main\FrankTheLocalLLM-main\.venv\Lib\site-packages\billiard\pool.py", line 473, in receive
    ready, req = _receive(1.0)
                 ~~~~~~~~^^^^^
  File "C:\Users\itsup\Downloads\FrankTheLocalLLM-main\FrankTheLocalLLM-main\.venv\Lib\site-packages\billiard\pool.py", line 445, in _recv
    return True, loads(get_payload())
                       ~~~~~~~~~~~^^
  File "C:\Users\itsup\Downloads\FrankTheLocalLLM-main\FrankTheLocalLLM-main\.venv\Lib\site-packages\billiard\queues.py", line 394, in get_payload
    with self._rlock:
         ^^^^^^^^^^^
  File "C:\Users\itsup\Downloads\FrankTheLocalLLM-main\FrankTheLocalLLM-main\.venv\Lib\site-packages\billiard\synchronize.py", line 118, in __exit__
    return self._semlock.__exit__(*args)
           ~~~~~~~~~~~~~~~~~~~~~~^^^^^^^
OSError: [WinError 6] The handle is invalid

During handling of the above exception, another exception occurred:

Traceback (most recent call last):
  File "C:\Users\itsup\Downloads\FrankTheLocalLLM-main\FrankTheLocalLLM-main\.venv\Lib\site-packages\billiard\pool.py", line 351, in workloop
    req = wait_for_job()
  File "C:\Users\itsup\Downloads\FrankTheLocalLLM-main\FrankTheLocalLLM-main\.venv\Lib\site-packages\billiard\pool.py", line 480, in receive
    raise SystemExit(EX_FAILURE)
SystemExit: 1

During handling of the above exception, another exception occurred:

Traceback (most recent call last):
  File "C:\Users\itsup\Downloads\FrankTheLocalLLM-main\FrankTheLocalLLM-main\.venv\Lib\site-packages\billiard\pool.py", line 292, in __call__
    sys.exit(self.workloop(pid=pid))
             ~~~~~~~~~~~~~^^^^^^^^^
  File "C:\Users\itsup\Downloads\FrankTheLocalLLM-main\FrankTheLocalLLM-main\.venv\Lib\site-packages\billiard\pool.py", line 396, in workloop
    self._ensure_messages_consumed(completed=completed)
    ~~~~~~~~~~~~~~~~~~~~~~~~~~~~~~^^^^^^^^^^^^^^^^^^^^^
  File "C:\Users\itsup\Downloads\FrankTheLocalLLM-main\FrankTheLocalLLM-main\.venv\Lib\site-packages\billiard\pool.py", line 406, in _ensure_messages_consumed
    if self.on_ready_counter.value >= completed:
       ^^^^^^^^^^^^^^^^^^^^^^^^^^^
  File "<string>", line 3, in getvalue
PermissionError: [WinError 5] Access is denied
[2025-08-20 13:01:46,885: ERROR/SpawnPoolWorker-3] Pool process <billiard.pool.Worker object at 0x000001C5D2FBA120> error: PermissionError(13, 'Access is denied', None, 5, None)
Traceback (most recent call last):
  File "C:\Users\itsup\Downloads\FrankTheLocalLLM-main\FrankTheLocalLLM-main\.venv\Lib\site-packages\billiard\pool.py", line 473, in receive
    ready, req = _receive(1.0)
                 ~~~~~~~~^^^^^
  File "C:\Users\itsup\Downloads\FrankTheLocalLLM-main\FrankTheLocalLLM-main\.venv\Lib\site-packages\billiard\pool.py", line 445, in _recv
    return True, loads(get_payload())
                       ~~~~~~~~~~~^^
  File "C:\Users\itsup\Downloads\FrankTheLocalLLM-main\FrankTheLocalLLM-main\.venv\Lib\site-packages\billiard\queues.py", line 394, in get_payload
    with self._rlock:
         ^^^^^^^^^^^
  File "C:\Users\itsup\Downloads\FrankTheLocalLLM-main\FrankTheLocalLLM-main\.venv\Lib\site-packages\billiard\synchronize.py", line 118, in __exit__
    return self._semlock.__exit__(*args)
           ~~~~~~~~~~~~~~~~~~~~~~^^^^^^^
OSError: [WinError 6] The handle is invalid

During handling of the above exception, another exception occurred:

Traceback (most recent call last):
  File "C:\Users\itsup\Downloads\FrankTheLocalLLM-main\FrankTheLocalLLM-main\.venv\Lib\site-packages\billiard\pool.py", line 351, in workloop
    req = wait_for_job()
  File "C:\Users\itsup\Downloads\FrankTheLocalLLM-main\FrankTheLocalLLM-main\.venv\Lib\site-packages\billiard\pool.py", line 480, in receive
    raise SystemExit(EX_FAILURE)
SystemExit: 1

During handling of the above exception, another exception occurred:

Traceback (most recent call last):
  File "C:\Users\itsup\Downloads\FrankTheLocalLLM-main\FrankTheLocalLLM-main\.venv\Lib\site-packages\billiard\pool.py", line 292, in __call__
    sys.exit(self.workloop(pid=pid))
             ~~~~~~~~~~~~~^^^^^^^^^
  File "C:\Users\itsup\Downloads\FrankTheLocalLLM-main\FrankTheLocalLLM-main\.venv\Lib\site-packages\billiard\pool.py", line 396, in workloop
    self._ensure_messages_consumed(completed=completed)
    ~~~~~~~~~~~~~~~~~~~~~~~~~~~~~~^^^^^^^^^^^^^^^^^^^^^
  File "C:\Users\itsup\Downloads\FrankTheLocalLLM-main\FrankTheLocalLLM-main\.venv\Lib\site-packages\billiard\pool.py", line 406, in _ensure_messages_consumed
    if self.on_ready_counter.value >= completed:
       ^^^^^^^^^^^^^^^^^^^^^^^^^^^
  File "<string>", line 3, in getvalue
PermissionError: [WinError 5] Access is denied
[2025-08-20 13:01:46,886: ERROR/SpawnPoolWorker-11] Pool process <billiard.pool.Worker object at 0x0000018CD236A120> error: PermissionError(13, 'Access is denied', None, 5, None)
Traceback (most recent call last):
  File "C:\Users\itsup\Downloads\FrankTheLocalLLM-main\FrankTheLocalLLM-main\.venv\Lib\site-packages\billiard\pool.py", line 473, in receive
    ready, req = _receive(1.0)
                 ~~~~~~~~^^^^^
  File "C:\Users\itsup\Downloads\FrankTheLocalLLM-main\FrankTheLocalLLM-main\.venv\Lib\site-packages\billiard\pool.py", line 445, in _recv
    return True, loads(get_payload())
                       ~~~~~~~~~~~^^
  File "C:\Users\itsup\Downloads\FrankTheLocalLLM-main\FrankTheLocalLLM-main\.venv\Lib\site-packages\billiard\queues.py", line 394, in get_payload
    with self._rlock:
         ^^^^^^^^^^^
  File "C:\Users\itsup\Downloads\FrankTheLocalLLM-main\FrankTheLocalLLM-main\.venv\Lib\site-packages\billiard\synchronize.py", line 118, in __exit__
    return self._semlock.__exit__(*args)
           ~~~~~~~~~~~~~~~~~~~~~~^^^^^^^
OSError: [WinError 6] The handle is invalid

During handling of the above exception, another exception occurred:

Traceback (most recent call last):
  File "C:\Users\itsup\Downloads\FrankTheLocalLLM-main\FrankTheLocalLLM-main\.venv\Lib\site-packages\billiard\pool.py", line 351, in workloop
    req = wait_for_job()
  File "C:\Users\itsup\Downloads\FrankTheLocalLLM-main\FrankTheLocalLLM-main\.venv\Lib\site-packages\billiard\pool.py", line 480, in receive
    raise SystemExit(EX_FAILURE)
SystemExit: 1

During handling of the above exception, another exception occurred:

Traceback (most recent call last):
  File "C:\Users\itsup\Downloads\FrankTheLocalLLM-main\FrankTheLocalLLM-main\.venv\Lib\site-packages\billiard\pool.py", line 292, in __call__
    sys.exit(self.workloop(pid=pid))
             ~~~~~~~~~~~~~^^^^^^^^^
  File "C:\Users\itsup\Downloads\FrankTheLocalLLM-main\FrankTheLocalLLM-main\.venv\Lib\site-packages\billiard\pool.py", line 396, in workloop
    self._ensure_messages_consumed(completed=completed)
    ~~~~~~~~~~~~~~~~~~~~~~~~~~~~~~^^^^^^^^^^^^^^^^^^^^^
  File "C:\Users\itsup\Downloads\FrankTheLocalLLM-main\FrankTheLocalLLM-main\.venv\Lib\site-packages\billiard\pool.py", line 406, in _ensure_messages_consumed
    if self.on_ready_counter.value >= completed:
       ^^^^^^^^^^^^^^^^^^^^^^^^^^^
  File "<string>", line 3, in getvalue
PermissionError: [WinError 5] Access is denied
